Workbook

Sheet Diseno_Marshall
A1: LABORATORIO DE ASFALTOS
A2: DISEÑO DE MEZCLAS ASFÁLTICAS EN CALIENTE - MÉTODO MARSHALL
A3: Proyecto: | C3: Práctica académica de diseño Marshall - Maestría UNA Puno
A4: Mezcla: | C4: MAC-2 fina (huso MAC-2, MTC EG-2013)
A5: C.A.: | C5: PEN 120-150
A6: Compactación: | C6: 50 golpes por cara
A8: PARÁMETROS DE DISEÑO (celdas amarillas editables) | G8: ESPECIFICACIONES (EG-2013, Clase B) | J8: Mín. | K8: Máx.
A9: Gb - Peso específico del asfalto | D9: 1.023 | G9: Estabilidad mínima (kN) | J9: 5.44
A10: Gsb - Peso esp. bulk agregado combinado | D10: 2.769 | G10: Flujo (mm) | J10: 2 | K10: 4
A11: Gse - Peso esp. efectivo del agregado | D11: 2.872 | G11: Vacíos de aire Va (%) | J11: 3 | K11: 5
A12: Pba - % asfalto absorbido (% peso agregado) | D12: =100*D9*(D11-D10)/(D10*D11) | G12: VMA mínimo (%) - TMN 12.5 mm | J12: 14
A13: Diámetro de briqueta (cm) | D13: 10.16 | G13: VFA (%) | J13: 65 | K13: 75
G14: Va objetivo para óptimo (%) | J14: 4
A16: Muestra | B16: Pb (%) | C16: Ps (%) | D16: h1 (cm) | E16: h2 (cm) | F16: h3 (cm) | G16: h4 (cm) | H16: h prom. (cm) | I16: Factor correc. | J16: Peso seco aire (g) | K16: Peso SSS (g) | L16: Sumerg. 1 (g) | M16: Sumerg. 2 (g) | N16: Sumerg. prom. (g) | O16: Vol. bulk (cc) | P16: Gmb | Q16: Gmm teórica | R16: Va (%) | S16: VMA (%) | T16: VFA (%) | U16: Pbe (%) | V16: Estab. leída (kg) | W16: Estab. correg. (kg) | X16: Estab. correg. (kN) | Y16: Flujo (mm) | Z16: Est./Flujo (kg/cm) | AA16: Densidad geom. | AB16: Absorción agua (%)
A17: M1 | B17: 5.5 | C17: =100-B17 | D17: 6.7 | E17: 6.4 | F17: 6.3 | G17: 6.6 | H17: =AVERAGE(D17:G17) | I17: =INDEX(Factor_Altura!$B$2:$B$34,MATCH(H17*10,Factor_Altura!$A$2:$A$34,1))+(H17*10-INDEX(Factor_Altura!$A$2:$A$34,MATCH(H17*10,Factor_Altura!$A$2:$A$34,1)))*(INDEX(Factor_Altura!$B$2:$B$34,MATCH(H17*10,Factor_Altura!$A$2:$A$34,1)+1)-INDEX(Factor_Altura!$B$2:$B$34,MATCH(H17*10,Factor_Altura!$A$2:$A$34,1)))/(INDEX(Factor_Altura!$A$2:$A$34,MATCH(H17*10,Factor_Altura!$A$2:$A$34,1)+1)-INDEX(Factor_Altura!$A$2:$A$34,MATCH(H17*10,Factor_Altura!$A$2:$A$34,1))) | J17: 1139 | K17: 1142 | L17: 582 | M17: 575 | N17: =AVERAGE(L17:M17) | O17: =K17-N17 | P17: =J17/O17 | Q17: =100/(B17/$D$9+C17/$D$11) | R17: =100*(Q17-P17)/Q17 | S17: =100-P17*C17/$D$10 | T17: =100*(S17-R17)/S17 | U17: =B17-$D$12*C17/100 | V17: 883.9 | W17: =V17*I17 | X17: =W17*9.80665/1000 | Y17: 4 | Z17: =W17/(Y17/10) | AA17: =J17/(PI()*$D$13^2/4*H17) | AB17: =100*(K17-J17)/O17
A18: M2 | B18: 6 | C18: =100-B18 | D18: 6.8 | E18: 6.7 | F18: 6.6 | G18: 6.6 | H18: =AVERAGE(D18:G18) | I18: =INDEX(Factor_Altura!$B$2:$B$34,MATCH(H18*10,Factor_Altura!$A$2:$A$34,1))+(H18*10-INDEX(Factor_Altura!$A$2:$A$34,MATCH(H18*10,Factor_Altura!$A$2:$A$34,1)))*(INDEX(Factor_Altura!$B$2:$B$34,MATCH(H18*10,Factor_Altura!$A$2:$A$34,1)+1)-INDEX(Factor_Altura!$B$2:$B$34,MATCH(H18*10,Factor_Altura!$A$2:$A$34,1)))/(INDEX(Factor_Altura!$A$2:$A$34,MATCH(H18*10,Factor_Altura!$A$2:$A$34,1)+1)-INDEX(Factor_Altura!$A$2:$A$34,MATCH(H18*10,Factor_Altura!$A$2:$A$34,1))) | J18: 1124 | K18: 1132 | L18: 609 | M18: 614 | N18: =AVERAGE(L18:M18) | O18: =K18-N18 | P18: =J18/O18 | Q18: =100/(B18/$D$9+C18/$D$11) | R18: =100*(Q18-P18)/Q18 | S18: =100-P18*C18/$D$10 | T18: =100*(S18-R18)/S18 | U18: =B18-$D$12*C18/100 | V18: 669.7 | W18: =V18*I18 | X18: =W18*9.80665/1000 | Y18: 4.4 | Z18: =W18/(Y18/10) | AA18: =J18/(PI()*$D$13^2/4*H18) | AB18: =100*(K18-J18)/O18
A19: M3 | B19: 6.5 | C19: =100-B19 | D19: 6.5 | E19: 6.9 | F19: 7 | G19: 6.8 | H19: =AVERAGE(D19:G19) | I19: =INDEX(Factor_Altura!$B$2:$B$34,MATCH(H19*10,Factor_Altura!$A$2:$A$34,1))+(H19*10-INDEX(Factor_Altura!$A$2:$A$34,MATCH(H19*10,Factor_Altura!$A$2:$A$34,1)))*(INDEX(Factor_Altura!$B$2:$B$34,MATCH(H19*10,Factor_Altura!$A$2:$A$34,1)+1)-INDEX(Factor_Altura!$B$2:$B$34,MATCH(H19*10,Factor_Altura!$A$2:$A$34,1)))/(INDEX(Factor_Altura!$A$2:$A$34,MATCH(H19*10,Factor_Altura!$A$2:$A$34,1)+1)-INDEX(Factor_Altura!$A$2:$A$34,MATCH(H19*10,Factor_Altura!$A$2:$A$34,1))) | J19: 1184 | K19: 1184 | L19: 641 | M19: 643 | N19: =AVERAGE(L19:M19) | O19: =K19-N19 | P19: =J19/O19 | Q19: =100/(B19/$D$9+C19/$D$11) | R19: =100*(Q19-P19)/Q19 | S19: =100-P19*C19/$D$10 | T19: =100*(S19-R19)/S19 | U19: =B19-$D$12*C19/100 | V19: 772 | W19: =V19*I19 | X19: =W19*9.80665/1000 | Y19: 4.9 | Z19: =W19/(Y19/10) | AA19: =J19/(PI()*$D$13^2/4*H19) | AB19: =100*(K19-J19)/O19
A20: M4 | B20: 8 | C20: =100-B20 | D20: 6.5 | E20: 6.6 | F20: 6.4 | G20: 6.4 | H20: =AVERAGE(D20:G20) | I20: =INDEX(Factor_Altura!$B$2:$B$34,MATCH(H20*10,Factor_Altura!$A$2:$A$34,1))+(H20*10-INDEX(Factor_Altura!$A$2:$A$34,MATCH(H20*10,Factor_Altura!$A$2:$A$34,1)))*(INDEX(Factor_Altura!$B$2:$B$34,MATCH(H20*10,Factor_Altura!$A$2:$A$34,1)+1)-INDEX(Factor_Altura!$B$2:$B$34,MATCH(H20*10,Factor_Altura!$A$2:$A$34,1)))/(INDEX(Factor_Altura!$A$2:$A$34,MATCH(H20*10,Factor_Altura!$A$2:$A$34,1)+1)-INDEX(Factor_Altura!$A$2:$A$34,MATCH(H20*10,Factor_Altura!$A$2:$A$34,1))) | J20: 1134 | K20: 1136 | L20: 617 | M20: 619 | N20: =AVERAGE(L20:M20) | O20: =K20-N20 | P20: =J20/O20 | Q20: =100/(B20/$D$9+C20/$D$11) | R20: =100*(Q20-P20)/Q20 | S20: =100-P20*C20/$D$10 | T20: =100*(S20-R20)/S20 | U20: =B20-$D$12*C20/100 | V20: 523 | W20: =V20*I20 | X20: =W20*9.80665/1000 | Y20: 5.8 | Z20: =W20/(Y20/10) | AA20: =J20/(PI()*$D$13^2/4*H20) | AB20: =100*(K20-J20)/O20
A21: M5 | B21: 10 | C21: =100-B21 | D21: 6.9 | E21: 6.9 | F21: 6.8 | G21: 6.8 | H21: =AVERAGE(D21:G21) | I21: =INDEX(Factor_Altura!$B$2:$B$34,MATCH(H21*10,Factor_Altura!$A$2:$A$34,1))+(H21*10-INDEX(Factor_Altura!$A$2:$A$34,MATCH(H21*10,Factor_Altura!$A$2:$A$34,1)))*(INDEX(Factor_Altura!$B$2:$B$34,MATCH(H21*10,Factor_Altura!$A$2:$A$34,1)+1)-INDEX(Factor_Altura!$B$2:$B$34,MATCH(H21*10,Factor_Altura!$A$2:$A$34,1)))/(INDEX(Factor_Altura!$A$2:$A$34,MATCH(H21*10,Factor_Altura!$A$2:$A$34,1)+1)-INDEX(Factor_Altura!$A$2:$A$34,MATCH(H21*10,Factor_Altura!$A$2:$A$34,1))) | J21: 1187 | K21: 1187 | L21: 640 | M21: 642 | N21: =AVERAGE(L21:M21) | O21: =K21-N21 | P21: =J21/O21 | Q21: =100/(B21/$D$9+C21/$D$11) | R21: =100*(Q21-P21)/Q21 | S21: =100-P21*C21/$D$10 | T21: =100*(S21-R21)/S21 | U21: =B21-$D$12*C21/100 | V21: 707.3 | W21: =V21*I21 | X21: =W21*9.80665/1000 | Y21: 6.7 | Z21: =W21/(Y21/10) | AA21: =J21/(PI()*$D$13^2/4*H21) | AB21: =100*(K21-J21)/O21
A23: VERIFICACIÓN POR BRIQUETA
A24: Muestra | B24: Pb (%) | C24: Va 3-5 % | D24: VMA ≥ mín | E24: VFA 65-75 % | F24: Estab. ≥ mín | G24: Flujo 2-4 mm | H24: Estado
A25: =A17 | B25: =B17 | C25: =IF(AND(R17>=$J$11,R17<=$K$11),"CUMPLE","NO") | D25: =IF(S17>=$J$12,"CUMPLE","NO") | E25: =IF(AND(T17>=$J$13,T17<=$K$13),"CUMPLE","NO") | F25: =IF(X17>=$J$9,"CUMPLE","NO") | G25: =IF(AND(Y17>=$J$10,Y17<=$K$10),"CUMPLE","NO") | H25: =IF(COUNTIF(C25:G25,"NO")=0,"CUMPLE","NO CUMPLE")
A26: =A18 | B26: =B18 | C26: =IF(AND(R18>=$J$11,R18<=$K$11),"CUMPLE","NO") | D26: =IF(S18>=$J$12,"CUMPLE","NO") | E26: =IF(AND(T18>=$J$13,T18<=$K$13),"CUMPLE","NO") | F26: =IF(X18>=$J$9,"CUMPLE","NO") | G26: =IF(AND(Y18>=$J$10,Y18<=$K$10),"CUMPLE","NO") | H26: =IF(COUNTIF(C26:G26,"NO")=0,"CUMPLE","NO CUMPLE")
A27: =A19 | B27: =B19 | C27: =IF(AND(R19>=$J$11,R19<=$K$11),"CUMPLE","NO") | D27: =IF(S19>=$J$12,"CUMPLE","NO") | E27: =IF(AND(T19>=$J$13,T19<=$K$13),"CUMPLE","NO") | F27: =IF(X19>=$J$9,"CUMPLE","NO") | G27: =IF(AND(Y19>=$J$10,Y19<=$K$10),"CUMPLE","NO") | H27: =IF(COUNTIF(C27:G27,"NO")=0,"CUMPLE","NO CUMPLE")
A28: =A20 | B28: =B20 | C28: =IF(AND(R20>=$J$11,R20<=$K$11),"CUMPLE","NO") | D28: =IF(S20>=$J$12,"CUMPLE","NO") | E28: =IF(AND(T20>=$J$13,T20<=$K$13),"CUMPLE","NO") | F28: =IF(X20>=$J$9,"CUMPLE","NO") | G28: =IF(AND(Y20>=$J$10,Y20<=$K$10),"CUMPLE","NO") | H28: =IF(COUNTIF(C28:G28,"NO")=0,"CUMPLE","NO CUMPLE")
A29: =A21 | B29: =B21 | C29: =IF(AND(R21>=$J$11,R21<=$K$11),"CUMPLE","NO") | D29: =IF(S21>=$J$12,"CUMPLE","NO") | E29: =IF(AND(T21>=$J$13,T21<=$K$13),"CUMPLE","NO") | F29: =IF(X21>=$J$9,"CUMPLE","NO") | G29: =IF(AND(Y21>=$J$10,Y21<=$K$10),"CUMPLE","NO") | H29: =IF(COUNTIF(C29:G29,"NO")=0,"CUMPLE","NO CUMPLE")
A31: CONTENIDO ÓPTIMO DE ASFALTO (ajuste parabólico y = a·Pb² + b·Pb + c, criterio Instituto del Asfalto MS-2)
A32: Propiedad | B32: a | C32: b | D32: c | E32: R² | F32: Pb criterio (%) | G32: Nota
A33: Gmb | B33: =INDEX(LINEST($P$17:$P$21,$B$17:$B$21^{1,2}),1,1) | C33: =INDEX(LINEST($P$17:$P$21,$B$17:$B$21^{1,2}),1,2) | D33: =INDEX(LINEST($P$17:$P$21,$B$17:$B$21^{1,2}),1,3) | E33: =INDEX(LINEST($P$17:$P$21,$B$17:$B$21^{1,2},TRUE,TRUE),3,1) | F33: =IF(AND(B33<0,-C33/(2*B33)>=MIN($B$17:$B$21),-C33/(2*B33)<=MAX($B$17:$B$21)),-C33/(2*B33),INDEX($B$17:$B$21,MATCH(MAX($P$17:$P$21),$P$17:$P$21,0))) | G33: =IF(AND(B33<0,-C33/(2*B33)>=MIN($B$17:$B$21),-C33/(2*B33)<=MAX($B$17:$B$21)),"Máximo de la parábola","Sin máximo interior: se toma el mayor Gmb medido")
A34: Va (%) | B34: =INDEX(LINEST($R$17:$R$21,$B$17:$B$21^{1,2}),1,1) | C34: =INDEX(LINEST($R$17:$R$21,$B$17:$B$21^{1,2}),1,2) | D34: =INDEX(LINEST($R$17:$R$21,$B$17:$B$21^{1,2}),1,3) | E34: =INDEX(LINEST($R$17:$R$21,$B$17:$B$21^{1,2},TRUE,TRUE),3,1) | F34: =IF((C34^2-4*B34*(D34-$J$14))<0,"N/A",IF(AND(((-C34+SQRT((C34^2-4*B34*(D34-$J$14))))/(2*B34))>=MIN($B$17:$B$21),((-C34+SQRT((C34^2-4*B34*(D34-$J$14))))/(2*B34))<=MAX($B$17:$B$21)),((-C34+SQRT((C34^2-4*B34*(D34-$J$14))))/(2*B34)),IF(AND(((-C34-SQRT((C34^2-4*B34*(D34-$J$14))))/(2*B34))>=MIN($B$17:$B$21),((-C34-SQRT((C34^2-4*B34*(D34-$J$14))))/(2*B34))<=MAX($B$17:$B$21)),((-C34-SQRT((C34^2-4*B34*(D34-$J$14))))/(2*B34)),"N/A"))) | G34: =IF(ISNUMBER(F34),"Pb para Va objetivo","Va objetivo NO se alcanza en el rango ensayado (Va mín. medido = "&TEXT(MIN($R$17:$R$21),"0.0")&" %)")
A35: VMA (%) | B35: =INDEX(LINEST($S$17:$S$21,$B$17:$B$21^{1,2}),1,1) | C35: =INDEX(LINEST($S$17:$S$21,$B$17:$B$21^{1,2}),1,2) | D35: =INDEX(LINEST($S$17:$S$21,$B$17:$B$21^{1,2}),1,3) | E35: =INDEX(LINEST($S$17:$S$21,$B$17:$B$21^{1,2},TRUE,TRUE),3,1)
A36: VFA (%) | B36: =INDEX(LINEST($T$17:$T$21,$B$17:$B$21^{1,2}),1,1) | C36: =INDEX(LINEST($T$17:$T$21,$B$17:$B$21^{1,2}),1,2) | D36: =INDEX(LINEST($T$17:$T$21,$B$17:$B$21^{1,2}),1,3) | E36: =INDEX(LINEST($T$17:$T$21,$B$17:$B$21^{1,2},TRUE,TRUE),3,1)
A37: Estabilidad (kN) | B37: =INDEX(LINEST($X$17:$X$21,$B$17:$B$21^{1,2}),1,1) | C37: =INDEX(LINEST($X$17:$X$21,$B$17:$B$21^{1,2}),1,2) | D37: =INDEX(LINEST($X$17:$X$21,$B$17:$B$21^{1,2}),1,3) | E37: =INDEX(LINEST($X$17:$X$21,$B$17:$B$21^{1,2},TRUE,TRUE),3,1) | F37: =IF(AND(B37<0,-C37/(2*B37)>=MIN($B$17:$B$21),-C37/(2*B37)<=MAX($B$17:$B$21)),-C37/(2*B37),INDEX($B$17:$B$21,MATCH(MAX($X$17:$X$21),$X$17:$X$21,0))) | G37: =IF(AND(B37<0,-C37/(2*B37)>=MIN($B$17:$B$21),-C37/(2*B37)<=MAX($B$17:$B$21)),"Máximo de la parábola","Sin máximo interior: se toma la mayor estabilidad medida")
A38: Flujo (mm) | B38: =INDEX(LINEST($Y$17:$Y$21,$B$17:$B$21^{1,2}),1,1) | C38: =INDEX(LINEST($Y$17:$Y$21,$B$17:$B$21^{1,2}),1,2) | D38: =INDEX(LINEST($Y$17:$Y$21,$B$17:$B$21^{1,2}),1,3) | E38: =INDEX(LINEST($Y$17:$Y$21,$B$17:$B$21^{1,2},TRUE,TRUE),3,1)
A40: Pb óptimo calculado (promedio de criterios disponibles) | F40: =AVERAGE(F33,F37,F34) | G40: =IF(ISNUMBER(F34),"Promedio de 3 criterios","PROVISIONAL: solo promedio de máx. Gmb y máx. estabilidad")
A41: Pb de diseño adoptado (editable; por defecto = calculado) | F41: =ROUND(F40*10,0)/10
A43: VERIFICACIÓN EN EL Pb DE DISEÑO (valores leídos de las curvas ajustadas)
A44: Propiedad | B44: Valor | C44: Especificación | D44: Resultado
A45: Gmb | B45: =B33*$F$41^2+C33*$F$41+D33 | C45: - | D45: ="-"
A46: Va (%) | B46: =B34*$F$41^2+C34*$F$41+D34 | C46: =TEXT($J$11,"0")&" - "&TEXT($K$11,"0")&" %" | D46: =IF(AND(B46>=$J$11,B46<=$K$11),"CUMPLE","NO CUMPLE")
...

Sheet Graficas_Marshall
A1: DISEÑO DE MEZCLAS ASFÁLTICAS EN CALIENTE - GRÁFICAS MARSHALL

Sheet EJEMPLO_SIMULADO
A1: LABORATORIO DE ASFALTOS
A2: DISEÑO DE MEZCLAS ASFÁLTICAS EN CALIENTE - MÉTODO MARSHALL
A3: Proyecto: | C3: EJEMPLO ILUSTRATIVO con datos simulados (no es el ensayo del grupo)
A4: Mezcla: | C4: MAC-2 típica (valores supuestos)
A5: C.A.: | C5: PEN 120-150 (Gb supuesto)
A6: Compactación: | C6: 50 golpes por cara
A7: EJEMPLO ILUSTRATIVO – DATOS SIMULADOS, NO CORRESPONDEN AL ENSAYO
A8: PARÁMETROS DE DISEÑO (celdas amarillas editables) | G8: ESPECIFICACIONES (EG-2013, Clase B) | J8: Mín. | K8: Máx.
A9: Gb - Peso específico del asfalto | D9: 1.023 | G9: Estabilidad mínima (kN) | J9: 5.44
A10: Gsb - Peso esp. bulk agregado combinado | D10: 2.565 | G10: Flujo (mm) | J10: 2 | K10: 4
A11: Gse - Peso esp. efectivo del agregado | D11: 2.66 | G11: Vacíos de aire Va (%) | J11: 3 | K11: 5
A12: Pba - % asfalto absorbido (% peso agregado) | D12: =100*D9*(D11-D10)/(D10*D11) | G12: VMA mínimo (%) - TMN 12.5 mm | J12: 14
A13: Diámetro de briqueta (cm) | D13: 10.16 | G13: VFA (%) | J13: 65 | K13: 75
G14: Va objetivo para óptimo (%) | J14: 4
A16: Muestra | B16: Pb (%) | C16: Ps (%) | D16: h1 (cm) | E16: h2 (cm) | F16: h3 (cm) | G16: h4 (cm) | H16: h prom. (cm) | I16: Factor correc. | J16: Peso seco aire (g) | K16: Peso SSS (g) | L16: Sumerg. 1 (g) | M16: Sumerg. 2 (g) | N16: Sumerg. prom. (g) | O16: Vol. bulk (cc) | P16: Gmb | Q16: Gmm teórica | R16: Va (%) | S16: VMA (%) | T16: VFA (%) | U16: Pbe (%) | V16: Estab. leída (kg) | W16: Estab. correg. (kg) | X16: Estab. correg. (kN) | Y16: Flujo (mm) | Z16: Est./Flujo (kg/cm) | AA16: Densidad geom. | AB16: Absorción agua (%)
A17: S1 | B17: 5 | C17: =100-B17 | D17: 6.53 | E17: 6.52 | F17: 6.49 | G17: 6.49 | H17: =AVERAGE(D17:G17) | I17: =INDEX(Factor_Altura!$B$2:$B$34,MATCH(H17*10,Factor_Altura!$A$2:$A$34,1))+(H17*10-INDEX(Factor_Altura!$A$2:$A$34,MATCH(H17*10,Factor_Altura!$A$2:$A$34,1)))*(INDEX(Factor_Altura!$B$2:$B$34,MATCH(H17*10,Factor_Altura!$A$2:$A$34,1)+1)-INDEX(Factor_Altura!$B$2:$B$34,MATCH(H17*10,Factor_Altura!$A$2:$A$34,1)))/(INDEX(Factor_Altura!$A$2:$A$34,MATCH(H17*10,Factor_Altura!$A$2:$A$34,1)+1)-INDEX(Factor_Altura!$A$2:$A$34,MATCH(H17*10,Factor_Altura!$A$2:$A$34,1))) | J17: 1204.5 | K17: 1206.1 | L17: 685.3 | M17: 684.7 | N17: =AVERAGE(L17:M17) | O17: =K17-N17 | P17: =J17/O17 | Q17: =100/(B17/$D$9+C17/$D$11) | R17: =100*(Q17-P17)/Q17 | S17: =100-P17*C17/$D$10 | T17: =100*(S17-R17)/S17 | U17: =B17-$D$12*C17/100 | V17: 985.2 | W17: =V17*I17 | X17: =W17*9.80665/1000 | Y17: 2.5 | Z17: =W17/(Y17/10) | AA17: =J17/(PI()*$D$13^2/4*H17) | AB17: =100*(K17-J17)/O17
A18: S2 | B18: 5 | C18: =100-B18 | D18: 6.46 | E18: 6.48 | F18: 6.48 | G18: 6.48 | H18: =AVERAGE(D18:G18) | I18: =INDEX(Factor_Altura!$B$2:$B$34,MATCH(H18*10,Factor_Altura!$A$2:$A$34,1))+(H18*10-INDEX(Factor_Altura!$A$2:$A$34,MATCH(H18*10,Factor_Altura!$A$2:$A$34,1)))*(INDEX(Factor_Altura!$B$2:$B$34,MATCH(H18*10,Factor_Altura!$A$2:$A$34,1)+1)-INDEX(Factor_Altura!$B$2:$B$34,MATCH(H18*10,Factor_Altura!$A$2:$A$34,1)))/(INDEX(Factor_Altura!$A$2:$A$34,MATCH(H18*10,Factor_Altura!$A$2:$A$34,1)+1)-INDEX(Factor_Altura!$A$2:$A$34,MATCH(H18*10,Factor_Altura!$A$2:$A$34,1))) | J18: 1205.9 | K18: 1207.2 | L18: 684.6 | M18: 683.8 | N18: =AVERAGE(L18:M18) | O18: =K18-N18 | P18: =J18/O18 | Q18: =100/(B18/$D$9+C18/$D$11) | R18: =100*(Q18-P18)/Q18 | S18: =100-P18*C18/$D$10 | T18: =100*(S18-R18)/S18 | U18: =B18-$D$12*C18/100 | V18: 960.9 | W18: =V18*I18 | X18: =W18*9.80665/1000 | Y18: 2.5 | Z18: =W18/(Y18/10) | AA18: =J18/(PI()*$D$13^2/4*H18) | AB18: =100*(K18-J18)/O18
A19: S3 | B19: 5 | C19: =100-B19 | D19: 6.48 | E19: 6.48 | F19: 6.5 | G19: 6.5 | H19: =AVERAGE(D19:G19) | I19: =INDEX(Factor_Altura!$B$2:$B$34,MATCH(H19*10,Factor_Altura!$A$2:$A$34,1))+(H19*10-INDEX(Factor_Altura!$A$2:$A$34,MATCH(H19*10,Factor_Altura!$A$2:$A$34,1)))*(INDEX(Factor_Altura!$B$2:$B$34,MATCH(H19*10,Factor_Altura!$A$2:$A$34,1)+1)-INDEX(Factor_Altura!$B$2:$B$34,MATCH(H19*10,Factor_Altura!$A$2:$A$34,1)))/(INDEX(Factor_Altura!$A$2:$A$34,MATCH(H19*10,Factor_Altura!$A$2:$A$34,1)+1)-INDEX(Factor_Altura!$A$2:$A$34,MATCH(H19*10,Factor_Altura!$A$2:$A$34,1))) | J19: 1205 | K19: 1206.2 | L19: 684.1 | M19: 683.6 | N19: =AVERAGE(L19:M19) | O19: =K19-N19 | P19: =J19/O19 | Q19: =100/(B19/$D$9+C19/$D$11) | R19: =100*(Q19-P19)/Q19 | S19: =100-P19*C19/$D$10 | T19: =100*(S19-R19)/S19 | U19: =B19-$D$12*C19/100 | V19: 966.7 | W19: =V19*I19 | X19: =W19*9.80665/1000 | Y19: 2.5 | Z19: =W19/(Y19/10) | AA19: =J19/(PI()*$D$13^2/4*H19) | AB19: =100*(K19-J19)/O19
A20: S4 | B20: 5.5 | C20: =100-B20 | D20: 6.48 | E20: 6.46 | F20: 6.47 | G20: 6.44 | H20: =AVERAGE(D20:G20) | I20: =INDEX(Factor_Altura!$B$2:$B$34,MATCH(H20*10,Factor_Altura!$A$2:$A$34,1))+(H20*10-INDEX(Factor_Altura!$A$2:$A$34,MATCH(H20*10,Factor_Altura!$A$2:$A$34,1)))*(INDEX(Factor_Altura!$B$2:$B$34,MATCH(H20*10,Factor_Altura!$A$2:$A$34,1)+1)-INDEX(Factor_Altura!$B$2:$B$34,MATCH(H20*10,Factor_Altura!$A$2:$A$34,1)))/(INDEX(Factor_Altura!$A$2:$A$34,MATCH(H20*10,Factor_Altura!$A$2:$A$34,1)+1)-INDEX(Factor_Altura!$A$2:$A$34,MATCH(H20*10,Factor_Altura!$A$2:$A$34,1))) | J20: 1204 | K20: 1204.9 | L20: 687.4 | M20: 686.7 | N20: =AVERAGE(L20:M20) | O20: =K20-N20 | P20: =J20/O20 | Q20: =100/(B20/$D$9+C20/$D$11) | R20: =100*(Q20-P20)/Q20 | S20: =100-P20*C20/$D$10 | T20: =100*(S20-R20)/S20 | U20: =B20-$D$12*C20/100 | V20: 1070.8 | W20: =V20*I20 | X20: =W20*9.80665/1000 | Y20: 3 | Z20: =W20/(Y20/10) | AA20: =J20/(PI()*$D$13^2/4*H20) | AB20: =100*(K20-J20)/O20
A21: S5 | B21: 5.5 | C21: =100-B21 | D21: 6.52 | E21: 6.48 | F21: 6.51 | G21: 6.51 | H21: =AVERAGE(D21:G21) | I21: =INDEX(Factor_Altura!$B$2:$B$34,MATCH(H21*10,Factor_Altura!$A$2:$A$34,1))+(H21*10-INDEX(Factor_Altura!$A$2:$A$34,MATCH(H21*10,Factor_Altura!$A$2:$A$34,1)))*(INDEX(Factor_Altura!$B$2:$B$34,MATCH(H21*10,Factor_Altura!$A$2:$A$34,1)+1)-INDEX(Factor_Altura!$B$2:$B$34,MATCH(H21*10,Factor_Altura!$A$2:$A$34,1)))/(INDEX(Factor_Altura!$A$2:$A$34,MATCH(H21*10,Factor_Altura!$A$2:$A$34,1)+1)-INDEX(Factor_Altura!$A$2:$A$34,MATCH(H21*10,Factor_Altura!$A$2:$A$34,1))) | J21: 1204.5 | K21: 1205.8 | L21: 687.5 | M21: 687.3 | N21: =AVERAGE(L21:M21) | O21: =K21-N21 | P21: =J21/O21 | Q21: =100/(B21/$D$9+C21/$D$11) | R21: =100*(Q21-P21)/Q21 | S21: =100-P21*C21/$D$10 | T21: =100*(S21-R21)/S21 | U21: =B21-$D$12*C21/100 | V21: 1074.9 | W21: =V21*I21 | X21: =W21*9.80665/1000 | Y21: 2.8 | Z21: =W21/(Y21/10) | AA21: =J21/(PI()*$D$13^2/4*H21) | AB21: =100*(K21-J21)/O21
A22: S6 | B22: 5.5 | C22: =100-B22 | D22: 6.49 | E22: 6.46 | F22: 6.5 | G22: 6.48 | H22: =AVERAGE(D22:G22) | I22: =INDEX(Factor_Altura!$B$2:$B$34,MATCH(H22*10,Factor_Altura!$A$2:$A$34,1))+(H22*10-INDEX(Factor_Altura!$A$2:$A$34,MATCH(H22*10,Factor_Altura!$A$2:$A$34,1)))*(INDEX(Factor_Altura!$B$2:$B$34,MATCH(H22*10,Factor_Altura!$A$2:$A$34,1)+1)-INDEX(Factor_Altura!$B$2:$B$34,MATCH(H22*10,Factor_Altura!$A$2:$A$34,1)))/(INDEX(Factor_Altura!$A$2:$A$34,MATCH(H22*10,Factor_Altura!$A$2:$A$34,1)+1)-INDEX(Factor_Altura!$A$2:$A$34,MATCH(H22*10,Factor_Altura!$A$2:$A$34,1))) | J22: 1201.3 | K22: 1202.7 | L22: 685.4 | M22: 685.1 | N22: =AVERAGE(L22:M22) | O22: =K22-N22 | P22: =J22/O22 | Q22: =100/(B22/$D$9+C22/$D$11) | R22: =100*(Q22-P22)/Q22 | S22: =100-P22*C22/$D$10 | T22: =100*(S22-R22)/S22 | U22: =B22-$D$12*C22/100 | V22: 1072 | W22: =V22*I22 | X22: =W22*9.80665/1000 | Y22: 2.8 | Z22: =W22/(Y22/10) | AA22: =J22/(PI()*$D$13^2/4*H22) | AB22: =100*(K22-J22)/O22
A23: S7 | B23: 6 | C23: =100-B23 | D23: 6.46 | E23: 6.52 | F23: 6.47 | G23: 6.5 | H23: =AVERAGE(D23:G23) | I23: =INDEX(Factor_Altura!$B$2:$B$34,MATCH(H23*10,Factor_Altura!$A$2:$A$34,1))+(H23*10-INDEX(Factor_Altura!$A$2:$A$34,MATCH(H23*10,Factor_Altura!$A$2:$A$34,1)))*(INDEX(Factor_Altura!$B$2:$B$34,MATCH(H23*10,Factor_Altura!$A$2:$A$34,1)+1)-INDEX(Factor_Altura!$B$2:$B$34,MATCH(H23*10,Factor_Altura!$A$2:$A$34,1)))/(INDEX(Factor_Altura!$A$2:$A$34,MATCH(H23*10,Factor_Altura!$A$2:$A$34,1)+1)-INDEX(Factor_Altura!$A$2:$A$34,MATCH(H23*10,Factor_Altura!$A$2:$A$34,1))) | J23: 1197.6 | K23: 1199 | L23: 684.8 | M23: 684.5 | N23: =AVERAGE(L23:M23) | O23: =K23-N23 | P23: =J23/O23 | Q23: =100/(B23/$D$9+C23/$D$11) | R23: =100*(Q23-P23)/Q23 | S23: =100-P23*C23/$D$10 | T23: =100*(S23-R23)/S23 | U23: =B23-$D$12*C23/100 | V23: 1130.7 | W23: =V23*I23 | X23: =W23*9.80665/1000 | Y23: 3.3 | Z23: =W23/(Y23/10) | AA23: =J23/(PI()*$D$13^2/4*H23) | AB23: =100*(K23-J23)/O23
A24: S8 | B24: 6 | C24: =100-B24 | D24: 6.53 | E24: 6.5 | F24: 6.5 | G24: 6.55 | H24: =AVERAGE(D24:G24) | I24: =INDEX(Factor_Altura!$B$2:$B$34,MATCH(H24*10,Factor_Altura!$A$2:$A$34,1))+(H24*10-INDEX(Factor_Altura!$A$2:$A$34,MATCH(H24*10,Factor_Altura!$A$2:$A$34,1)))*(INDEX(Factor_Altura!$B$2:$B$34,MATCH(H24*10,Factor_Altura!$A$2:$A$34,1)+1)-INDEX(Factor_Altura!$B$2:$B$34,MATCH(H24*10,Factor_Altura!$A$2:$A$34,1)))/(INDEX(Factor_Altura!$A$2:$A$34,MATCH(H24*10,Factor_Altura!$A$2:$A$34,1)+1)-INDEX(Factor_Altura!$A$2:$A$34,MATCH(H24*10,Factor_Altura!$A$2:$A$34,1))) | J24: 1200.6 | K24: 1202.3 | L24: 688.1 | M24: 687.5 | N24: =AVERAGE(L24:M24) | O24: =K24-N24 | P24: =J24/O24 | Q24: =100/(B24/$D$9+C24/$D$11) | R24: =100*(Q24-P24)/Q24 | S24: =100-P24*C24/$D$10 | T24: =100*(S24-R24)/S24 | U24: =B24-$D$12*C24/100 | V24: 1121.9 | W24: =V24*I24 | X24: =W24*9.80665/1000 | Y24: 3.2 | Z24: =W24/(Y24/10) | AA24: =J24/(PI()*$D$13^2/4*H24) | AB24: =100*(K24-J24)/O24
A25: S9 | B25: 6 | C25: =100-B25 | D25: 6.47 | E25: 6.46 | F25: 6.51 | G25: 6.49 | H25: =AVERAGE(D25:G25) | I25: =INDEX(Factor_Altura!$B$2:$B$34,MATCH(H25*10,Factor_Altura!$A$2:$A$34,1))+(H25*10-INDEX(Factor_Altura!$A$2:$A$34,MATCH(H25*10,Factor_Altura!$A$2:$A$34,1)))*(INDEX(Factor_Altura!$B$2:$B$34,MATCH(H25*10,Factor_Altura!$A$2:$A$34,1)+1)-INDEX(Factor_Altura!$B$2:$B$34,MATCH(H25*10,Factor_Altura!$A$2:$A$34,1)))/(INDEX(Factor_Altura!$A$2:$A$34,MATCH(H25*10,Factor_Altura!$A$2:$A$34,1)+1)-INDEX(Factor_Altura!$A$2:$A$34,MATCH(H25*10,Factor_Altura!$A$2:$A$34,1))) | J25: 1200.6 | K25: 1202.1 | L25: 687.5 | M25: 687.2 | N25: =AVERAGE(L25:M25) | O25: =K25-N25 | P25: =J25/O25 | Q25: =100/(B25/$D$9+C25/$D$11) | R25: =100*(Q25-P25)/Q25 | S25: =100-P25*C25/$D$10 | T25: =100*(S25-R25)/S25 | U25: =B25-$D$12*C25/100 | V25: 1099.3 | W25: =V25*I25 | X25: =W25*9.80665/1000 | Y25: 3.1 | Z25: =W25/(Y25/10) | AA25: =J25/(PI()*$D$13^2/4*H25) | AB25: =100*(K25-J25)/O25
A26: S10 | B26: 6.5 | C26: =100-B26 | D26: 6.5 | E26: 6.48 | F26: 6.46 | G26: 6.47 | H26: =AVERAGE(D26:G26) | I26: =INDEX(Factor_Altura!$B$2:$B$34,MATCH(H26*10,Factor_Altura!$A$2:$A$34,1))+(H26*10-INDEX(Factor_Altura!$A$2:$A$34,MATCH(H26*10,Factor_Altura!$A$2:$A$34,1)))*(INDEX(Factor_Altura!$B$2:$B$34,MATCH(H26*10,Factor_Altura!$A$2:$A$34,1)+1)-INDEX(Factor_Altura!$B$2:$B$34,MATCH(H26*10,Factor_Altura!$A$2:$A$34,1)))/(INDEX(Factor_Altura!$A$2:$A$34,MATCH(H26*10,Factor_Altura!$A$2:$A$34,1)+1)-INDEX(Factor_Altura!$A$2:$A$34,MATCH(H26*10,Factor_Altura!$A$2:$A$34,1))) | J26: 1204.5 | K26: 1205.8 | L26: 689.9 | M26: 689.3 | N26: =AVERAGE(L26:M26) | O26: =K26-N26 | P26: =J26/O26 | Q26: =100/(B26/$D$9+C26/$D$11) | R26: =100*(Q26-P26)/Q26 | S26: =100-P26*C26/$D$10 | T26: =100*(S26-R26)/S26 | U26: =B26-$D$12*C26/100 | V26: 1044.2 | W26: =V26*I26 | X26: =W26*9.80665/1000 | Y26: 3.6 | Z26: =W26/(Y26/10) | AA26: =J26/(PI()*$D$13^2/4*H26) | AB26: =100*(K26-J26)/O26
A27: S11 | B27: 6.5 | C27: =100-B27 | D27: 6.54 | E27: 6.49 | F27: 6.54 | G27: 6.48 | H27: =AVERAGE(D27:G27) | I27: =INDEX(Factor_Altura!$B$2:$B$34,MATCH(H27*10,Factor_Altura!$A$2:$A$34,1))+(H27*10-INDEX(Factor_Altura!$A$2:$A$34,MATCH(H27*10,Factor_Altura!$A$2:$A$34,1)))*(INDEX(Factor_Altura!$B$2:$B$34,MATCH(H27*10,Factor_Altura!$A$2:$A$34,1)+1)-INDEX(Factor_Altura!$B$2:$B$34,MATCH(H27*10,Factor_Altura!$A$2:$A$34,1)))/(INDEX(Factor_Altura!$A$2:$A$34,MATCH(H27*10,Factor_Altura!$A$2:$A$34,1)+1)-INDEX(Factor_Altura!$A$2:$A$34,MATCH(H27*10,Factor_Altura!$A$2:$A$34,1))) | J27: 1203 | K27: 1203.8 | L27: 687.7 | M27: 687.3 | N27: =AVERAGE(L27:M27) | O27: =K27-N27 | P27: =J27/O27 | Q27: =100/(B27/$D$9+C27/$D$11) | R27: =100*(Q27-P27)/Q27 | S27: =100-P27*C27/$D$10 | T27: =100*(S27-R27)/S27 | U27: =B27-$D$12*C27/100 | V27: 1082.8 | W27: =V27*I27 | X27: =W27*9.80665/1000 | Y27: 3.5 | Z27: =W27/(Y27/10) | AA27: =J27/(PI()*$D$13^2/4*H27) | AB27: =100*(K27-J27)/O27
A28: S12 | B28: 6.5 | C28: =100-B28 | D28: 6.52 | E28: 6.5 | F28: 6.52 | G28: 6.49 | H28: =AVERAGE(D28:G28) | I28: =INDEX(Factor_Altura!$B$2:$B$34,MATCH(H28*10,Factor_Altura!$A$2:$A$34,1))+(H28*10-INDEX(Factor_Altura!$A$2:$A$34,MATCH(H28*10,Factor_Altura!$A$2:$A$34,1)))*(INDEX(Factor_Altura!$B$2:$B$34,MATCH(H28*10,Factor_Altura!$A$2:$A$34,1)+1)-INDEX(Factor_Altura!$B$2:$B$34,MATCH(H28*10,Factor_Altura!$A$2:$A$34,1)))/(INDEX(Factor_Altura!$A$2:$A$34,MATCH(H28*10,Factor_Altura!$A$2:$A$34,1)+1)-INDEX(Factor_Altura!$A$2:$A$34,MATCH(H28*10,Factor_Altura!$A$2:$A$34,1))) | J28: 1196.4 | K28: 1197.2 | L28: 684.6 | M28: 684.2 | N28: =AVERAGE(L28:M28) | O28: =K28-N28 | P28: =J28/O28 | Q28: =100/(B28/$D$9+C28/$D$11) | R28: =100*(Q28-P28)/Q28 | S28: =100-P28*C28/$D$10 | T28: =100*(S28-R28)/S28 | U28: =B28-$D$12*C28/100 | V28: 1090.1 | W28: =V28*I28 | X28: =W28*9.80665/1000 | Y28: 3.6 | Z28: =W28/(Y28/10) | AA28: =J28/(PI()*$D$13^2/4*H28) | AB28: =100*(K28-J28)/O28
... A31: S15 | B31: 7 | C31: =100-B31 | D31: 6.53 | E31: 6.49 | F31: 6.5 | G31: 6.49 | H31: =AVERAGE(D31:G31) | I31: =INDEX(Factor_Altura!$B$2:$B$34,MATCH(H31*10,Factor_Altura!$A$2:$A$34,1))+(H31*10-INDEX(Factor_Altura!$A$2:$A$34,MATCH(H31*10,Factor_Altura!$A$2:$A$34,1)))*(INDEX(Factor_Altura!$B$2:$B$34,MATCH(H31*10,Factor_Altura!$A$2:$A$34,1)+1)-INDEX(Factor_Altura!$B$2:$B$34,MATCH(H31*10,Factor_Altura!$A$2:$A$34,1)))/(INDEX(Factor_Altura!$A$2:$A$34,MATCH(H31*10,Factor_Altura!$A$2:$A$34,1)+1)-INDEX(Factor_Altura!$A$2:$A$34,MATCH(H31*10,Factor_Altura!$A$2:$A$34,1))) | J31: 1194.6 | K31: 1196.3 | L31: 683.8 | M31: 683.1 | N31: =AVERAGE(L31:M31) | O31: =K31-N31 | P31: =J31/O31 | Q31: =100/(B31/$D$9+C31/$D$11) | R31: =100*(Q31-P31)/Q31 | S31: =100-P31*C31/$D$10 | T31: =100*(S31-R31)/S31 | U31: =B31-$D$12*C31/100 | V31: 940.1 | W31: =V31*I31 | X31: =W31*9.80665/1000 | Y31: 4 | Z31: =W31/(Y31/10) | AA31: =J31/(PI()*$D$13^2/4*H31) | AB31: =100*(K31-J31)/O31
A33: VERIFICACIÓN POR BRIQUETA
A34: Muestra | B34: Pb (%) | C34: Va 3-5 % | D34: VMA ≥ mín | E34: VFA 65-75 % | F34: Estab. ≥ mín | G34: Flujo 2-4 mm | H34: Estado
A35: =A17 | B35: =B17 | C35: =IF(AND(R17>=$J$11,R17<=$K$11),"CUMPLE","NO") | D35: =IF(S17>=$J$12,"CUMPLE","NO") | E35: =IF(AND(T17>=$J$13,T17<=$K$13),"CUMPLE","NO") | F35: =IF(X17>=$J$9,"CUMPLE","NO") | G35: =IF(AND(Y17>=$J$10,Y17<=$K$10),"CUMPLE","NO") | H35: =IF(COUNTIF(C35:G35,"NO")=0,"CUMPLE","NO CUMPLE")
A36: =A18 | B36: =B18 | C36: =IF(AND(R18>=$J$11,R18<=$K$11),"CUMPLE","NO") | D36: =IF(S18>=$J$12,"CUMPLE","NO") | E36: =IF(AND(T18>=$J$13,T18<=$K$13),"CUMPLE","NO") | F36: =IF(X18>=$J$9,"CUMPLE","NO") | G36: =IF(AND(Y18>=$J$10,Y18<=$K$10),"CUMPLE","NO") | H36: =IF(COUNTIF(C36:G36,"NO")=0,"CUMPLE","NO CUMPLE")
A37: =A19 | B37: =B19 | C37: =IF(AND(R19>=$J$11,R19<=$K$11),"CUMPLE","NO") | D37: =IF(S19>=$J$12,"CUMPLE","NO") | E37: =IF(AND(T19>=$J$13,T19<=$K$13),"CUMPLE","NO") | F37: =IF(X19>=$J$9,"CUMPLE","NO") | G37: =IF(AND(Y19>=$J$10,Y19<=$K$10),"CUMPLE","NO") | H37: =IF(COUNTIF(C37:G37,"NO")=0,"CUMPLE","NO CUMPLE")
A38: =A20 | B38: =B20 | C38: =IF(AND(R20>=$J$11,R20<=$K$11),"CUMPLE","NO") | D38: =IF(S20>=$J$12,"CUMPLE","NO") | E38: =IF(AND(T20>=$J$13,T20<=$K$13),"CUMPLE","NO") | F38: =IF(X20>=$J$9,"CUMPLE","NO") | G38: =IF(AND(Y20>=$J$10,Y20<=$K$10),"CUMPLE","NO") | H38: =IF(COUNTIF(C38:G38,"NO")=0,"CUMPLE","NO CUMPLE")
A39: =A21 | B39: =B21 | C39: =IF(AND(R21>=$J$11,R21<=$K$11),"CUMPLE","NO") | D39: =IF(S21>=$J$12,"CUMPLE","NO") | E39: =IF(AND(T21>=$J$13,T21<=$K$13),"CUMPLE","NO") | F39: =IF(X21>=$J$9,"CUMPLE","NO") | G39: =IF(AND(Y21>=$J$10,Y21<=$K$10),"CUMPLE","NO") | H39: =IF(COUNTIF(C39:G39,"NO")=0,"CUMPLE","NO CUMPLE")
A40: =A22 | B40: =B22 | C40: =IF(AND(R22>=$J$11,R22<=$K$11),"CUMPLE","NO") | D40: =IF(S22>=$J$12,"CUMPLE","NO") | E40: =IF(AND(T22>=$J$13,T22<=$K$13),"CUMPLE","NO") | F40: =IF(X22>=$J$9,"CUMPLE","NO") | G40: =IF(AND(Y22>=$J$10,Y22<=$K$10),"CUMPLE","NO") | H40: =IF(COUNTIF(C40:G40,"NO")=0,"CUMPLE","NO CUMPLE")
A41: =A23 | B41: =B23 | C41: =IF(AND(R23>=$J$11,R23<=$K$11),"CUMPLE","NO") | D41: =IF(S23>=$J$12,"CUMPLE","NO") | E41: =IF(AND(T23>=$J$13,T23<=$K$13),"CUMPLE","NO") | F41: =IF(X23>=$J$9,"CUMPLE","NO") | G41: =IF(AND(Y23>=$J$10,Y23<=$K$10),"CUMPLE","NO") | H41: =IF(COUNTIF(C41:G41,"NO")=0,"CUMPLE","NO CUMPLE")
A42: =A24 | B42: =B24 | C42: =IF(AND(R24>=$J$11,R24<=$K$11),"CUMPLE","NO") | D42: =IF(S24>=$J$12,"CUMPLE","NO") | E42: =IF(AND(T24>=$J$13,T24<=$K$13),"CUMPLE","NO") | F42: =IF(X24>=$J$9,"CUMPLE","NO") | G42: =IF(AND(Y24>=$J$10,Y24<=$K$10),"CUMPLE","NO") | H42: =IF(COUNTIF(C42:G42,"NO")=0,"CUMPLE","NO CUMPLE")
A43: =A25 | B43: =B25 | C43: =IF(AND(R25>=$J$11,R25<=$K$11),"CUMPLE","NO") | D43: =IF(S25>=$J$12,"CUMPLE","NO") | E43: =IF(AND(T25>=$J$13,T25<=$K$13),"CUMPLE","NO") | F43: =IF(X25>=$J$9,"CUMPLE","NO") | G43: =IF(AND(Y25>=$J$10,Y25<=$K$10),"CUMPLE","NO") | H43: =IF(COUNTIF(C43:G43,"NO")=0,"CUMPLE","NO CUMPLE")
A44: =A26 | B44: =B26 | C44: =IF(AND(R26>=$J$11,R26<=$K$11),"CUMPLE","NO") | D44: =IF(S26>=$J$12,"CUMPLE","NO") | E44: =IF(AND(T26>=$J$13,T26<=$K$13),"CUMPLE","NO") | F44: =IF(X26>=$J$9,"CUMPLE","NO") | G44: =IF(AND(Y26>=$J$10,Y26<=$K$10),"CUMPLE","NO") | H44: =IF(COUNTIF(C44:G44,"NO")=0,"CUMPLE","NO CUMPLE")
...

Sheet Graficas_EJEMPLO_SIMULADO
A1: DISEÑO DE MEZCLAS ASFÁLTICAS EN CALIENTE - GRÁFICAS MARSHALL
A2: EJEMPLO ILUSTRATIVO – DATOS SIMULADOS, NO CORRESPONDEN AL ENSAYO

Sheet Factor_Altura
A1: Altura (mm) | B1: Factor corrección | D1: Fuente: MTC E 504 / ASTM D6927 (interpolación lineal).
A2: 25.4 | B2: 5.56
A3: 27 | B3: 5
A4: 28.6 | B4: 4.55
A5: 30.2 | B5: 4.17
A6: 31.8 | B6: 3.85
A7: 33.3 | B7: 3.57
A8: 34.9 | B8: 3.33
A9: 36.5 | B9: 3.03
A10: 38.1 | B10: 2.78
A11: 39.7 | B11: 2.5
A12: 41.3 | B12: 2.27
A13: 42.9 | B13: 2.08
... A34: 76.2 | B34: 0.76
