Workbook

Sheet INSTRUCCIONES
A1: SUPERHERRAMIENTA LAST PLANNER SYSTEM (LPS)
B3: LEYENDA
B4: Celda amarilla / texto azul | C4: Dato de entrada: se llena a mano o con lista desplegable.
B5: Celda gris / texto negro | C5: Fórmula: no editar (se calcula sola).
B7: PESTAÑAS
B8: LISTAS | C8: Catálogos de los desplegables: responsables, cuadrillas, tipos de restricción, causas de incumplimiento. Agregue filas dentro del rango.
B9: MASTER | C9: Plan Maestro: hitos (fechas contractuales vs proyectadas) y fases macro con duración, responsable, % de avance y Gantt mensual.
B10: LOOKAHEAD | C10: Ventana de 6 semanas. Cada actividad cuelga de una Fase (ID Fase). Su estado pasa a LISTA solo cuando no tiene restricciones pendientes.
B11: RESTRICCIONES | C11: Análisis de restricciones (1 actividad → N restricciones). Responsable único, fecha comprometida y fecha real. Estado = Liberado al ingresar la fecha real.
B12: SEMANAL | C12: Plan operativo lunes–sábado (programado vs ejecutado por día). Solo acepta actividades en estado LISTA. Calcula ¿Cumplió? y el PPC; exige causa si no se cumplió.
B13: DASHBOARD | C13: PPC semanal y acumulado, Pareto de causas, PPC por cuadrilla y salud de restricciones.
B15: CONEXIONES
B16: MASTER → LOOKAHEAD | C16: LOOKAHEAD!C (ID Fase). El % de avance de la fase se promedia desde LOOKAHEAD.
B17: LOOKAHEAD ⇄ RESTRICCIONES | C17: RESTRICCIONES!B (ID Actividad). LOOKAHEAD cuenta restricciones pendientes y define LISTA / RESTRINGIDA.
B18: LOOKAHEAD → SEMANAL | C18: SEMANAL!C valida que la actividad esté LISTA (escudo del plan). Lo ejecutado vuelve como % avance a LOOKAHEAD y de ahí a MASTER.
B19: SEMANAL → DASHBOARD | C19: Tabla acumulada: cada fila lleva su N° de semana; el DASHBOARD agrupa por semana, causa y cuadrilla.
B21: CICLO SEMANAL
B22: 1. Medir | C22: Cerrar la semana: completar ejecutado diario, revisar ¿Cumplió? y registrar causas + acción correctiva.
B23: 2. Aprender | C23: Revisar PPC y Pareto de causas en DASHBOARD (análisis 5 porqués de la causa principal).
B24: 3. Avanzar ventana | C24: Actualizar LOOKAHEAD!B2 si no usa la fecha automática; agregar actividades de la nueva semana 6.
B25: 4. Liberar | C25: Revisar RESTRICCIONES vencidas / en riesgo con cada responsable; registrar fechas reales.
B26: 5. Comprometer | C26: Armar el plan de la próxima semana en SEMANAL solo con actividades LISTA; compromiso de cada capataz.
B28: NOTA | C28: Las filas con datos de ejemplo (obra edificio 5 pisos) muestran el formato esperado: reemplácelas por las de su proyecto. Las fórmulas están precargadas hasta: LOOKAHEAD 200 filas, RESTRICCIONES 300, SEMANAL 500.

Sheet LISTAS
A1: LISTAS / CATÁLOGOS | D1: Agregue elementos dentro de cada columna (hasta la fila 41).
A3: Responsables | B3: Cuadrillas | C3: TipoRestriccion | D3: Causas | E3: Unidades
A4: Ing. Residente | B4: Cuadrilla Excavación | C4: Permisos / Licencias | D4: Clima | E4: m2
A5: Jefe de Terreno | B5: Cuadrilla Enfierradura | C5: Materiales | D5: Falta de material | E5: m3
A6: Oficina Técnica | B6: Cuadrilla Moldajes | C6: Mano de obra | D6: Falta de mano de obra | E6: ml
A7: Bodega / Adquisiciones | B7: Cuadrilla Hormigón | C7: Subcontratos | D7: Interferencias entre cuadrillas | E7: kg
A8: Prevención de Riesgos | B8: Cuadrilla Albañilería | C8: Diseño / Ingeniería (RFI) | D8: Falta de equipos / maquinaria | E8: und
A9: Calidad | B9: Subc. Eléctrico | C9: Equipos / Maquinaria | D9: Actividad previa no terminada | E9: gl
A10: Administrador de Obra | B10: Subc. Sanitario | C10: Espacio / Frente de trabajo | D10: Cambio de prioridades
A11: Arquitecto / Proyectista | B11: Subc. Climatización | C11: Actividad previa | D11: Error de planificación
B12: Subc. Terminaciones | C12: Información / Aprobación cliente | D12: Diseño / información incompleta
C13: Seguridad / Calidad | D13: Retrabajo / calidad
D14: Subcontratista no se presentó
D15: Permiso / inspección no aprobada

Sheet MASTER
A1: PLAN MAESTRO | D1: Hitos y fases macro del proyecto.
A2: Proyecto: | C2: Edificio Residencial 5 pisos (ejemplo)
A3: Inicio Gantt (1er mes): | C3: 46235
A4: HITOS PRINCIPALES
A5: ID Hito | B5: Hito | C5: Fecha Contractual | D5: Fecha Proyectada | E5: Desvío (días) | F5: Responsable | G5: Estado
A6: H-01 | B6: Inicio de obra | C6: 46237 | D6: 46237 | E6: =IF(OR(C6="",D6=""),"",D6-C6) -> 0 | F6: Administrador de Obra | G6: =IF(E6="","",IF(E6<=0,"En plazo",IF(E6<=7,"Riesgo","Atrasado"))) -> En plazo
A7: H-02 | B7: Fundaciones terminadas | C7: 46297 | D7: 46304 | E7: =IF(OR(C7="",D7=""),"",D7-C7) -> 7 | F7: Ing. Residente | G7: =IF(E7="","",IF(E7<=0,"En plazo",IF(E7<=7,"Riesgo","Atrasado"))) -> Riesgo
A8: H-03 | B8: Obra gruesa terminada | C8: 46444 | D8: 46451 | E8: =IF(OR(C8="",D8=""),"",D8-C8) -> 7 | F8: Ing. Residente | G8: =IF(E8="","",IF(E8<=0,"En plazo",IF(E8<=7,"Riesgo","Atrasado"))) -> Riesgo
A9: H-04 | B9: Instalaciones probadas | C9: 46535 | D9: 46535 | E9: =IF(OR(C9="",D9=""),"",D9-C9) -> 0 | F9: Oficina Técnica | G9: =IF(E9="","",IF(E9<=0,"En plazo",IF(E9<=7,"Riesgo","Atrasado"))) -> En plazo
A10: H-05 | B10: Recepción municipal | C10: 46598 | D10: 46598 | E10: =IF(OR(C10="",D10=""),"",D10-C10) -> 0 | F10: Administrador de Obra | G10: =IF(E10="","",IF(E10<=0,"En plazo",IF(E10<=7,"Riesgo","Atrasado"))) -> En plazo
E11: =IF(OR(C11="",D11=""),"",D11-C11) | G11: =IF(E11="","",IF(E11<=0,"En plazo",IF(E11<=7,"Riesgo","Atrasado")))
E12: =IF(OR(C12="",D12=""),"",D12-C12) | G12: =IF(E12="","",IF(E12<=0,"En plazo",IF(E12<=7,"Riesgo","Atrasado")))
E13: =IF(OR(C13="",D13=""),"",D13-C13) | G13: =IF(E13="","",IF(E13<=0,"En plazo",IF(E13<=7,"Riesgo","Atrasado")))
E14: =IF(OR(C14="",D14=""),"",D14-C14) | G14: =IF(E14="","",IF(E14<=0,"En plazo",IF(E14<=7,"Riesgo","Atrasado")))
E15: =IF(OR(C15="",D15=""),"",D15-C15) | G15: =IF(E15="","",IF(E15<=0,"En plazo",IF(E15<=7,"Riesgo","Atrasado")))
A17: FASES MACRO | K17: GANTT MENSUAL
A18: ID Fase | B18: Fase | C18: Hito asociado | D18: Inicio | E18: Fin | F18: Duración (días háb. L-S) | G18: Responsable general | H18: N° act. Lookahead | I18: % Avance | J18: Estado | K18: =$C$3 -> 46235 | L18: =EDATE(K18,1) -> 46266 | M18: =EDATE(L18,1) -> 46296 | N18: =EDATE(M18,1) -> 46327 | O18: =EDATE(N18,1) -> 46357 | P18: =EDATE(O18,1) -> 46388 | Q18: =EDATE(P18,1) -> 46419 | R18: =EDATE(Q18,1) -> 46447 | S18: =EDATE(R18,1) -> 46478 | ... AB18: =EDATE(AA18,1) -> 46753
A19: F-01 | B19: Instalación de faena | C19: H-01 | D19: 46237 | E19: 46255 | F19: =IF(OR(D19="",E19=""),"",NETWORKDAYS.INTL(D19,E19,11)) -> 17 | G19: Administrador de Obra | H19: =IF(A19="","",COUNTIF(LOOKAHEAD!$C$5:$C$204,A19)) -> 0 | I19: =IF(A19="","",IFERROR(AVERAGEIF(LOOKAHEAD!$C$5:$C$204,A19,LOOKAHEAD!$N$5:$N$204),0)) -> 0 | J19: =IF(A19="","",IF(H19=0,IF(TODAY()>E19,"Fin planificado",IF(TODAY()>=D19,"En curso","Por iniciar")),IF(I19>=1,"Terminada",IF(TODAY()>E19,"Atrasada",IF(TODAY()>=D19,"En curso","Por iniciar"))))) -> Fin planificado
A20: F-02 | B20: Excavaciones y movimiento de tierra | C20: H-02 | D20: 46251 | E20: 46276 | F20: =IF(OR(D20="",E20=""),"",NETWORKDAYS.INTL(D20,E20,11)) -> 23 | G20: Jefe de Terreno | H20: =IF(A20="","",COUNTIF(LOOKAHEAD!$C$5:$C$204,A20)) -> 0 | I20: =IF(A20="","",IFERROR(AVERAGEIF(LOOKAHEAD!$C$5:$C$204,A20,LOOKAHEAD!$N$5:$N$204),0)) -> 0 | J20: =IF(A20="","",IF(H20=0,IF(TODAY()>E20,"Fin planificado",IF(TODAY()>=D20,"En curso","Por iniciar")),IF(I20>=1,"Terminada",IF(TODAY()>E20,"Atrasada",IF(TODAY()>=D20,"En curso","Por iniciar"))))) -> Fin planificado
A21: F-03 | B21: Fundaciones | C21: H-02 | D21: 46272 | E21: 46304 | F21: =IF(OR(D21="",E21=""),"",NETWORKDAYS.INTL(D21,E21,11)) -> 29 | G21: Ing. Residente | H21: =IF(A21="","",COUNTIF(LOOKAHEAD!$C$5:$C$204,A21)) -> 1 | I21: =IF(A21="","",IFERROR(AVERAGEIF(LOOKAHEAD!$C$5:$C$204,A21,LOOKAHEAD!$N$5:$N$204),0)) -> 0.66666667 | J21: =IF(A21="","",IF(H21=0,IF(TODAY()>E21,"Fin planificado",IF(TODAY()>=D21,"En curso","Por iniciar")),IF(I21>=1,"Terminada",IF(TODAY()>E21,"Atrasada",IF(TODAY()>=D21,"En curso","Por iniciar"))))) -> En curso
A22: F-04 | B22: Obra gruesa (estructura pisos 1-5) | C22: H-03 | D22: 46300 | E22: 46451 | F22: =IF(OR(D22="",E22=""),"",NETWORKDAYS.INTL(D22,E22,11)) -> 131 | G22: Ing. Residente | H22: =IF(A22="","",COUNTIF(LOOKAHEAD!$C$5:$C$204,A22)) -> 5 | I22: =IF(A22="","",IFERROR(AVERAGEIF(LOOKAHEAD!$C$5:$C$204,A22,LOOKAHEAD!$N$5:$N$204),0)) -> 0.21761905 | J22: =IF(A22="","",IF(H22=0,IF(TODAY()>E22,"Fin planificado",IF(TODAY()>=D22,"En curso","Por iniciar")),IF(I22>=1,"Terminada",IF(TODAY()>E22,"Atrasada",IF(TODAY()>=D22,"En curso","Por iniciar"))))) -> En curso
A23: F-05 | B23: Instalaciones (eléctrica, sanitaria, clima) | C23: H-04 | D23: 46342 | E23: 46535 | F23: =IF(OR(D23="",E23=""),"",NETWORKDAYS.INTL(D23,E23,11)) -> 167 | G23: Oficina Técnica | H23: =IF(A23="","",COUNTIF(LOOKAHEAD!$C$5:$C$204,A23)) -> 2 | I23: =IF(A23="","",IFERROR(AVERAGEIF(LOOKAHEAD!$C$5:$C$204,A23,LOOKAHEAD!$N$5:$N$204),0)) -> 0 | J23: =IF(A23="","",IF(H23=0,IF(TODAY()>E23,"Fin planificado",IF(TODAY()>=D23,"En curso","Por iniciar")),IF(I23>=1,"Terminada",IF(TODAY()>E23,"Atrasada",IF(TODAY()>=D23,"En curso","Por iniciar"))))) -> Por iniciar
A24: F-06 | B24: Terminaciones | C24: H-05 | D24: 46419 | E24: 46591 | F24: =IF(OR(D24="",E24=""),"",NETWORKDAYS.INTL(D24,E24,11)) -> 149 | G24: Jefe de Terreno | H24: =IF(A24="","",COUNTIF(LOOKAHEAD!$C$5:$C$204,A24)) -> 0 | I24: =IF(A24="","",IFERROR(AVERAGEIF(LOOKAHEAD!$C$5:$C$204,A24,LOOKAHEAD!$N$5:$N$204),0)) -> 0 | J24: =IF(A24="","",IF(H24=0,IF(TODAY()>E24,"Fin planificado",IF(TODAY()>=D24,"En curso","Por iniciar")),IF(I24>=1,"Terminada",IF(TODAY()>E24,"Atrasada",IF(TODAY()>=D24,"En curso","Por iniciar"))))) -> Por iniciar
F25: =IF(OR(D25="",E25=""),"",NETWORKDAYS.INTL(D25,E25,11)) | H25: =IF(A25="","",COUNTIF(LOOKAHEAD!$C$5:$C$204,A25)) | I25: =IF(A25="","",IFERROR(AVERAGEIF(LOOKAHEAD!$C$5:$C$204,A25,LOOKAHEAD!$N$5:$N$204),0)) | J25: =IF(A25="","",IF(H25=0,IF(TODAY()>E25,"Fin planificado",IF(TODAY()>=D25,"En curso","Por iniciar")),IF(I25>=1,"Terminada",IF(TODAY()>E25,"Atrasada",IF(TODAY()>=D25,"En curso","Por iniciar")))))
F26: =IF(OR(D26="",E26=""),"",NETWORKDAYS.INTL(D26,E26,11)) | H26: =IF(A26="","",COUNTIF(LOOKAHEAD!$C$5:$C$204,A26)) | I26: =IF(A26="","",IFERROR(AVERAGEIF(LOOKAHEAD!$C$5:$C$204,A26,LOOKAHEAD!$N$5:$N$204),0)) | J26: =IF(A26="","",IF(H26=0,IF(TODAY()>E26,"Fin planificado",IF(TODAY()>=D26,"En curso","Por iniciar")),IF(I26>=1,"Terminada",IF(TODAY()>E26,"Atrasada",IF(TODAY()>=D26,"En curso","Por iniciar")))))
F27: =IF(OR(D27="",E27=""),"",NETWORKDAYS.INTL(D27,E27,11)) | H27: =IF(A27="","",COUNTIF(LOOKAHEAD!$C$5:$C$204,A27)) | I27: =IF(A27="","",IFERROR(AVERAGEIF(LOOKAHEAD!$C$5:$C$204,A27,LOOKAHEAD!$N$5:$N$204),0)) | J27: =IF(A27="","",IF(H27=0,IF(TODAY()>E27,"Fin planificado",IF(TODAY()>=D27,"En curso","Por iniciar")),IF(I27>=1,"Terminada",IF(TODAY()>E27,"Atrasada",IF(TODAY()>=D27,"En curso","Por iniciar")))))
F28: =IF(OR(D28="",E28=""),"",NETWORKDAYS.INTL(D28,E28,11)) | H28: =IF(A28="","",COUNTIF(LOOKAHEAD!$C$5:$C$204,A28)) | I28: =IF(A28="","",IFERROR(AVERAGEIF(LOOKAHEAD!$C$5:$C$204,A28,LOOKAHEAD!$N$5:$N$204),0)) | J28: =IF(A28="","",IF(H28=0,IF(TODAY()>E28,"Fin planificado",IF(TODAY()>=D28,"En curso","Por iniciar")),IF(I28>=1,"Terminada",IF(TODAY()>E28,"Atrasada",IF(TODAY()>=D28,"En curso","Por iniciar")))))
F29: =IF(OR(D29="",E29=""),"",NETWORKDAYS.INTL(D29,E29,11)) | H29: =IF(A29="","",COUNTIF(LOOKAHEAD!$C$5:$C$204,A29)) | I29: =IF(A29="","",IFERROR(AVERAGEIF(LOOKAHEAD!$C$5:$C$204,A29,LOOKAHEAD!$N$5:$N$204),0)) | J29: =IF(A29="","",IF(H29=0,IF(TODAY()>E29,"Fin planificado",IF(TODAY()>=D29,"En curso","Por iniciar")),IF(I29>=1,"Terminada",IF(TODAY()>E29,"Atrasada",IF(TODAY()>=D29,"En curso","Por iniciar")))))
F30: =IF(OR(D30="",E30=""),"",NETWORKDAYS.INTL(D30,E30,11)) | H30: =IF(A30="","",COUNTIF(LOOKAHEAD!$C$5:$C$204,A30)) | I30: =IF(A30="","",IFERROR(AVERAGEIF(LOOKAHEAD!$C$5:$C$204,A30,LOOKAHEAD!$N$5:$N$204),0)) | J30: =IF(A30="","",IF(H30=0,IF(TODAY()>E30,"Fin planificado",IF(TODAY()>=D30,"En curso","Por iniciar")),IF(I30>=1,"Terminada",IF(TODAY()>E30,"Atrasada",IF(TODAY()>=D30,"En curso","Por iniciar")))))
F31: =IF(OR(D31="",E31=""),"",NETWORKDAYS.INTL(D31,E31,11)) | H31: =IF(A31="","",COUNTIF(LOOKAHEAD!$C$5:$C$204,A31)) | I31: =IF(A31="","",IFERROR(AVERAGEIF(LOOKAHEAD!$C$5:$C$204,A31,LOOKAHEAD!$N$5:$N$204),0)) | J31: =IF(A31="","",IF(H31=0,IF(TODAY()>E31,"Fin planificado",IF(TODAY()>=D31,"En curso","Por iniciar")),IF(I31>=1,"Terminada",IF(TODAY()>E31,"Atrasada",IF(TODAY()>=D31,"En curso","Por iniciar")))))
F32: =IF(OR(D32="",E32=""),"",NETWORKDAYS.INTL(D32,E32,11)) | H32: =IF(A32="","",COUNTIF(LOOKAHEAD!$C$5:$C$204,A32)) | I32: =IF(A32="","",IFERROR(AVERAGEIF(LOOKAHEAD!$C$5:$C$204,A32,LOOKAHEAD!$N$5:$N$204),0)) | J32: =IF(A32="","",IF(H32=0,IF(TODAY()>E32,"Fin planificado",IF(TODAY()>=D32,"En curso","Por iniciar")),IF(I32>=1,"Terminada",IF(TODAY()>E32,"Atrasada",IF(TODAY()>=D32,"En curso","Por iniciar")))))
F33: =IF(OR(D33="",E33=""),"",NETWORKDAYS.INTL(D33,E33,11)) | H33: =IF(A33="","",COUNTIF(LOOKAHEAD!$C$5:$C$204,A33)) | I33: =IF(A33="","",IFERROR(AVERAGEIF(LOOKAHEAD!$C$5:$C$204,A33,LOOKAHEAD!$N$5:$N$204),0)) | J33: =IF(A33="","",IF(H33=0,IF(TODAY()>E33,"Fin planificado",IF(TODAY()>=D33,"En curso","Por iniciar")),IF(I33>=1,"Terminada",IF(TODAY()>E33,"Atrasada",IF(TODAY()>=D33,"En curso","Por iniciar")))))
F34: =IF(OR(D34="",E34=""),"",NETWORKDAYS.INTL(D34,E34,11)) | H34: =IF(A34="","",COUNTIF(LOOKAHEAD!$C$5:$C$204,A34)) | I34: =IF(A34="","",IFERROR(AVERAGEIF(LOOKAHEAD!$C$5:$C$204,A34,LOOKAHEAD!$N$5:$N$204),0)) | J34: =IF(A34="","",IF(H34=0,IF(TODAY()>E34,"Fin planificado",IF(TODAY()>=D34,"En curso","Por iniciar")),IF(I34>=1,"Terminada",IF(TODAY()>E34,"Atrasada",IF(TODAY()>=D34,"En curso","Por iniciar")))))
F35: =IF(OR(D35="",E35=""),"",NETWORKDAYS.INTL(D35,E35,11)) | H35: =IF(A35="","",COUNTIF(LOOKAHEAD!$C$5:$C$204,A35)) | I35: =IF(A35="","",IFERROR(AVERAGEIF(LOOKAHEAD!$C$5:$C$204,A35,LOOKAHEAD!$N$5:$N$204),0)) | J35: =IF(A35="","",IF(H35=0,IF(TODAY()>E35,"Fin planificado",IF(TODAY()>=D35,"En curso","Por iniciar")),IF(I35>=1,"Terminada",IF(TODAY()>E35,"Atrasada",IF(TODAY()>=D35,"En curso","Por iniciar")))))
F36: =IF(OR(D36="",E36=""),"",NETWORKDAYS.INTL(D36,E36,11)) | H36: =IF(A36="","",COUNTIF(LOOKAHEAD!$C$5:$C$204,A36)) | I36: =IF(A36="","",IFERROR(AVERAGEIF(LOOKAHEAD!$C$5:$C$204,A36,LOOKAHEAD!$N$5:$N$204),0)) | J36: =IF(A36="","",IF(H36=0,IF(TODAY()>E36,"Fin planificado",IF(TODAY()>=D36,"En curso","Por iniciar")),IF(I36>=1,"Terminada",IF(TODAY()>E36,"Atrasada",IF(TODAY()>=D36,"En curso","Por iniciar")))))
... F38: =IF(OR(D38="",E38=""),"",NETWORKDAYS.INTL(D38,E38,11)) | H38: =IF(A38="","",COUNTIF(LOOKAHEAD!$C$5:$C$204,A38)) | I38: =IF(A38="","",IFERROR(AVERAGEIF(LOOKAHEAD!$C$5:$C$204,A38,LOOKAHEAD!$N$5:$N$204),0)) | J38: =IF(A38="","",IF(H38=0,IF(TODAY()>E38,"Fin planificado",IF(TODAY()>=D38,"En curso","Por iniciar")),IF(I38>=1,"Terminada",IF(TODAY()>E38,"Atrasada",IF(TODAY()>=D38,"En curso","Por iniciar")))))

Sheet LOOKAHEAD
A1: LOOKAHEAD – PLANIFICACIÓN INTERMEDIA (6 SEMANAS) | D1: Estado LISTA = sin restricciones pendientes en la pestaña RESTRICCIONES.
A2: Lunes semana actual: | C2: =TODAY()-WEEKDAY(TODAY(),2)+1 -> 46300 | E2: Actividades LISTAS: | G2: =COUNTIF($M$5:$M$204,"LISTA") -> 3 | H2: Restringidas: | J2: =COUNTIF($M$5:$M$204,"RESTRINGIDA") -> 5
O3: VENTANA LOOKAHEAD (semanas desde el lunes indicado)
A4: ID Actividad | B4: Actividad | C4: ID Fase | D4: Fase | E4: Ubicación / Frente | F4: Cuadrilla / Subcontrato | G4: Unidad | H4: Cantidad | I4: Inicio planif. | J4: Fin planif. | K4: Restr. totales | L4: Restr. pendientes | M4: Estado | N4: % Avance acum. | O4: =$C$2 -> 46300 | P4: =O4+7 -> 46307 | Q4: =P4+7 -> 46314 | R4: =Q4+7 -> 46321 | S4: =R4+7 -> 46328 | T4: =S4+7 -> 46335 | U4: Observaciones
A5: LA-001 | B5: Hormigonado fundaciones eje D-F | C5: F-03 | D5: =IF(C5="","",IFERROR(INDEX(MASTER!$B$19:$B$38,MATCH(C5,MASTER!$A$19:$A$38,0)),"ID no existe")) -> Fundaciones | E5: Eje D-F | F5: Cuadrilla Hormigón | G5: m3 | H5: 45 | I5: 46300 | J5: 46304 | K5: =IF(A5="","",COUNTIF(RESTRICCIONES!$B$5:$B$304,A5)) -> 0 | L5: =IF(A5="","",COUNTIFS(RESTRICCIONES!$B$5:$B$304,A5,RESTRICCIONES!$L$5:$L$304,"Pendiente")) -> 0 | M5: =IF(A5="","",IF(L5=0,"LISTA","RESTRINGIDA")) -> LISTA | N5: =IF(OR(A5="",H5=""),"",IFERROR(MIN(1,SUMIF(SEMANAL!$C$7:$C$506,A5,SEMANAL!$W$7:$W$506)/H5),0)) -> 0.66666667
A6: LA-002 | B6: Enfierradura muros piso 1 | C6: F-04 | D6: =IF(C6="","",IFERROR(INDEX(MASTER!$B$19:$B$38,MATCH(C6,MASTER!$A$19:$A$38,0)),"ID no existe")) -> Obra gruesa (estructura pisos 1-5) | E6: Piso 1 | F6: Cuadrilla Enfierradura | G6: kg | H6: 6000 | I6: 46300 | J6: 46311 | K6: =IF(A6="","",COUNTIF(RESTRICCIONES!$B$5:$B$304,A6)) -> 1 | L6: =IF(A6="","",COUNTIFS(RESTRICCIONES!$B$5:$B$304,A6,RESTRICCIONES!$L$5:$L$304,"Pendiente")) -> 0 | M6: =IF(A6="","",IF(L6=0,"LISTA","RESTRINGIDA")) -> LISTA | N6: =IF(OR(A6="",H6=""),"",IFERROR(MIN(1,SUMIF(SEMANAL!$C$7:$C$506,A6,SEMANAL!$W$7:$W$506)/H6),0)) -> 0.85
A7: LA-003 | B7: Moldaje muros piso 1 | C7: F-04 | D7: =IF(C7="","",IFERROR(INDEX(MASTER!$B$19:$B$38,MATCH(C7,MASTER!$A$19:$A$38,0)),"ID no existe")) -> Obra gruesa (estructura pisos 1-5) | E7: Piso 1 | F7: Cuadrilla Moldajes | G7: m2 | H7: 420 | I7: 46307 | J7: 46318 | K7: =IF(A7="","",COUNTIF(RESTRICCIONES!$B$5:$B$304,A7)) -> 1 | L7: =IF(A7="","",COUNTIFS(RESTRICCIONES!$B$5:$B$304,A7,RESTRICCIONES!$L$5:$L$304,"Pendiente")) -> 0 | M7: =IF(A7="","",IF(L7=0,"LISTA","RESTRINGIDA")) -> LISTA | N7: =IF(OR(A7="",H7=""),"",IFERROR(MIN(1,SUMIF(SEMANAL!$C$7:$C$506,A7,SEMANAL!$W$7:$W$506)/H7),0)) -> 0.23809524
A8: LA-004 | B8: Hormigonado muros piso 1 | C8: F-04 | D8: =IF(C8="","",IFERROR(INDEX(MASTER!$B$19:$B$38,MATCH(C8,MASTER!$A$19:$A$38,0)),"ID no existe")) -> Obra gruesa (estructura pisos 1-5) | E8: Piso 1 | F8: Cuadrilla Hormigón | G8: m3 | H8: 60 | I8: 46314 | J8: 46319 | K8: =IF(A8="","",COUNTIF(RESTRICCIONES!$B$5:$B$304,A8)) -> 2 | L8: =IF(A8="","",COUNTIFS(RESTRICCIONES!$B$5:$B$304,A8,RESTRICCIONES!$L$5:$L$304,"Pendiente")) -> 2 | M8: =IF(A8="","",IF(L8=0,"LISTA","RESTRINGIDA")) -> RESTRINGIDA | N8: =IF(OR(A8="",H8=""),"",IFERROR(MIN(1,SUMIF(SEMANAL!$C$7:$C$506,A8,SEMANAL!$W$7:$W$506)/H8),0)) -> 0
A9: LA-005 | B9: Moldaje y enfierradura losa piso 2 | C9: F-04 | D9: =IF(C9="","",IFERROR(INDEX(MASTER!$B$19:$B$38,MATCH(C9,MASTER!$A$19:$A$38,0)),"ID no existe")) -> Obra gruesa (estructura pisos 1-5) | E9: Piso 2 | F9: Cuadrilla Moldajes | G9: m2 | H9: 380 | I9: 46321 | J9: 46332 | K9: =IF(A9="","",COUNTIF(RESTRICCIONES!$B$5:$B$304,A9)) -> 1 | L9: =IF(A9="","",COUNTIFS(RESTRICCIONES!$B$5:$B$304,A9,RESTRICCIONES!$L$5:$L$304,"Pendiente")) -> 1 | M9: =IF(A9="","",IF(L9=0,"LISTA","RESTRINGIDA")) -> RESTRINGIDA | N9: =IF(OR(A9="",H9=""),"",IFERROR(MIN(1,SUMIF(SEMANAL!$C$7:$C$506,A9,SEMANAL!$W$7:$W$506)/H9),0)) -> 0
A10: LA-006 | B10: Hormigonado losa piso 2 | C10: F-04 | D10: =IF(C10="","",IFERROR(INDEX(MASTER!$B$19:$B$38,MATCH(C10,MASTER!$A$19:$A$38,0)),"ID no existe")) -> Obra gruesa (estructura pisos 1-5) | E10: Piso 2 | F10: Cuadrilla Hormigón | G10: m3 | H10: 55 | I10: 46333 | J10: 46334 | K10: =IF(A10="","",COUNTIF(RESTRICCIONES!$B$5:$B$304,A10)) -> 1 | L10: =IF(A10="","",COUNTIFS(RESTRICCIONES!$B$5:$B$304,A10,RESTRICCIONES!$L$5:$L$304,"Pendiente")) -> 1 | M10: =IF(A10="","",IF(L10=0,"LISTA","RESTRINGIDA")) -> RESTRINGIDA | N10: =IF(OR(A10="",H10=""),"",IFERROR(MIN(1,SUMIF(SEMANAL!$C$7:$C$506,A10,SEMANAL!$W$7:$W$506)/H10),0)) -> 0
A11: LA-007 | B11: Canalización eléctrica embutida losa P2 | C11: F-05 | D11: =IF(C11="","",IFERROR(INDEX(MASTER!$B$19:$B$38,MATCH(C11,MASTER!$A$19:$A$38,0)),"ID no existe")) -> Instalaciones (eléctrica, sanitaria, clima) | E11: Piso 2 | F11: Subc. Eléctrico | G11: ml | H11: 350 | I11: 46328 | J11: 46332 | K11: =IF(A11="","",COUNTIF(RESTRICCIONES!$B$5:$B$304,A11)) -> 1 | L11: =IF(A11="","",COUNTIFS(RESTRICCIONES!$B$5:$B$304,A11,RESTRICCIONES!$L$5:$L$304,"Pendiente")) -> 1 | M11: =IF(A11="","",IF(L11=0,"LISTA","RESTRINGIDA")) -> RESTRINGIDA | N11: =IF(OR(A11="",H11=""),"",IFERROR(MIN(1,SUMIF(SEMANAL!$C$7:$C$506,A11,SEMANAL!$W$7:$W$506)/H11),0)) -> 0
A12: LA-008 | B12: Pasadas sanitarias losa P2 | C12: F-05 | D12: =IF(C12="","",IFERROR(INDEX(MASTER!$B$19:$B$38,MATCH(C12,MASTER!$A$19:$A$38,0)),"ID no existe")) -> Instalaciones (eléctrica, sanitaria, clima) | E12: Piso 2 | F12: Subc. Sanitario | G12: und | H12: 24 | I12: 46328 | J12: 46332 | K12: =IF(A12="","",COUNTIF(RESTRICCIONES!$B$5:$B$304,A12)) -> 1 | L12: =IF(A12="","",COUNTIFS(RESTRICCIONES!$B$5:$B$304,A12,RESTRICCIONES!$L$5:$L$304,"Pendiente")) -> 1 | M12: =IF(A12="","",IF(L12=0,"LISTA","RESTRINGIDA")) -> RESTRINGIDA | N12: =IF(OR(A12="",H12=""),"",IFERROR(MIN(1,SUMIF(SEMANAL!$C$7:$C$506,A12,SEMANAL!$W$7:$W$506)/H12),0)) -> 0
D13: =IF(C13="","",IFERROR(INDEX(MASTER!$B$19:$B$38,MATCH(C13,MASTER!$A$19:$A$38,0)),"ID no existe")) | K13: =IF(A13="","",COUNTIF(RESTRICCIONES!$B$5:$B$304,A13)) | L13: =IF(A13="","",COUNTIFS(RESTRICCIONES!$B$5:$B$304,A13,RESTRICCIONES!$L$5:$L$304,"Pendiente")) | M13: =IF(A13="","",IF(L13=0,"LISTA","RESTRINGIDA")) | N13: =IF(OR(A13="",H13=""),"",IFERROR(MIN(1,SUMIF(SEMANAL!$C$7:$C$506,A13,SEMANAL!$W$7:$W$506)/H13),0))
D14: =IF(C14="","",IFERROR(INDEX(MASTER!$B$19:$B$38,MATCH(C14,MASTER!$A$19:$A$38,0)),"ID no existe")) | K14: =IF(A14="","",COUNTIF(RESTRICCIONES!$B$5:$B$304,A14)) | L14: =IF(A14="","",COUNTIFS(RESTRICCIONES!$B$5:$B$304,A14,RESTRICCIONES!$L$5:$L$304,"Pendiente")) | M14: =IF(A14="","",IF(L14=0,"LISTA","RESTRINGIDA")) | N14: =IF(OR(A14="",H14=""),"",IFERROR(MIN(1,SUMIF(SEMANAL!$C$7:$C$506,A14,SEMANAL!$W$7:$W$506)/H14),0))
D15: =IF(C15="","",IFERROR(INDEX(MASTER!$B$19:$B$38,MATCH(C15,MASTER!$A$19:$A$38,0)),"ID no existe")) | K15: =IF(A15="","",COUNTIF(RESTRICCIONES!$B$5:$B$304,A15)) | L15: =IF(A15="","",COUNTIFS(RESTRICCIONES!$B$5:$B$304,A15,RESTRICCIONES!$L$5:$L$304,"Pendiente")) | M15: =IF(A15="","",IF(L15=0,"LISTA","RESTRINGIDA")) | N15: =IF(OR(A15="",H15=""),"",IFERROR(MIN(1,SUMIF(SEMANAL!$C$7:$C$506,A15,SEMANAL!$W$7:$W$506)/H15),0))
D16: =IF(C16="","",IFERROR(INDEX(MASTER!$B$19:$B$38,MATCH(C16,MASTER!$A$19:$A$38,0)),"ID no existe")) | K16: =IF(A16="","",COUNTIF(RESTRICCIONES!$B$5:$B$304,A16)) | L16: =IF(A16="","",COUNTIFS(RESTRICCIONES!$B$5:$B$304,A16,RESTRICCIONES!$L$5:$L$304,"Pendiente")) | M16: =IF(A16="","",IF(L16=0,"LISTA","RESTRINGIDA")) | N16: =IF(OR(A16="",H16=""),"",IFERROR(MIN(1,SUMIF(SEMANAL!$C$7:$C$506,A16,SEMANAL!$W$7:$W$506)/H16),0))
D17: =IF(C17="","",IFERROR(INDEX(MASTER!$B$19:$B$38,MATCH(C17,MASTER!$A$19:$A$38,0)),"ID no existe")) | K17: =IF(A17="","",COUNTIF(RESTRICCIONES!$B$5:$B$304,A17)) | L17: =IF(A17="","",COUNTIFS(RESTRICCIONES!$B$5:$B$304,A17,RESTRICCIONES!$L$5:$L$304,"Pendiente")) | M17: =IF(A17="","",IF(L17=0,"LISTA","RESTRINGIDA")) | N17: =IF(OR(A17="",H17=""),"",IFERROR(MIN(1,SUMIF(SEMANAL!$C$7:$C$506,A17,SEMANAL!$W$7:$W$506)/H17),0))
D18: =IF(C18="","",IFERROR(INDEX(MASTER!$B$19:$B$38,MATCH(C18,MASTER!$A$19:$A$38,0)),"ID no existe")) | K18: =IF(A18="","",COUNTIF(RESTRICCIONES!$B$5:$B$304,A18)) | L18: =IF(A18="","",COUNTIFS(RESTRICCIONES!$B$5:$B$304,A18,RESTRICCIONES!$L$5:$L$304,"Pendiente")) | M18: =IF(A18="","",IF(L18=0,"LISTA","RESTRINGIDA")) | N18: =IF(OR(A18="",H18=""),"",IFERROR(MIN(1,SUMIF(SEMANAL!$C$7:$C$506,A18,SEMANAL!$W$7:$W$506)/H18),0))
D19: =IF(C19="","",IFERROR(INDEX(MASTER!$B$19:$B$38,MATCH(C19,MASTER!$A$19:$A$38,0)),"ID no existe")) | K19: =IF(A19="","",COUNTIF(RESTRICCIONES!$B$5:$B$304,A19)) | L19: =IF(A19="","",COUNTIFS(RESTRICCIONES!$B$5:$B$304,A19,RESTRICCIONES!$L$5:$L$304,"Pendiente")) | M19: =IF(A19="","",IF(L19=0,"LISTA","RESTRINGIDA")) | N19: =IF(OR(A19="",H19=""),"",IFERROR(MIN(1,SUMIF(SEMANAL!$C$7:$C$506,A19,SEMANAL!$W$7:$W$506)/H19),0))
D20: =IF(C20="","",IFERROR(INDEX(MASTER!$B$19:$B$38,MATCH(C20,MASTER!$A$19:$A$38,0)),"ID no existe")) | K20: =IF(A20="","",COUNTIF(RESTRICCIONES!$B$5:$B$304,A20)) | L20: =IF(A20="","",COUNTIFS(RESTRICCIONES!$B$5:$B$304,A20,RESTRICCIONES!$L$5:$L$304,"Pendiente")) | M20: =IF(A20="","",IF(L20=0,"LISTA","RESTRINGIDA")) | N20: =IF(OR(A20="",H20=""),"",IFERROR(MIN(1,SUMIF(SEMANAL!$C$7:$C$506,A20,SEMANAL!$W$7:$W$506)/H20),0))
D21: =IF(C21="","",IFERROR(INDEX(MASTER!$B$19:$B$38,MATCH(C21,MASTER!$A$19:$A$38,0)),"ID no existe")) | K21: =IF(A21="","",COUNTIF(RESTRICCIONES!$B$5:$B$304,A21)) | L21: =IF(A21="","",COUNTIFS(RESTRICCIONES!$B$5:$B$304,A21,RESTRICCIONES!$L$5:$L$304,"Pendiente")) | M21: =IF(A21="","",IF(L21=0,"LISTA","RESTRINGIDA")) | N21: =IF(OR(A21="",H21=""),"",IFERROR(MIN(1,SUMIF(SEMANAL!$C$7:$C$506,A21,SEMANAL!$W$7:$W$506)/H21),0))
D22: =IF(C22="","",IFERROR(INDEX(MASTER!$B$19:$B$38,MATCH(C22,MASTER!$A$19:$A$38,0)),"ID no existe")) | K22: =IF(A22="","",COUNTIF(RESTRICCIONES!$B$5:$B$304,A22)) | L22: =IF(A22="","",COUNTIFS(RESTRICCIONES!$B$5:$B$304,A22,RESTRICCIONES!$L$5:$L$304,"Pendiente")) | M22: =IF(A22="","",IF(L22=0,"LISTA","RESTRINGIDA")) | N22: =IF(OR(A22="",H22=""),"",IFERROR(MIN(1,SUMIF(SEMANAL!$C$7:$C$506,A22,SEMANAL!$W$7:$W$506)/H22),0))
D23: =IF(C23="","",IFERROR(INDEX(MASTER!$B$19:$B$38,MATCH(C23,MASTER!$A$19:$A$38,0)),"ID no existe")) | K23: =IF(A23="","",COUNTIF(RESTRICCIONES!$B$5:$B$304,A23)) | L23: =IF(A23="","",COUNTIFS(RESTRICCIONES!$B$5:$B$304,A23,RESTRICCIONES!$L$5:$L$304,"Pendiente")) | M23: =IF(A23="","",IF(L23=0,"LISTA","RESTRINGIDA")) | N23: =IF(OR(A23="",H23=""),"",IFERROR(MIN(1,SUMIF(SEMANAL!$C$7:$C$506,A23,SEMANAL!$W$7:$W$506)/H23),0))
D24: =IF(C24="","",IFERROR(INDEX(MASTER!$B$19:$B$38,MATCH(C24,MASTER!$A$19:$A$38,0)),"ID no existe")) | K24: =IF(A24="","",COUNTIF(RESTRICCIONES!$B$5:$B$304,A24)) | L24: =IF(A24="","",COUNTIFS(RESTRICCIONES!$B$5:$B$304,A24,RESTRICCIONES!$L$5:$L$304,"Pendiente")) | M24: =IF(A24="","",IF(L24=0,"LISTA","RESTRINGIDA")) | N24: =IF(OR(A24="",H24=""),"",IFERROR(MIN(1,SUMIF(SEMANAL!$C$7:$C$506,A24,SEMANAL!$W$7:$W$506)/H24),0))
... D204: =IF(C204="","",IFERROR(INDEX(MASTER!$B$19:$B$38,MATCH(C204,MASTER!$A$19:$A$38,0)),"ID no existe")) | K204: =IF(A204="","",COUNTIF(RESTRICCIONES!$B$5:$B$304,A204)) | L204: =IF(A204="","",COUNTIFS(RESTRICCIONES!$B$5:$B$304,A204,RESTRICCIONES!$L$5:$L$304,"Pendiente")) | M204: =IF(A204="","",IF(L204=0,"LISTA","RESTRINGIDA")) | N204: =IF(OR(A204="",H204=""),"",IFERROR(MIN(1,SUMIF(SEMANAL!$C$7:$C$506,A204,SEMANAL!$W$7:$W$506)/H204),0))

Sheet RESTRICCIONES
A1: ANÁLISIS DE RESTRICCIONES | D1: Estado = Liberado cuando se ingresa la Fecha real de liberación.
A2: Colchón (días antes del inicio): | D2: 3 | F2: Pendientes: | G2: =COUNTIF($L$5:$L$304,"Pendiente") -> 6 | H2: Vencidas: | I2: =COUNTIF($M$5:$M$304,"VENCIDA") -> 1
A4: ID Restricción | B4: ID Actividad | C4: Actividad | D4: Inicio actividad | E4: Tipo de restricción | F4: Descripción de la restricción | G4: Responsable único | H4: Fecha identificación | I4: Fecha requerida | J4: Fecha comprometida | K4: Fecha real liberación | L4: Estado | M4: Alerta | N4: Holgura (días) | O4: Acción / Comentario
A5: R-001 | B5: LA-003 | C5: =IF(B5="","",IFERROR(INDEX(LOOKAHEAD!$B$5:$B$204,MATCH(B5,LOOKAHEAD!$A$5:$A$204,0)),"ID no existe")) -> Moldaje muros piso 1 | D5: =IF(B5="","",IFERROR(INDEX(LOOKAHEAD!$I$5:$I$204,MATCH(B5,LOOKAHEAD!$A$5:$A$204,0)),"")) -> 46307 | E5: Materiales | F5: Llegada de paneles de moldaje arrendados | G5: Bodega / Adquisiciones | H5: 46293 | I5: =IF(OR(D5="",D5=0),"",D5-$D$2) -> 46304 | J5: 46304 | K5: 46303 | L5: =IF(B5="","",IF(K5<>"","Liberado","Pendiente")) -> Liberado | M5: =IF(B5="","",IF(L5="Liberado",IF(OR(I5="",K5<=I5),"A tiempo","Liberada tarde"),IF(J5="","Sin compromiso",IF(TODAY()>J5,"VENCIDA",IF(AND(I5<>"",J5>I5),"En riesgo","En gestión"))))) -> A tiempo | N5: =IF(OR(B5="",I5=""),"",IF(K5<>"",I5-K5,IF(J5<>"",I5-J5,""))) -> 1
A6: R-002 | B6: LA-004 | C6: =IF(B6="","",IFERROR(INDEX(LOOKAHEAD!$B$5:$B$204,MATCH(B6,LOOKAHEAD!$A$5:$A$204,0)),"ID no existe")) -> Hormigonado muros piso 1 | D6: =IF(B6="","",IFERROR(INDEX(LOOKAHEAD!$I$5:$I$204,MATCH(B6,LOOKAHEAD!$A$5:$A$204,0)),"")) -> 46314 | E6: Equipos / Maquinaria | F6: Reserva de bomba de hormigón | G6: Jefe de Terreno | H6: 46293 | I6: =IF(OR(D6="",D6=0),"",D6-$D$2) -> 46311 | J6: 46309 | L6: =IF(B6="","",IF(K6<>"","Liberado","Pendiente")) -> Pendiente | M6: =IF(B6="","",IF(L6="Liberado",IF(OR(I6="",K6<=I6),"A tiempo","Liberada tarde"),IF(J6="","Sin compromiso",IF(TODAY()>J6,"VENCIDA",IF(AND(I6<>"",J6>I6),"En riesgo","En gestión"))))) -> En gestión | N6: =IF(OR(B6="",I6=""),"",IF(K6<>"",I6-K6,IF(J6<>"",I6-J6,""))) -> 2
A7: R-003 | B7: LA-004 | C7: =IF(B7="","",IFERROR(INDEX(LOOKAHEAD!$B$5:$B$204,MATCH(B7,LOOKAHEAD!$A$5:$A$204,0)),"ID no existe")) -> Hormigonado muros piso 1 | D7: =IF(B7="","",IFERROR(INDEX(LOOKAHEAD!$I$5:$I$204,MATCH(B7,LOOKAHEAD!$A$5:$A$204,0)),"")) -> 46314 | E7: Seguridad / Calidad | F7: Protocolo de inspección de enfierradura P1 aprobado | G7: Calidad | H7: 46296 | I7: =IF(OR(D7="",D7=0),"",D7-$D$2) -> 46311 | J7: 46311 | L7: =IF(B7="","",IF(K7<>"","Liberado","Pendiente")) -> Pendiente | M7: =IF(B7="","",IF(L7="Liberado",IF(OR(I7="",K7<=I7),"A tiempo","Liberada tarde"),IF(J7="","Sin compromiso",IF(TODAY()>J7,"VENCIDA",IF(AND(I7<>"",J7>I7),"En riesgo","En gestión"))))) -> En gestión | N7: =IF(OR(B7="",I7=""),"",IF(K7<>"",I7-K7,IF(J7<>"",I7-J7,""))) -> 0
A8: R-004 | B8: LA-005 | C8: =IF(B8="","",IFERROR(INDEX(LOOKAHEAD!$B$5:$B$204,MATCH(B8,LOOKAHEAD!$A$5:$A$204,0)),"ID no existe")) -> Moldaje y enfierradura losa piso 2 | D8: =IF(B8="","",IFERROR(INDEX(LOOKAHEAD!$I$5:$I$204,MATCH(B8,LOOKAHEAD!$A$5:$A$204,0)),"")) -> 46321 | E8: Diseño / Ingeniería (RFI) | F8: RFI-012: refuerzo de losa en shaft ascensor | G8: Oficina Técnica | H8: 46296 | I8: =IF(OR(D8="",D8=0),"",D8-$D$2) -> 46318 | J8: 46302 | L8: =IF(B8="","",IF(K8<>"","Liberado","Pendiente")) -> Pendiente | M8: =IF(B8="","",IF(L8="Liberado",IF(OR(I8="",K8<=I8),"A tiempo","Liberada tarde"),IF(J8="","Sin compromiso",IF(TODAY()>J8,"VENCIDA",IF(AND(I8<>"",J8>I8),"En riesgo","En gestión"))))) -> VENCIDA | N8: =IF(OR(B8="",I8=""),"",IF(K8<>"",I8-K8,IF(J8<>"",I8-J8,""))) -> 16
A9: R-005 | B9: LA-006 | C9: =IF(B9="","",IFERROR(INDEX(LOOKAHEAD!$B$5:$B$204,MATCH(B9,LOOKAHEAD!$A$5:$A$204,0)),"ID no existe")) -> Hormigonado losa piso 2 | D9: =IF(B9="","",IFERROR(INDEX(LOOKAHEAD!$I$5:$I$204,MATCH(B9,LOOKAHEAD!$A$5:$A$204,0)),"")) -> 46333 | E9: Subcontratos | F9: Firma contrato hormigón premezclado Q4 | G9: Administrador de Obra | H9: 46297 | I9: =IF(OR(D9="",D9=0),"",D9-$D$2) -> 46330 | J9: 46325 | L9: =IF(B9="","",IF(K9<>"","Liberado","Pendiente")) -> Pendiente | M9: =IF(B9="","",IF(L9="Liberado",IF(OR(I9="",K9<=I9),"A tiempo","Liberada tarde"),IF(J9="","Sin compromiso",IF(TODAY()>J9,"VENCIDA",IF(AND(I9<>"",J9>I9),"En riesgo","En gestión"))))) -> En gestión | N9: =IF(OR(B9="",I9=""),"",IF(K9<>"",I9-K9,IF(J9<>"",I9-J9,""))) -> 5
A10: R-006 | B10: LA-007 | C10: =IF(B10="","",IFERROR(INDEX(LOOKAHEAD!$B$5:$B$204,MATCH(B10,LOOKAHEAD!$A$5:$A$204,0)),"ID no existe")) -> Canalización eléctrica embutida losa P2 | D10: =IF(B10="","",IFERROR(INDEX(LOOKAHEAD!$I$5:$I$204,MATCH(B10,LOOKAHEAD!$A$5:$A$204,0)),"")) -> 46328 | E10: Subcontratos | F10: Ingreso subcontrato eléctrico a obra | G10: Administrador de Obra | H10: 46297 | I10: =IF(OR(D10="",D10=0),"",D10-$D$2) -> 46325 | J10: 46318 | L10: =IF(B10="","",IF(K10<>"","Liberado","Pendiente")) -> Pendiente | M10: =IF(B10="","",IF(L10="Liberado",IF(OR(I10="",K10<=I10),"A tiempo","Liberada tarde"),IF(J10="","Sin compromiso",IF(TODAY()>J10,"VENCIDA",IF(AND(I10<>"",J10>I10),"En riesgo","En gestión"))))) -> En gestión | N10: =IF(OR(B10="",I10=""),"",IF(K10<>"",I10-K10,IF(J10<>"",I10-J10,""))) -> 7
A11: R-007 | B11: LA-008 | C11: =IF(B11="","",IFERROR(INDEX(LOOKAHEAD!$B$5:$B$204,MATCH(B11,LOOKAHEAD!$A$5:$A$204,0)),"ID no existe")) -> Pasadas sanitarias losa P2 | D11: =IF(B11="","",IFERROR(INDEX(LOOKAHEAD!$I$5:$I$204,MATCH(B11,LOOKAHEAD!$A$5:$A$204,0)),"")) -> 46328 | E11: Diseño / Ingeniería (RFI) | F11: Plano de pasadas sanitarias coordinado (BIM) | G11: Oficina Técnica | H11: 46300 | I11: =IF(OR(D11="",D11=0),"",D11-$D$2) -> 46325 | J11: 46322 | L11: =IF(B11="","",IF(K11<>"","Liberado","Pendiente")) -> Pendiente | M11: =IF(B11="","",IF(L11="Liberado",IF(OR(I11="",K11<=I11),"A tiempo","Liberada tarde"),IF(J11="","Sin compromiso",IF(TODAY()>J11,"VENCIDA",IF(AND(I11<>"",J11>I11),"En riesgo","En gestión"))))) -> En gestión | N11: =IF(OR(B11="",I11=""),"",IF(K11<>"",I11-K11,IF(J11<>"",I11-J11,""))) -> 3
A12: R-008 | B12: LA-002 | C12: =IF(B12="","",IFERROR(INDEX(LOOKAHEAD!$B$5:$B$204,MATCH(B12,LOOKAHEAD!$A$5:$A$204,0)),"ID no existe")) -> Enfierradura muros piso 1 | D12: =IF(B12="","",IFERROR(INDEX(LOOKAHEAD!$I$5:$I$204,MATCH(B12,LOOKAHEAD!$A$5:$A$204,0)),"")) -> 46300 | E12: Mano de obra | F12: Refuerzo de 4 enfierradores | G12: Jefe de Terreno | H12: 46290 | I12: =IF(OR(D12="",D12=0),"",D12-$D$2) -> 46297 | J12: 46297 | K12: 46297 | L12: =IF(B12="","",IF(K12<>"","Liberado","Pendiente")) -> Liberado | M12: =IF(B12="","",IF(L12="Liberado",IF(OR(I12="",K12<=I12),"A tiempo","Liberada tarde"),IF(J12="","Sin compromiso",IF(TODAY()>J12,"VENCIDA",IF(AND(I12<>"",J12>I12),"En riesgo","En gestión"))))) -> A tiempo | N12: =IF(OR(B12="",I12=""),"",IF(K12<>"",I12-K12,IF(J12<>"",I12-J12,""))) -> 0
C13: =IF(B13="","",IFERROR(INDEX(LOOKAHEAD!$B$5:$B$204,MATCH(B13,LOOKAHEAD!$A$5:$A$204,0)),"ID no existe")) | D13: =IF(B13="","",IFERROR(INDEX(LOOKAHEAD!$I$5:$I$204,MATCH(B13,LOOKAHEAD!$A$5:$A$204,0)),"")) | I13: =IF(OR(D13="",D13=0),"",D13-$D$2) | L13: =IF(B13="","",IF(K13<>"","Liberado","Pendiente")) | M13: =IF(B13="","",IF(L13="Liberado",IF(OR(I13="",K13<=I13),"A tiempo","Liberada tarde"),IF(J13="","Sin compromiso",IF(TODAY()>J13,"VENCIDA",IF(AND(I13<>"",J13>I13),"En riesgo","En gestión"))))) | N13: =IF(OR(B13="",I13=""),"",IF(K13<>"",I13-K13,IF(J13<>"",I13-J13,"")))
C14: =IF(B14="","",IFERROR(INDEX(LOOKAHEAD!$B$5:$B$204,MATCH(B14,LOOKAHEAD!$A$5:$A$204,0)),"ID no existe")) | D14: =IF(B14="","",IFERROR(INDEX(LOOKAHEAD!$I$5:$I$204,MATCH(B14,LOOKAHEAD!$A$5:$A$204,0)),"")) | I14: =IF(OR(D14="",D14=0),"",D14-$D$2) | L14: =IF(B14="","",IF(K14<>"","Liberado","Pendiente")) | M14: =IF(B14="","",IF(L14="Liberado",IF(OR(I14="",K14<=I14),"A tiempo","Liberada tarde"),IF(J14="","Sin compromiso",IF(TODAY()>J14,"VENCIDA",IF(AND(I14<>"",J14>I14),"En riesgo","En gestión"))))) | N14: =IF(OR(B14="",I14=""),"",IF(K14<>"",I14-K14,IF(J14<>"",I14-J14,"")))
C15: =IF(B15="","",IFERROR(INDEX(LOOKAHEAD!$B$5:$B$204,MATCH(B15,LOOKAHEAD!$A$5:$A$204,0)),"ID no existe")) | D15: =IF(B15="","",IFERROR(INDEX(LOOKAHEAD!$I$5:$I$204,MATCH(B15,LOOKAHEAD!$A$5:$A$204,0)),"")) | I15: =IF(OR(D15="",D15=0),"",D15-$D$2) | L15: =IF(B15="","",IF(K15<>"","Liberado","Pendiente")) | M15: =IF(B15="","",IF(L15="Liberado",IF(OR(I15="",K15<=I15),"A tiempo","Liberada tarde"),IF(J15="","Sin compromiso",IF(TODAY()>J15,"VENCIDA",IF(AND(I15<>"",J15>I15),"En riesgo","En gestión"))))) | N15: =IF(OR(B15="",I15=""),"",IF(K15<>"",I15-K15,IF(J15<>"",I15-J15,"")))
C16: =IF(B16="","",IFERROR(INDEX(LOOKAHEAD!$B$5:$B$204,MATCH(B16,LOOKAHEAD!$A$5:$A$204,0)),"ID no existe")) | D16: =IF(B16="","",IFERROR(INDEX(LOOKAHEAD!$I$5:$I$204,MATCH(B16,LOOKAHEAD!$A$5:$A$204,0)),"")) | I16: =IF(OR(D16="",D16=0),"",D16-$D$2) | L16: =IF(B16="","",IF(K16<>"","Liberado","Pendiente")) | M16: =IF(B16="","",IF(L16="Liberado",IF(OR(I16="",K16<=I16),"A tiempo","Liberada tarde"),IF(J16="","Sin compromiso",IF(TODAY()>J16,"VENCIDA",IF(AND(I16<>"",J16>I16),"En riesgo","En gestión"))))) | N16: =IF(OR(B16="",I16=""),"",IF(K16<>"",I16-K16,IF(J16<>"",I16-J16,"")))
C17: =IF(B17="","",IFERROR(INDEX(LOOKAHEAD!$B$5:$B$204,MATCH(B17,LOOKAHEAD!$A$5:$A$204,0)),"ID no existe")) | D17: =IF(B17="","",IFERROR(INDEX(LOOKAHEAD!$I$5:$I$204,MATCH(B17,LOOKAHEAD!$A$5:$A$204,0)),"")) | I17: =IF(OR(D17="",D17=0),"",D17-$D$2) | L17: =IF(B17="","",IF(K17<>"","Liberado","Pendiente")) | M17: =IF(B17="","",IF(L17="Liberado",IF(OR(I17="",K17<=I17),"A tiempo","Liberada tarde"),IF(J17="","Sin compromiso",IF(TODAY()>J17,"VENCIDA",IF(AND(I17<>"",J17>I17),"En riesgo","En gestión"))))) | N17: =IF(OR(B17="",I17=""),"",IF(K17<>"",I17-K17,IF(J17<>"",I17-J17,"")))
C18: =IF(B18="","",IFERROR(INDEX(LOOKAHEAD!$B$5:$B$204,MATCH(B18,LOOKAHEAD!$A$5:$A$204,0)),"ID no existe")) | D18: =IF(B18="","",IFERROR(INDEX(LOOKAHEAD!$I$5:$I$204,MATCH(B18,LOOKAHEAD!$A$5:$A$204,0)),"")) | I18: =IF(OR(D18="",D18=0),"",D18-$D$2) | L18: =IF(B18="","",IF(K18<>"","Liberado","Pendiente")) | M18: =IF(B18="","",IF(L18="Liberado",IF(OR(I18="",K18<=I18),"A tiempo","Liberada tarde"),IF(J18="","Sin compromiso",IF(TODAY()>J18,"VENCIDA",IF(AND(I18<>"",J18>I18),"En riesgo","En gestión"))))) | N18: =IF(OR(B18="",I18=""),"",IF(K18<>"",I18-K18,IF(J18<>"",I18-J18,"")))
C19: =IF(B19="","",IFERROR(INDEX(LOOKAHEAD!$B$5:$B$204,MATCH(B19,LOOKAHEAD!$A$5:$A$204,0)),"ID no existe")) | D19: =IF(B19="","",IFERROR(INDEX(LOOKAHEAD!$I$5:$I$204,MATCH(B19,LOOKAHEAD!$A$5:$A$204,0)),"")) | I19: =IF(OR(D19="",D19=0),"",D19-$D$2) | L19: =IF(B19="","",IF(K19<>"","Liberado","Pendiente")) | M19: =IF(B19="","",IF(L19="Liberado",IF(OR(I19="",K19<=I19),"A tiempo","Liberada tarde"),IF(J19="","Sin compromiso",IF(TODAY()>J19,"VENCIDA",IF(AND(I19<>"",J19>I19),"En riesgo","En gestión"))))) | N19: =IF(OR(B19="",I19=""),"",IF(K19<>"",I19-K19,IF(J19<>"",I19-J19,"")))
C20: =IF(B20="","",IFERROR(INDEX(LOOKAHEAD!$B$5:$B$204,MATCH(B20,LOOKAHEAD!$A$5:$A$204,0)),"ID no existe")) | D20: =IF(B20="","",IFERROR(INDEX(LOOKAHEAD!$I$5:$I$204,MATCH(B20,LOOKAHEAD!$A$5:$A$204,0)),"")) | I20: =IF(OR(D20="",D20=0),"",D20-$D$2) | L20: =IF(B20="","",IF(K20<>"","Liberado","Pendiente")) | M20: =IF(B20="","",IF(L20="Liberado",IF(OR(I20="",K20<=I20),"A tiempo","Liberada tarde"),IF(J20="","Sin compromiso",IF(TODAY()>J20,"VENCIDA",IF(AND(I20<>"",J20>I20),"En riesgo","En gestión"))))) | N20: =IF(OR(B20="",I20=""),"",IF(K20<>"",I20-K20,IF(J20<>"",I20-J20,"")))
C21: =IF(B21="","",IFERROR(INDEX(LOOKAHEAD!$B$5:$B$204,MATCH(B21,LOOKAHEAD!$A$5:$A$204,0)),"ID no existe")) | D21: =IF(B21="","",IFERROR(INDEX(LOOKAHEAD!$I$5:$I$204,MATCH(B21,LOOKAHEAD!$A$5:$A$204,0)),"")) | I21: =IF(OR(D21="",D21=0),"",D21-$D$2) | L21: =IF(B21="","",IF(K21<>"","Liberado","Pendiente")) | M21: =IF(B21="","",IF(L21="Liberado",IF(OR(I21="",K21<=I21),"A tiempo","Liberada tarde"),IF(J21="","Sin compromiso",IF(TODAY()>J21,"VENCIDA",IF(AND(I21<>"",J21>I21),"En riesgo","En gestión"))))) | N21: =IF(OR(B21="",I21=""),"",IF(K21<>"",I21-K21,IF(J21<>"",I21-J21,"")))
C22: =IF(B22="","",IFERROR(INDEX(LOOKAHEAD!$B$5:$B$204,MATCH(B22,LOOKAHEAD!$A$5:$A$204,0)),"ID no existe")) | D22: =IF(B22="","",IFERROR(INDEX(LOOKAHEAD!$I$5:$I$204,MATCH(B22,LOOKAHEAD!$A$5:$A$204,0)),"")) | I22: =IF(OR(D22="",D22=0),"",D22-$D$2) | L22: =IF(B22="","",IF(K22<>"","Liberado","Pendiente")) | M22: =IF(B22="","",IF(L22="Liberado",IF(OR(I22="",K22<=I22),"A tiempo","Liberada tarde"),IF(J22="","Sin compromiso",IF(TODAY()>J22,"VENCIDA",IF(AND(I22<>"",J22>I22),"En riesgo","En gestión"))))) | N22: =IF(OR(B22="",I22=""),"",IF(K22<>"",I22-K22,IF(J22<>"",I22-J22,"")))
C23: =IF(B23="","",IFERROR(INDEX(LOOKAHEAD!$B$5:$B$204,MATCH(B23,LOOKAHEAD!$A$5:$A$204,0)),"ID no existe")) | D23: =IF(B23="","",IFERROR(INDEX(LOOKAHEAD!$I$5:$I$204,MATCH(B23,LOOKAHEAD!$A$5:$A$204,0)),"")) | I23: =IF(OR(D23="",D23=0),"",D23-$D$2) | L23: =IF(B23="","",IF(K23<>"","Liberado","Pendiente")) | M23: =IF(B23="","",IF(L23="Liberado",IF(OR(I23="",K23<=I23),"A tiempo","Liberada tarde"),IF(J23="","Sin compromiso",IF(TODAY()>J23,"VENCIDA",IF(AND(I23<>"",J23>I23),"En riesgo","En gestión"))))) | N23: =IF(OR(B23="",I23=""),"",IF(K23<>"",I23-K23,IF(J23<>"",I23-J23,"")))
C24: =IF(B24="","",IFERROR(INDEX(LOOKAHEAD!$B$5:$B$204,MATCH(B24,LOOKAHEAD!$A$5:$A$204,0)),"ID no existe")) | D24: =IF(B24="","",IFERROR(INDEX(LOOKAHEAD!$I$5:$I$204,MATCH(B24,LOOKAHEAD!$A$5:$A$204,0)),"")) | I24: =IF(OR(D24="",D24=0),"",D24-$D$2) | L24: =IF(B24="","",IF(K24<>"","Liberado","Pendiente")) | M24: =IF(B24="","",IF(L24="Liberado",IF(OR(I24="",K24<=I24),"A tiempo","Liberada tarde"),IF(J24="","Sin compromiso",IF(TODAY()>J24,"VENCIDA",IF(AND(I24<>"",J24>I24),"En riesgo","En gestión"))))) | N24: =IF(OR(B24="",I24=""),"",IF(K24<>"",I24-K24,IF(J24<>"",I24-J24,"")))
... C304: =IF(B304="","",IFERROR(INDEX(LOOKAHEAD!$B$5:$B$204,MATCH(B304,LOOKAHEAD!$A$5:$A$204,0)),"ID no existe")) | D304: =IF(B304="","",IFERROR(INDEX(LOOKAHEAD!$I$5:$I$204,MATCH(B304,LOOKAHEAD!$A$5:$A$204,0)),"")) | I304: =IF(OR(D304="",D304=0),"",D304-$D$2) | L304: =IF(B304="","",IF(K304<>"","Liberado","Pendiente")) | M304: =IF(B304="","",IF(L304="Liberado",IF(OR(I304="",K304<=I304),"A tiempo","Liberada tarde"),IF(J304="","Sin compromiso",IF(TODAY()>J304,"VENCIDA",IF(AND(I304<>"",J304>I304),"En riesgo","En gestión"))))) | N304: =IF(OR(B304="",I304=""),"",IF(K304<>"",I304-K304,IF(J304<>"",I304-J304,"")))

Sheet SEMANAL
A1: PLAN SEMANAL – PLANIFICACIÓN OPERATIVA (LUNES A SÁBADO) | D1: Tabla acumulada: cada fila lleva su N° de semana. Solo acepta actividades LISTA.
A2: Semana a mostrar: | C2: 41 | D2: Último planificador: | F2: Jefe de Terreno | H2: PPC SEMANA: | J2: =IFERROR(COUNTIFS($B$7:$B$506,$C$2,$Y$7:$Y$506,"Sí")/COUNTIFS($B$7:$B$506,$C$2,$Y$7:$Y$506,"?*"),"") -> 0.66666667 | L2: PPC GLOBAL: | N2: =IFERROR(COUNTIF($Y$7:$Y$506,"Sí")/COUNTIF($Y$7:$Y$506,"?*"),"") -> 0.6
I4: PPC diario → | J4: =IFERROR(SUMPRODUCT(($B$7:$B$506=$C$2)*(J$7:J$506>0)*(P$7:P$506>=J$7:J$506))/SUMPRODUCT(($B$7:$B$506=$C$2)*(J$7:J$506>0)),"") -> 1 | K4: =IFERROR(SUMPRODUCT(($B$7:$B$506=$C$2)*(K$7:K$506>0)*(Q$7:Q$506>=K$7:K$506))/SUMPRODUCT(($B$7:$B$506=$C$2)*(K$7:K$506>0)),"") -> 1 | L4: =IFERROR(SUMPRODUCT(($B$7:$B$506=$C$2)*(L$7:L$506>0)*(R$7:R$506>=L$7:L$506))/SUMPRODUCT(($B$7:$B$506=$C$2)*(L$7:L$506>0)),"") -> 0.5 | M4: =IFERROR(SUMPRODUCT(($B$7:$B$506=$C$2)*(M$7:M$506>0)*(S$7:S$506>=M$7:M$506))/SUMPRODUCT(($B$7:$B$506=$C$2)*(M$7:M$506>0)),"") -> 1 | N4: =IFERROR(SUMPRODUCT(($B$7:$B$506=$C$2)*(N$7:N$506>0)*(T$7:T$506>=N$7:N$506))/SUMPRODUCT(($B$7:$B$506=$C$2)*(N$7:N$506>0)),"") -> 0.66666667 | O4: =IFERROR(SUMPRODUCT(($B$7:$B$506=$C$2)*(O$7:O$506>0)*(U$7:U$506>=O$7:O$506))/SUMPRODUCT(($B$7:$B$506=$C$2)*(O$7:O$506>0)),"") -> 1
J5: PROGRAMADO (cantidad) | P5: EJECUTADO (cantidad)
A6: ID Semanal | B6: Semana N° | C6: ID Actividad | D6: Actividad | E6: Ubicación | F6: Estado Lookahead | G6: Cuadrilla / Subcontrato | H6: Capataz / Jefe cuadrilla | I6: Unidad | J6: Lu | K6: Ma | L6: Mi | M6: Ju | N6: Vi | O6: Sá | P6: Lu | Q6: Ma | R6: Mi | S6: Ju | T6: Vi | U6: Sá | V6: Total progr. | W6: Total ejec. | X6: % Cumpl. | Y6: ¿Cumplió? | Z6: Causa de incumplimiento | AA6: Acción correctiva
A7: S40-01 | B7: 40 | C7: LA-001 | D7: =IF(C7="","",IFERROR(INDEX(LOOKAHEAD!$B$5:$B$204,MATCH(C7,LOOKAHEAD!$A$5:$A$204,0)),"")) -> Hormigonado fundaciones eje D-F | E7: =IF(C7="","",IFERROR(INDEX(LOOKAHEAD!$E$5:$E$204,MATCH(C7,LOOKAHEAD!$A$5:$A$204,0)),"")) -> Eje D-F | F7: =IF(C7="","",IFERROR(INDEX(LOOKAHEAD!$M$5:$M$204,MATCH(C7,LOOKAHEAD!$A$5:$A$204,0)),"")) -> LISTA | G7: Cuadrilla Hormigón | H7: J. Pérez | I7: =IF(C7="","",IFERROR(INDEX(LOOKAHEAD!$G$5:$G$204,MATCH(C7,LOOKAHEAD!$A$5:$A$204,0)),"")) -> m3 | K7: 10 | M7: 10 | Q7: 10 | S7: 10 | V7: =IF(C7="","",SUM(J7:O7)) -> 20 | W7: =IF(C7="","",SUM(P7:U7)) -> 20 | X7: =IF(OR(C7="",V7=0),"",W7/V7) -> 1 | Y7: =IF(OR(C7="",V7=0),"",IF(W7>=V7,"Sí","No")) -> Sí
A8: S40-02 | B8: 40 | C8: LA-002 | D8: =IF(C8="","",IFERROR(INDEX(LOOKAHEAD!$B$5:$B$204,MATCH(C8,LOOKAHEAD!$A$5:$A$204,0)),"")) -> Enfierradura muros piso 1 | E8: =IF(C8="","",IFERROR(INDEX(LOOKAHEAD!$E$5:$E$204,MATCH(C8,LOOKAHEAD!$A$5:$A$204,0)),"")) -> Piso 1 | F8: =IF(C8="","",IFERROR(INDEX(LOOKAHEAD!$M$5:$M$204,MATCH(C8,LOOKAHEAD!$A$5:$A$204,0)),"")) -> LISTA | G8: Cuadrilla Enfierradura | H8: M. Soto | I8: =IF(C8="","",IFERROR(INDEX(LOOKAHEAD!$G$5:$G$204,MATCH(C8,LOOKAHEAD!$A$5:$A$204,0)),"")) -> kg | J8: 500 | K8: 500 | L8: 500 | M8: 500 | N8: 500 | O8: 250 | P8: 500 | Q8: 450 | R8: 400 | S8: 500 | T8: 500 | U8: 250 | V8: =IF(C8="","",SUM(J8:O8)) -> 2750 | W8: =IF(C8="","",SUM(P8:U8)) -> 2600 | X8: =IF(OR(C8="",V8=0),"",W8/V8) -> 0.94545455 | Y8: =IF(OR(C8="",V8=0),"",IF(W8>=V8,"Sí","No")) -> No | Z8: Falta de mano de obra | AA8: Refuerzo de 4 enfierradores (R-008)
A9: S41-01 | B9: 41 | C9: LA-001 | D9: =IF(C9="","",IFERROR(INDEX(LOOKAHEAD!$B$5:$B$204,MATCH(C9,LOOKAHEAD!$A$5:$A$204,0)),"")) -> Hormigonado fundaciones eje D-F | E9: =IF(C9="","",IFERROR(INDEX(LOOKAHEAD!$E$5:$E$204,MATCH(C9,LOOKAHEAD!$A$5:$A$204,0)),"")) -> Eje D-F | F9: =IF(C9="","",IFERROR(INDEX(LOOKAHEAD!$M$5:$M$204,MATCH(C9,LOOKAHEAD!$A$5:$A$204,0)),"")) -> LISTA | G9: Cuadrilla Hormigón | H9: J. Pérez | I9: =IF(C9="","",IFERROR(INDEX(LOOKAHEAD!$G$5:$G$204,MATCH(C9,LOOKAHEAD!$A$5:$A$204,0)),"")) -> m3 | J9: 10 | L9: 10 | N9: 5 | P9: 10 | R9: 0 | T9: 0 | V9: =IF(C9="","",SUM(J9:O9)) -> 25 | W9: =IF(C9="","",SUM(P9:U9)) -> 10 | X9: =IF(OR(C9="",V9=0),"",W9/V9) -> 0.4 | Y9: =IF(OR(C9="",V9=0),"",IF(W9>=V9,"Sí","No")) -> No | Z9: Clima | AA9: Reprogramar con pronóstico; carpa de protección
A10: S41-02 | B10: 41 | C10: LA-002 | D10: =IF(C10="","",IFERROR(INDEX(LOOKAHEAD!$B$5:$B$204,MATCH(C10,LOOKAHEAD!$A$5:$A$204,0)),"")) -> Enfierradura muros piso 1 | E10: =IF(C10="","",IFERROR(INDEX(LOOKAHEAD!$E$5:$E$204,MATCH(C10,LOOKAHEAD!$A$5:$A$204,0)),"")) -> Piso 1 | F10: =IF(C10="","",IFERROR(INDEX(LOOKAHEAD!$M$5:$M$204,MATCH(C10,LOOKAHEAD!$A$5:$A$204,0)),"")) -> LISTA | G10: Cuadrilla Enfierradura | H10: M. Soto | I10: =IF(C10="","",IFERROR(INDEX(LOOKAHEAD!$G$5:$G$204,MATCH(C10,LOOKAHEAD!$A$5:$A$204,0)),"")) -> kg | J10: 500 | K10: 500 | L10: 500 | M10: 500 | N10: 500 | P10: 500 | Q10: 500 | R10: 500 | S10: 500 | T10: 500 | V10: =IF(C10="","",SUM(J10:O10)) -> 2500 | W10: =IF(C10="","",SUM(P10:U10)) -> 2500 | X10: =IF(OR(C10="",V10=0),"",W10/V10) -> 1 | Y10: =IF(OR(C10="",V10=0),"",IF(W10>=V10,"Sí","No")) -> Sí
A11: S41-03 | B11: 41 | C11: LA-003 | D11: =IF(C11="","",IFERROR(INDEX(LOOKAHEAD!$B$5:$B$204,MATCH(C11,LOOKAHEAD!$A$5:$A$204,0)),"")) -> Moldaje muros piso 1 | E11: =IF(C11="","",IFERROR(INDEX(LOOKAHEAD!$E$5:$E$204,MATCH(C11,LOOKAHEAD!$A$5:$A$204,0)),"")) -> Piso 1 | F11: =IF(C11="","",IFERROR(INDEX(LOOKAHEAD!$M$5:$M$204,MATCH(C11,LOOKAHEAD!$A$5:$A$204,0)),"")) -> LISTA | G11: Cuadrilla Moldajes | H11: R. Díaz | I11: =IF(C11="","",IFERROR(INDEX(LOOKAHEAD!$G$5:$G$204,MATCH(C11,LOOKAHEAD!$A$5:$A$204,0)),"")) -> m2 | M11: 40 | N11: 40 | O11: 20 | S11: 40 | T11: 40 | U11: 20 | V11: =IF(C11="","",SUM(J11:O11)) -> 100 | W11: =IF(C11="","",SUM(P11:U11)) -> 100 | X11: =IF(OR(C11="",V11=0),"",W11/V11) -> 1 | Y11: =IF(OR(C11="",V11=0),"",IF(W11>=V11,"Sí","No")) -> Sí
D12: =IF(C12="","",IFERROR(INDEX(LOOKAHEAD!$B$5:$B$204,MATCH(C12,LOOKAHEAD!$A$5:$A$204,0)),"")) | E12: =IF(C12="","",IFERROR(INDEX(LOOKAHEAD!$E$5:$E$204,MATCH(C12,LOOKAHEAD!$A$5:$A$204,0)),"")) | F12: =IF(C12="","",IFERROR(INDEX(LOOKAHEAD!$M$5:$M$204,MATCH(C12,LOOKAHEAD!$A$5:$A$204,0)),"")) | I12: =IF(C12="","",IFERROR(INDEX(LOOKAHEAD!$G$5:$G$204,MATCH(C12,LOOKAHEAD!$A$5:$A$204,0)),"")) | V12: =IF(C12="","",SUM(J12:O12)) | W12: =IF(C12="","",SUM(P12:U12)) | X12: =IF(OR(C12="",V12=0),"",W12/V12) | Y12: =IF(OR(C12="",V12=0),"",IF(W12>=V12,"Sí","No"))
D13: =IF(C13="","",IFERROR(INDEX(LOOKAHEAD!$B$5:$B$204,MATCH(C13,LOOKAHEAD!$A$5:$A$204,0)),"")) | E13: =IF(C13="","",IFERROR(INDEX(LOOKAHEAD!$E$5:$E$204,MATCH(C13,LOOKAHEAD!$A$5:$A$204,0)),"")) | F13: =IF(C13="","",IFERROR(INDEX(LOOKAHEAD!$M$5:$M$204,MATCH(C13,LOOKAHEAD!$A$5:$A$204,0)),"")) | I13: =IF(C13="","",IFERROR(INDEX(LOOKAHEAD!$G$5:$G$204,MATCH(C13,LOOKAHEAD!$A$5:$A$204,0)),"")) | V13: =IF(C13="","",SUM(J13:O13)) | W13: =IF(C13="","",SUM(P13:U13)) | X13: =IF(OR(C13="",V13=0),"",W13/V13) | Y13: =IF(OR(C13="",V13=0),"",IF(W13>=V13,"Sí","No"))
D14: =IF(C14="","",IFERROR(INDEX(LOOKAHEAD!$B$5:$B$204,MATCH(C14,LOOKAHEAD!$A$5:$A$204,0)),"")) | E14: =IF(C14="","",IFERROR(INDEX(LOOKAHEAD!$E$5:$E$204,MATCH(C14,LOOKAHEAD!$A$5:$A$204,0)),"")) | F14: =IF(C14="","",IFERROR(INDEX(LOOKAHEAD!$M$5:$M$204,MATCH(C14,LOOKAHEAD!$A$5:$A$204,0)),"")) | I14: =IF(C14="","",IFERROR(INDEX(LOOKAHEAD!$G$5:$G$204,MATCH(C14,LOOKAHEAD!$A$5:$A$204,0)),"")) | V14: =IF(C14="","",SUM(J14:O14)) | W14: =IF(C14="","",SUM(P14:U14)) | X14: =IF(OR(C14="",V14=0),"",W14/V14) | Y14: =IF(OR(C14="",V14=0),"",IF(W14>=V14,"Sí","No"))
D15: =IF(C15="","",IFERROR(INDEX(LOOKAHEAD!$B$5:$B$204,MATCH(C15,LOOKAHEAD!$A$5:$A$204,0)),"")) | E15: =IF(C15="","",IFERROR(INDEX(LOOKAHEAD!$E$5:$E$204,MATCH(C15,LOOKAHEAD!$A$5:$A$204,0)),"")) | F15: =IF(C15="","",IFERROR(INDEX(LOOKAHEAD!$M$5:$M$204,MATCH(C15,LOOKAHEAD!$A$5:$A$204,0)),"")) | I15: =IF(C15="","",IFERROR(INDEX(LOOKAHEAD!$G$5:$G$204,MATCH(C15,LOOKAHEAD!$A$5:$A$204,0)),"")) | V15: =IF(C15="","",SUM(J15:O15)) | W15: =IF(C15="","",SUM(P15:U15)) | X15: =IF(OR(C15="",V15=0),"",W15/V15) | Y15: =IF(OR(C15="",V15=0),"",IF(W15>=V15,"Sí","No"))
D16: =IF(C16="","",IFERROR(INDEX(LOOKAHEAD!$B$5:$B$204,MATCH(C16,LOOKAHEAD!$A$5:$A$204,0)),"")) | E16: =IF(C16="","",IFERROR(INDEX(LOOKAHEAD!$E$5:$E$204,MATCH(C16,LOOKAHEAD!$A$5:$A$204,0)),"")) | F16: =IF(C16="","",IFERROR(INDEX(LOOKAHEAD!$M$5:$M$204,MATCH(C16,LOOKAHEAD!$A$5:$A$204,0)),"")) | I16: =IF(C16="","",IFERROR(INDEX(LOOKAHEAD!$G$5:$G$204,MATCH(C16,LOOKAHEAD!$A$5:$A$204,0)),"")) | V16: =IF(C16="","",SUM(J16:O16)) | W16: =IF(C16="","",SUM(P16:U16)) | X16: =IF(OR(C16="",V16=0),"",W16/V16) | Y16: =IF(OR(C16="",V16=0),"",IF(W16>=V16,"Sí","No"))
D17: =IF(C17="","",IFERROR(INDEX(LOOKAHEAD!$B$5:$B$204,MATCH(C17,LOOKAHEAD!$A$5:$A$204,0)),"")) | E17: =IF(C17="","",IFERROR(INDEX(LOOKAHEAD!$E$5:$E$204,MATCH(C17,LOOKAHEAD!$A$5:$A$204,0)),"")) | F17: =IF(C17="","",IFERROR(INDEX(LOOKAHEAD!$M$5:$M$204,MATCH(C17,LOOKAHEAD!$A$5:$A$204,0)),"")) | I17: =IF(C17="","",IFERROR(INDEX(LOOKAHEAD!$G$5:$G$204,MATCH(C17,LOOKAHEAD!$A$5:$A$204,0)),"")) | V17: =IF(C17="","",SUM(J17:O17)) | W17: =IF(C17="","",SUM(P17:U17)) | X17: =IF(OR(C17="",V17=0),"",W17/V17) | Y17: =IF(OR(C17="",V17=0),"",IF(W17>=V17,"Sí","No"))
D18: =IF(C18="","",IFERROR(INDEX(LOOKAHEAD!$B$5:$B$204,MATCH(C18,LOOKAHEAD!$A$5:$A$204,0)),"")) | E18: =IF(C18="","",IFERROR(INDEX(LOOKAHEAD!$E$5:$E$204,MATCH(C18,LOOKAHEAD!$A$5:$A$204,0)),"")) | F18: =IF(C18="","",IFERROR(INDEX(LOOKAHEAD!$M$5:$M$204,MATCH(C18,LOOKAHEAD!$A$5:$A$204,0)),"")) | I18: =IF(C18="","",IFERROR(INDEX(LOOKAHEAD!$G$5:$G$204,MATCH(C18,LOOKAHEAD!$A$5:$A$204,0)),"")) | V18: =IF(C18="","",SUM(J18:O18)) | W18: =IF(C18="","",SUM(P18:U18)) | X18: =IF(OR(C18="",V18=0),"",W18/V18) | Y18: =IF(OR(C18="",V18=0),"",IF(W18>=V18,"Sí","No"))
D19: =IF(C19="","",IFERROR(INDEX(LOOKAHEAD!$B$5:$B$204,MATCH(C19,LOOKAHEAD!$A$5:$A$204,0)),"")) | E19: =IF(C19="","",IFERROR(INDEX(LOOKAHEAD!$E$5:$E$204,MATCH(C19,LOOKAHEAD!$A$5:$A$204,0)),"")) | F19: =IF(C19="","",IFERROR(INDEX(LOOKAHEAD!$M$5:$M$204,MATCH(C19,LOOKAHEAD!$A$5:$A$204,0)),"")) | I19: =IF(C19="","",IFERROR(INDEX(LOOKAHEAD!$G$5:$G$204,MATCH(C19,LOOKAHEAD!$A$5:$A$204,0)),"")) | V19: =IF(C19="","",SUM(J19:O19)) | W19: =IF(C19="","",SUM(P19:U19)) | X19: =IF(OR(C19="",V19=0),"",W19/V19) | Y19: =IF(OR(C19="",V19=0),"",IF(W19>=V19,"Sí","No"))
D20: =IF(C20="","",IFERROR(INDEX(LOOKAHEAD!$B$5:$B$204,MATCH(C20,LOOKAHEAD!$A$5:$A$204,0)),"")) | E20: =IF(C20="","",IFERROR(INDEX(LOOKAHEAD!$E$5:$E$204,MATCH(C20,LOOKAHEAD!$A$5:$A$204,0)),"")) | F20: =IF(C20="","",IFERROR(INDEX(LOOKAHEAD!$M$5:$M$204,MATCH(C20,LOOKAHEAD!$A$5:$A$204,0)),"")) | I20: =IF(C20="","",IFERROR(INDEX(LOOKAHEAD!$G$5:$G$204,MATCH(C20,LOOKAHEAD!$A$5:$A$204,0)),"")) | V20: =IF(C20="","",SUM(J20:O20)) | W20: =IF(C20="","",SUM(P20:U20)) | X20: =IF(OR(C20="",V20=0),"",W20/V20) | Y20: =IF(OR(C20="",V20=0),"",IF(W20>=V20,"Sí","No"))
D21: =IF(C21="","",IFERROR(INDEX(LOOKAHEAD!$B$5:$B$204,MATCH(C21,LOOKAHEAD!$A$5:$A$204,0)),"")) | E21: =IF(C21="","",IFERROR(INDEX(LOOKAHEAD!$E$5:$E$204,MATCH(C21,LOOKAHEAD!$A$5:$A$204,0)),"")) | F21: =IF(C21="","",IFERROR(INDEX(LOOKAHEAD!$M$5:$M$204,MATCH(C21,LOOKAHEAD!$A$5:$A$204,0)),"")) | I21: =IF(C21="","",IFERROR(INDEX(LOOKAHEAD!$G$5:$G$204,MATCH(C21,LOOKAHEAD!$A$5:$A$204,0)),"")) | V21: =IF(C21="","",SUM(J21:O21)) | W21: =IF(C21="","",SUM(P21:U21)) | X21: =IF(OR(C21="",V21=0),"",W21/V21) | Y21: =IF(OR(C21="",V21=0),"",IF(W21>=V21,"Sí","No"))
D22: =IF(C22="","",IFERROR(INDEX(LOOKAHEAD!$B$5:$B$204,MATCH(C22,LOOKAHEAD!$A$5:$A$204,0)),"")) | E22: =IF(C22="","",IFERROR(INDEX(LOOKAHEAD!$E$5:$E$204,MATCH(C22,LOOKAHEAD!$A$5:$A$204,0)),"")) | F22: =IF(C22="","",IFERROR(INDEX(LOOKAHEAD!$M$5:$M$204,MATCH(C22,LOOKAHEAD!$A$5:$A$204,0)),"")) | I22: =IF(C22="","",IFERROR(INDEX(LOOKAHEAD!$G$5:$G$204,MATCH(C22,LOOKAHEAD!$A$5:$A$204,0)),"")) | V22: =IF(C22="","",SUM(J22:O22)) | W22: =IF(C22="","",SUM(P22:U22)) | X22: =IF(OR(C22="",V22=0),"",W22/V22) | Y22: =IF(OR(C22="",V22=0),"",IF(W22>=V22,"Sí","No"))
D23: =IF(C23="","",IFERROR(INDEX(LOOKAHEAD!$B$5:$B$204,MATCH(C23,LOOKAHEAD!$A$5:$A$204,0)),"")) | E23: =IF(C23="","",IFERROR(INDEX(LOOKAHEAD!$E$5:$E$204,MATCH(C23,LOOKAHEAD!$A$5:$A$204,0)),"")) | F23: =IF(C23="","",IFERROR(INDEX(LOOKAHEAD!$M$5:$M$204,MATCH(C23,LOOKAHEAD!$A$5:$A$204,0)),"")) | I23: =IF(C23="","",IFERROR(INDEX(LOOKAHEAD!$G$5:$G$204,MATCH(C23,LOOKAHEAD!$A$5:$A$204,0)),"")) | V23: =IF(C23="","",SUM(J23:O23)) | W23: =IF(C23="","",SUM(P23:U23)) | X23: =IF(OR(C23="",V23=0),"",W23/V23) | Y23: =IF(OR(C23="",V23=0),"",IF(W23>=V23,"Sí","No"))
... D506: =IF(C506="","",IFERROR(INDEX(LOOKAHEAD!$B$5:$B$204,MATCH(C506,LOOKAHEAD!$A$5:$A$204,0)),"")) | E506: =IF(C506="","",IFERROR(INDEX(LOOKAHEAD!$E$5:$E$204,MATCH(C506,LOOKAHEAD!$A$5:$A$204,0)),"")) | F506: =IF(C506="","",IFERROR(INDEX(LOOKAHEAD!$M$5:$M$204,MATCH(C506,LOOKAHEAD!$A$5:$A$204,0)),"")) | I506: =IF(C506="","",IFERROR(INDEX(LOOKAHEAD!$G$5:$G$204,MATCH(C506,LOOKAHEAD!$A$5:$A$204,0)),"")) | V506: =IF(C506="","",SUM(J506:O506)) | W506: =IF(C506="","",SUM(P506:U506)) | X506: =IF(OR(C506="",V506=0),"",W506/V506) | Y506: =IF(OR(C506="",V506=0),"",IF(W506>=V506,"Sí","No"))

Sheet DASHBOARD
A1: DASHBOARD DE CONTROL LPS
A3: INDICADORES CLAVE | G3: PARETO DE CAUSAS DE INCUMPLIMIENTO | L3: RESTRICCIONES POR TIPO
A4: Meta PPC | B4: 0.85 | C4: Supuesto: meta típica LPS ≥ 85% | G4: Causa (ordenada) | H4: Frecuencia | I4: % | J4: % Acum. | L4: Tipo | M4: Pendientes | N4: Liberadas
A5: PPC global (todas las semanas) | B5: =SEMANAL!$N$2 -> 0.6 | G5: =IF(INDEX($R$44:$R$81,MATCH(LARGE($S$44:$S$81,1),$S$44:$S$81,0))<=0,"",INDEX($Q$44:$Q$81,MATCH(LARGE($S$44:$S$81,1),$S$44:$S$81,0))) -> Clima | H5: =IF(G5="","",COUNTIF(SEMANAL!$Z$7:$Z$506,G5)) -> 1 | I5: =IF(G5="","",IFERROR(H5/SUM($H$5:$H$16),0)) -> 0.5 | J5: =IF(G5="","",SUM($I$5:I5)) -> 0.5 | L5: =IF(LISTAS!$C$4="","",LISTAS!$C$4) -> Permisos / Licencias | M5: =IF(L5="","",COUNTIFS(RESTRICCIONES!$E$5:$E$304,L5,RESTRICCIONES!$L$5:$L$304,"Pendiente")) -> 0 | N5: =IF(L5="","",COUNTIFS(RESTRICCIONES!$E$5:$E$304,L5,RESTRICCIONES!$L$5:$L$304,"Liberado")) -> 0
A6: PPC semana seleccionada | B6: =SEMANAL!$J$2 -> 0.66666667 | G6: =IF(INDEX($R$44:$R$81,MATCH(LARGE($S$44:$S$81,2),$S$44:$S$81,0))<=0,"",INDEX($Q$44:$Q$81,MATCH(LARGE($S$44:$S$81,2),$S$44:$S$81,0))) -> Falta de mano de obra | H6: =IF(G6="","",COUNTIF(SEMANAL!$Z$7:$Z$506,G6)) -> 1 | I6: =IF(G6="","",IFERROR(H6/SUM($H$5:$H$16),0)) -> 0.5 | J6: =IF(G6="","",SUM($I$5:I6)) -> 1 | L6: =IF(LISTAS!$C$5="","",LISTAS!$C$5) -> Materiales | M6: =IF(L6="","",COUNTIFS(RESTRICCIONES!$E$5:$E$304,L6,RESTRICCIONES!$L$5:$L$304,"Pendiente")) -> 0 | N6: =IF(L6="","",COUNTIFS(RESTRICCIONES!$E$5:$E$304,L6,RESTRICCIONES!$L$5:$L$304,"Liberado")) -> 1
A7: Actividades LISTAS (inventario ejecutable) | B7: =LOOKAHEAD!$G$2 -> 3 | G7: =IF(INDEX($R$44:$R$81,MATCH(LARGE($S$44:$S$81,3),$S$44:$S$81,0))<=0,"",INDEX($Q$44:$Q$81,MATCH(LARGE($S$44:$S$81,3),$S$44:$S$81,0))) | H7: =IF(G7="","",COUNTIF(SEMANAL!$Z$7:$Z$506,G7)) | I7: =IF(G7="","",IFERROR(H7/SUM($H$5:$H$16),0)) | J7: =IF(G7="","",SUM($I$5:I7)) | L7: =IF(LISTAS!$C$6="","",LISTAS!$C$6) -> Mano de obra | M7: =IF(L7="","",COUNTIFS(RESTRICCIONES!$E$5:$E$304,L7,RESTRICCIONES!$L$5:$L$304,"Pendiente")) -> 0 | N7: =IF(L7="","",COUNTIFS(RESTRICCIONES!$E$5:$E$304,L7,RESTRICCIONES!$L$5:$L$304,"Liberado")) -> 1
A8: Actividades RESTRINGIDAS | B8: =LOOKAHEAD!$J$2 -> 5 | G8: =IF(INDEX($R$44:$R$81,MATCH(LARGE($S$44:$S$81,4),$S$44:$S$81,0))<=0,"",INDEX($Q$44:$Q$81,MATCH(LARGE($S$44:$S$81,4),$S$44:$S$81,0))) | H8: =IF(G8="","",COUNTIF(SEMANAL!$Z$7:$Z$506,G8)) | I8: =IF(G8="","",IFERROR(H8/SUM($H$5:$H$16),0)) | J8: =IF(G8="","",SUM($I$5:I8)) | L8: =IF(LISTAS!$C$7="","",LISTAS!$C$7) -> Subcontratos | M8: =IF(L8="","",COUNTIFS(RESTRICCIONES!$E$5:$E$304,L8,RESTRICCIONES!$L$5:$L$304,"Pendiente")) -> 2 | N8: =IF(L8="","",COUNTIFS(RESTRICCIONES!$E$5:$E$304,L8,RESTRICCIONES!$L$5:$L$304,"Liberado")) -> 0
A9: Restricciones pendientes | B9: =COUNTIF(RESTRICCIONES!$L$5:$L$304,"Pendiente") -> 6 | G9: =IF(INDEX($R$44:$R$81,MATCH(LARGE($S$44:$S$81,5),$S$44:$S$81,0))<=0,"",INDEX($Q$44:$Q$81,MATCH(LARGE($S$44:$S$81,5),$S$44:$S$81,0))) | H9: =IF(G9="","",COUNTIF(SEMANAL!$Z$7:$Z$506,G9)) | I9: =IF(G9="","",IFERROR(H9/SUM($H$5:$H$16),0)) | J9: =IF(G9="","",SUM($I$5:I9)) | L9: =IF(LISTAS!$C$8="","",LISTAS!$C$8) -> Diseño / Ingeniería (RFI) | M9: =IF(L9="","",COUNTIFS(RESTRICCIONES!$E$5:$E$304,L9,RESTRICCIONES!$L$5:$L$304,"Pendiente")) -> 2 | N9: =IF(L9="","",COUNTIFS(RESTRICCIONES!$E$5:$E$304,L9,RESTRICCIONES!$L$5:$L$304,"Liberado")) -> 0
A10: Restricciones vencidas | B10: =COUNTIF(RESTRICCIONES!$M$5:$M$304,"VENCIDA") -> 1 | G10: =IF(INDEX($R$44:$R$81,MATCH(LARGE($S$44:$S$81,6),$S$44:$S$81,0))<=0,"",INDEX($Q$44:$Q$81,MATCH(LARGE($S$44:$S$81,6),$S$44:$S$81,0))) | H10: =IF(G10="","",COUNTIF(SEMANAL!$Z$7:$Z$506,G10)) | I10: =IF(G10="","",IFERROR(H10/SUM($H$5:$H$16),0)) | J10: =IF(G10="","",SUM($I$5:I10)) | L10: =IF(LISTAS!$C$9="","",LISTAS!$C$9) -> Equipos / Maquinaria | M10: =IF(L10="","",COUNTIFS(RESTRICCIONES!$E$5:$E$304,L10,RESTRICCIONES!$L$5:$L$304,"Pendiente")) -> 1 | N10: =IF(L10="","",COUNTIFS(RESTRICCIONES!$E$5:$E$304,L10,RESTRICCIONES!$L$5:$L$304,"Liberado")) -> 0
A11: % restricciones liberadas a tiempo | B11: =IFERROR(COUNTIF(RESTRICCIONES!$M$5:$M$304,"A tiempo")/COUNTIF(RESTRICCIONES!$L$5:$L$304,"Liberado"),"") -> 1 | G11: =IF(INDEX($R$44:$R$81,MATCH(LARGE($S$44:$S$81,7),$S$44:$S$81,0))<=0,"",INDEX($Q$44:$Q$81,MATCH(LARGE($S$44:$S$81,7),$S$44:$S$81,0))) | H11: =IF(G11="","",COUNTIF(SEMANAL!$Z$7:$Z$506,G11)) | I11: =IF(G11="","",IFERROR(H11/SUM($H$5:$H$16),0)) | J11: =IF(G11="","",SUM($I$5:I11)) | L11: =IF(LISTAS!$C$10="","",LISTAS!$C$10) -> Espacio / Frente de trabajo | M11: =IF(L11="","",COUNTIFS(RESTRICCIONES!$E$5:$E$304,L11,RESTRICCIONES!$L$5:$L$304,"Pendiente")) -> 0 | N11: =IF(L11="","",COUNTIFS(RESTRICCIONES!$E$5:$E$304,L11,RESTRICCIONES!$L$5:$L$304,"Liberado")) -> 0
G12: =IF(INDEX($R$44:$R$81,MATCH(LARGE($S$44:$S$81,8),$S$44:$S$81,0))<=0,"",INDEX($Q$44:$Q$81,MATCH(LARGE($S$44:$S$81,8),$S$44:$S$81,0))) | H12: =IF(G12="","",COUNTIF(SEMANAL!$Z$7:$Z$506,G12)) | I12: =IF(G12="","",IFERROR(H12/SUM($H$5:$H$16),0)) | J12: =IF(G12="","",SUM($I$5:I12)) | L12: =IF(LISTAS!$C$11="","",LISTAS!$C$11) -> Actividad previa | M12: =IF(L12="","",COUNTIFS(RESTRICCIONES!$E$5:$E$304,L12,RESTRICCIONES!$L$5:$L$304,"Pendiente")) -> 0 | N12: =IF(L12="","",COUNTIFS(RESTRICCIONES!$E$5:$E$304,L12,RESTRICCIONES!$L$5:$L$304,"Liberado")) -> 0
A13: PPC POR SEMANA | G13: =IF(INDEX($R$44:$R$81,MATCH(LARGE($S$44:$S$81,9),$S$44:$S$81,0))<=0,"",INDEX($Q$44:$Q$81,MATCH(LARGE($S$44:$S$81,9),$S$44:$S$81,0))) | H13: =IF(G13="","",COUNTIF(SEMANAL!$Z$7:$Z$506,G13)) | I13: =IF(G13="","",IFERROR(H13/SUM($H$5:$H$16),0)) | J13: =IF(G13="","",SUM($I$5:I13)) | L13: =IF(LISTAS!$C$12="","",LISTAS!$C$12) -> Información / Aprobación cliente | M13: =IF(L13="","",COUNTIFS(RESTRICCIONES!$E$5:$E$304,L13,RESTRICCIONES!$L$5:$L$304,"Pendiente")) -> 0 | N13: =IF(L13="","",COUNTIFS(RESTRICCIONES!$E$5:$E$304,L13,RESTRICCIONES!$L$5:$L$304,"Liberado")) -> 0
