Workbook

Sheet Registro
A1: REPORTE DE DETECCIÓN DE INTERFERENCIAS – NAVISWORKS
A2: Proyecto: | C2: Edificio Ejemplo | F2: Modelo federado: | H2: Modelo_Federado.nwd | K2: Revisión: | M2: R01 | P2: Fecha reporte: | R2: Hoy: | S2: =TODAY() -> 46304
A4: N° | B4: ID Interferencia | C4: Imagen | D4: Prueba (Clash Test) | E4: Fecha detección | F4: Disciplina A | G4: Elemento A | H4: Disciplina B | I4: Elemento B | J4: Nivel | K4: Eje / Ubicación | L4: Tipo | M4: Distancia (m) | N4: Estado | O4: Prioridad | P4: Responsable | Q4: Fecha compromiso | R4: Fecha cierre | S4: Días abiertos | T4: Solución propuesta / Observaciones
A5: 1 | B5: Clash1 | C5: =HYPERLINK("cd000001.jpg","cd000001.jpg") -> cd000001.jpg | D5: Estructura vs MEP | E5: 46296 | F5: Estructura | G5: Viga V-12 30x60 | H5: Sanitaria | I5: Tubería PVC Ø110 | J5: Piso 2 | K5: C-4 | L5: Dura | M5: -0.085 | N5: Activo | O5: Alta | P5: Especialidades MEP | Q5: 46310 | S5: =IF(E5="","",IF(R5<>"",R5,$S$2)-E5) -> 8 | T5: Desviar tubería bajo viga o pasada con manguito (ejemplo)
A6: 2 | B6: Clash2 | C6: =HYPERLINK("cd000002.jpg","cd000002.jpg") -> cd000002.jpg | S6: =IF(E6="","",IF(R6<>"",R6,$S$2)-E6)
A7: 3 | B7: Clash3 | C7: =HYPERLINK("cd000003.jpg","cd000003.jpg") -> cd000003.jpg | S7: =IF(E7="","",IF(R7<>"",R7,$S$2)-E7)
A8: 4 | B8: Clash4 | C8: =HYPERLINK("cd000004.jpg","cd000004.jpg") -> cd000004.jpg | S8: =IF(E8="","",IF(R8<>"",R8,$S$2)-E8)
A9: 5 | B9: Clash5 | C9: =HYPERLINK("cd000005.jpg","cd000005.jpg") -> cd000005.jpg | S9: =IF(E9="","",IF(R9<>"",R9,$S$2)-E9)
A10: 6 | B10: Clash6 | C10: =HYPERLINK("cd000006.jpg","cd000006.jpg") -> cd000006.jpg | S10: =IF(E10="","",IF(R10<>"",R10,$S$2)-E10)
A11: 7 | B11: Clash7 | C11: =HYPERLINK("cd000007.jpg","cd000007.jpg") -> cd000007.jpg | S11: =IF(E11="","",IF(R11<>"",R11,$S$2)-E11)
A12: 8 | B12: Clash8 | C12: =HYPERLINK("cd000008.jpg","cd000008.jpg") -> cd000008.jpg | S12: =IF(E12="","",IF(R12<>"",R12,$S$2)-E12)
A13: 9 | B13: Clash9 | C13: =HYPERLINK("cd000009.jpg","cd000009.jpg") -> cd000009.jpg | S13: =IF(E13="","",IF(R13<>"",R13,$S$2)-E13)
A14: 10 | B14: Clash10 | C14: =HYPERLINK("cd000010.jpg","cd000010.jpg") -> cd000010.jpg | S14: =IF(E14="","",IF(R14<>"",R14,$S$2)-E14)
A15: 11 | B15: Clash11 | C15: =HYPERLINK("cd000011.jpg","cd000011.jpg") -> cd000011.jpg | S15: =IF(E15="","",IF(R15<>"",R15,$S$2)-E15)
A16: 12 | B16: Clash12 | C16: =HYPERLINK("cd000012.jpg","cd000012.jpg") -> cd000012.jpg | S16: =IF(E16="","",IF(R16<>"",R16,$S$2)-E16)
A17: 13 | B17: Clash13 | C17: =HYPERLINK("cd000013.jpg","cd000013.jpg") -> cd000013.jpg | S17: =IF(E17="","",IF(R17<>"",R17,$S$2)-E17)
A18: 14 | B18: Clash14 | C18: =HYPERLINK("cd000014.jpg","cd000014.jpg") -> cd000014.jpg | S18: =IF(E18="","",IF(R18<>"",R18,$S$2)-E18)
A19: 15 | B19: Clash15 | C19: =HYPERLINK("cd000015.jpg","cd000015.jpg") -> cd000015.jpg | S19: =IF(E19="","",IF(R19<>"",R19,$S$2)-E19)
A20: 16 | B20: Clash16 | C20: =HYPERLINK("cd000016.jpg","cd000016.jpg") -> cd000016.jpg | S20: =IF(E20="","",IF(R20<>"",R20,$S$2)-E20)
A21: 17 | B21: Clash17 | C21: =HYPERLINK("cd000017.jpg","cd000017.jpg") -> cd000017.jpg | S21: =IF(E21="","",IF(R21<>"",R21,$S$2)-E21)
A22: 18 | B22: Clash18 | C22: =HYPERLINK("cd000018.jpg","cd000018.jpg") -> cd000018.jpg | S22: =IF(E22="","",IF(R22<>"",R22,$S$2)-E22)
A23: 19 | B23: Clash19 | C23: =HYPERLINK("cd000019.jpg","cd000019.jpg") -> cd000019.jpg | S23: =IF(E23="","",IF(R23<>"",R23,$S$2)-E23)
A24: 20 | B24: Clash20 | C24: =HYPERLINK("cd000020.jpg","cd000020.jpg") -> cd000020.jpg | S24: =IF(E24="","",IF(R24<>"",R24,$S$2)-E24)
A25: 21 | B25: Clash21 | C25: =HYPERLINK("cd000021.jpg","cd000021.jpg") -> cd000021.jpg | S25: =IF(E25="","",IF(R25<>"",R25,$S$2)-E25)
A26: 22 | B26: Clash22 | C26: =HYPERLINK("cd000022.jpg","cd000022.jpg") -> cd000022.jpg | S26: =IF(E26="","",IF(R26<>"",R26,$S$2)-E26)
A27: 23 | B27: Clash23 | C27: =HYPERLINK("cd000023.jpg","cd000023.jpg") -> cd000023.jpg | S27: =IF(E27="","",IF(R27<>"",R27,$S$2)-E27)
A28: 24 | B28: Clash24 | C28: =HYPERLINK("cd000024.jpg","cd000024.jpg") -> cd000024.jpg | S28: =IF(E28="","",IF(R28<>"",R28,$S$2)-E28)
A29: 25 | B29: Clash25 | C29: =HYPERLINK("cd000025.jpg","cd000025.jpg") -> cd000025.jpg | S29: =IF(E29="","",IF(R29<>"",R29,$S$2)-E29)
A30: 26 | B30: Clash26 | C30: =HYPERLINK("cd000026.jpg","cd000026.jpg") -> cd000026.jpg | S30: =IF(E30="","",IF(R30<>"",R30,$S$2)-E30)
A31: 27 | B31: Clash27 | C31: =HYPERLINK("cd000027.jpg","cd000027.jpg") -> cd000027.jpg | S31: =IF(E31="","",IF(R31<>"",R31,$S$2)-E31)
A32: 28 | B32: Clash28 | C32: =HYPERLINK("cd000028.jpg","cd000028.jpg") -> cd000028.jpg | S32: =IF(E32="","",IF(R32<>"",R32,$S$2)-E32)
A33: 29 | B33: Clash29 | C33: =HYPERLINK("cd000029.jpg","cd000029.jpg") -> cd000029.jpg | S33: =IF(E33="","",IF(R33<>"",R33,$S$2)-E33)
A34: 30 | B34: Clash30 | C34: =HYPERLINK("cd000030.jpg","cd000030.jpg") -> cd000030.jpg | S34: =IF(E34="","",IF(R34<>"",R34,$S$2)-E34)
A35: 31 | B35: Clash31 | C35: =HYPERLINK("cd000031.jpg","cd000031.jpg") -> cd000031.jpg | S35: =IF(E35="","",IF(R35<>"",R35,$S$2)-E35)
A36: 32 | B36: Clash32 | C36: =HYPERLINK("cd000032.jpg","cd000032.jpg") -> cd000032.jpg | S36: =IF(E36="","",IF(R36<>"",R36,$S$2)-E36)
A37: 33 | B37: Clash33 | C37: =HYPERLINK("cd000033.jpg","cd000033.jpg") -> cd000033.jpg | S37: =IF(E37="","",IF(R37<>"",R37,$S$2)-E37)
A38: 34 | B38: Clash34 | C38: =HYPERLINK("cd000034.jpg","cd000034.jpg") -> cd000034.jpg | S38: =IF(E38="","",IF(R38<>"",R38,$S$2)-E38)
A39: 35 | B39: Clash35 | C39: =HYPERLINK("cd000035.jpg","cd000035.jpg") -> cd000035.jpg | S39: =IF(E39="","",IF(R39<>"",R39,$S$2)-E39)
A40: 36 | B40: Clash36 | C40: =HYPERLINK("cd000036.jpg","cd000036.jpg") -> cd000036.jpg | S40: =IF(E40="","",IF(R40<>"",R40,$S$2)-E40)
A41: 37 | B41: Clash37 | C41: =HYPERLINK("cd000037.jpg","cd000037.jpg") -> cd000037.jpg | S41: =IF(E41="","",IF(R41<>"",R41,$S$2)-E41)
...

Sheet Resumen
A1: RESUMEN DE INTERFERENCIAS
A3: Total registradas | B3: =COUNTA(Registro!$B$5:$B$66) -> 62 | C3: Total = filas con ID; Pendientes = con estado asignado y no resueltas.
A4: Con estado asignado | B4: =COUNTA(Registro!$N$5:$N$66) -> 1
A5: Resueltas | B5: =COUNTIF(Registro!$N$5:$N$66,"Resuelto") -> 0
A6: Pendientes | B6: =B4-B5 -> 1
A7: % avance | B7: =IF(B4=0,0,B5/B4) -> 0
A8: Vencidas | B8: =SUMPRODUCT((Registro!$Q$5:$Q$66<>"")*(Registro!$Q$5:$Q$66<Registro!$S$2)*(Registro!$N$5:$N$66<>"Resuelto")) -> 0
A11: Por estado | B11: Cantidad
A12: =Listas!$C$2 -> Nuevo | B12: =COUNTIF(Registro!$N$5:$N$66,A12) -> 0
A13: =Listas!$C$3 -> Activo | B13: =COUNTIF(Registro!$N$5:$N$66,A13) -> 1
A14: =Listas!$C$4 -> Revisado | B14: =COUNTIF(Registro!$N$5:$N$66,A14) -> 0
A15: =Listas!$C$5 -> Aprobado | B15: =COUNTIF(Registro!$N$5:$N$66,A15) -> 0
A16: =Listas!$C$6 -> Resuelto | B16: =COUNTIF(Registro!$N$5:$N$66,A16) -> 0
A18: Por prioridad | B18: Cantidad
A19: =Listas!$D$2 -> Alta | B19: =COUNTIF(Registro!$O$5:$O$66,A19) -> 1
A20: =Listas!$D$3 -> Media | B20: =COUNTIF(Registro!$O$5:$O$66,A20) -> 0
A21: =Listas!$D$4 -> Baja | B21: =COUNTIF(Registro!$O$5:$O$66,A21) -> 0
A23: Disciplina A \ B | B23: =Listas!$A$2 -> Arquitectura | C23: =Listas!$A$3 -> Estructura | D23: =Listas!$A$4 -> Sanitaria | E23: =Listas!$A$5 -> Eléctrica | F23: =Listas!$A$6 -> HVAC | G23: =Listas!$A$7 -> Contra Incendio | H23: =Listas!$A$8 -> Gas | I23: =Listas!$A$9 -> Corrientes Débiles
A24: =Listas!$A$2 -> Arquitectura | B24: =COUNTIFS(Registro!$F$5:$F$66,$A24,Registro!$H$5:$H$66,B$23) -> 0 | C24: =COUNTIFS(Registro!$F$5:$F$66,$A24,Registro!$H$5:$H$66,C$23) -> 0 | D24: =COUNTIFS(Registro!$F$5:$F$66,$A24,Registro!$H$5:$H$66,D$23) -> 0 | E24: =COUNTIFS(Registro!$F$5:$F$66,$A24,Registro!$H$5:$H$66,E$23) -> 0 | F24: =COUNTIFS(Registro!$F$5:$F$66,$A24,Registro!$H$5:$H$66,F$23) -> 0 | G24: =COUNTIFS(Registro!$F$5:$F$66,$A24,Registro!$H$5:$H$66,G$23) -> 0 | H24: =COUNTIFS(Registro!$F$5:$F$66,$A24,Registro!$H$5:$H$66,H$23) -> 0 | I24: =COUNTIFS(Registro!$F$5:$F$66,$A24,Registro!$H$5:$H$66,I$23) -> 0
A25: =Listas!$A$3 -> Estructura | B25: =COUNTIFS(Registro!$F$5:$F$66,$A25,Registro!$H$5:$H$66,B$23) -> 0 | C25: =COUNTIFS(Registro!$F$5:$F$66,$A25,Registro!$H$5:$H$66,C$23) -> 0 | D25: =COUNTIFS(Registro!$F$5:$F$66,$A25,Registro!$H$5:$H$66,D$23) -> 1 | E25: =COUNTIFS(Registro!$F$5:$F$66,$A25,Registro!$H$5:$H$66,E$23) -> 0 | F25: =COUNTIFS(Registro!$F$5:$F$66,$A25,Registro!$H$5:$H$66,F$23) -> 0 | G25: =COUNTIFS(Registro!$F$5:$F$66,$A25,Registro!$H$5:$H$66,G$23) -> 0 | H25: =COUNTIFS(Registro!$F$5:$F$66,$A25,Registro!$H$5:$H$66,H$23) -> 0 | I25: =COUNTIFS(Registro!$F$5:$F$66,$A25,Registro!$H$5:$H$66,I$23) -> 0
A26: =Listas!$A$4 -> Sanitaria | B26: =COUNTIFS(Registro!$F$5:$F$66,$A26,Registro!$H$5:$H$66,B$23) -> 0 | C26: =COUNTIFS(Registro!$F$5:$F$66,$A26,Registro!$H$5:$H$66,C$23) -> 0 | D26: =COUNTIFS(Registro!$F$5:$F$66,$A26,Registro!$H$5:$H$66,D$23) -> 0 | E26: =COUNTIFS(Registro!$F$5:$F$66,$A26,Registro!$H$5:$H$66,E$23) -> 0 | F26: =COUNTIFS(Registro!$F$5:$F$66,$A26,Registro!$H$5:$H$66,F$23) -> 0 | G26: =COUNTIFS(Registro!$F$5:$F$66,$A26,Registro!$H$5:$H$66,G$23) -> 0 | H26: =COUNTIFS(Registro!$F$5:$F$66,$A26,Registro!$H$5:$H$66,H$23) -> 0 | I26: =COUNTIFS(Registro!$F$5:$F$66,$A26,Registro!$H$5:$H$66,I$23) -> 0
A27: =Listas!$A$5 -> Eléctrica | B27: =COUNTIFS(Registro!$F$5:$F$66,$A27,Registro!$H$5:$H$66,B$23) -> 0 | C27: =COUNTIFS(Registro!$F$5:$F$66,$A27,Registro!$H$5:$H$66,C$23) -> 0 | D27: =COUNTIFS(Registro!$F$5:$F$66,$A27,Registro!$H$5:$H$66,D$23) -> 0 | E27: =COUNTIFS(Registro!$F$5:$F$66,$A27,Registro!$H$5:$H$66,E$23) -> 0 | F27: =COUNTIFS(Registro!$F$5:$F$66,$A27,Registro!$H$5:$H$66,F$23) -> 0 | G27: =COUNTIFS(Registro!$F$5:$F$66,$A27,Registro!$H$5:$H$66,G$23) -> 0 | H27: =COUNTIFS(Registro!$F$5:$F$66,$A27,Registro!$H$5:$H$66,H$23) -> 0 | I27: =COUNTIFS(Registro!$F$5:$F$66,$A27,Registro!$H$5:$H$66,I$23) -> 0
A28: =Listas!$A$6 -> HVAC | B28: =COUNTIFS(Registro!$F$5:$F$66,$A28,Registro!$H$5:$H$66,B$23) -> 0 | C28: =COUNTIFS(Registro!$F$5:$F$66,$A28,Registro!$H$5:$H$66,C$23) -> 0 | D28: =COUNTIFS(Registro!$F$5:$F$66,$A28,Registro!$H$5:$H$66,D$23) -> 0 | E28: =COUNTIFS(Registro!$F$5:$F$66,$A28,Registro!$H$5:$H$66,E$23) -> 0 | F28: =COUNTIFS(Registro!$F$5:$F$66,$A28,Registro!$H$5:$H$66,F$23) -> 0 | G28: =COUNTIFS(Registro!$F$5:$F$66,$A28,Registro!$H$5:$H$66,G$23) -> 0 | H28: =COUNTIFS(Registro!$F$5:$F$66,$A28,Registro!$H$5:$H$66,H$23) -> 0 | I28: =COUNTIFS(Registro!$F$5:$F$66,$A28,Registro!$H$5:$H$66,I$23) -> 0
A29: =Listas!$A$7 -> Contra Incendio | B29: =COUNTIFS(Registro!$F$5:$F$66,$A29,Registro!$H$5:$H$66,B$23) -> 0 | C29: =COUNTIFS(Registro!$F$5:$F$66,$A29,Registro!$H$5:$H$66,C$23) -> 0 | D29: =COUNTIFS(Registro!$F$5:$F$66,$A29,Registro!$H$5:$H$66,D$23) -> 0 | E29: =COUNTIFS(Registro!$F$5:$F$66,$A29,Registro!$H$5:$H$66,E$23) -> 0 | F29: =COUNTIFS(Registro!$F$5:$F$66,$A29,Registro!$H$5:$H$66,F$23) -> 0 | G29: =COUNTIFS(Registro!$F$5:$F$66,$A29,Registro!$H$5:$H$66,G$23) -> 0 | H29: =COUNTIFS(Registro!$F$5:$F$66,$A29,Registro!$H$5:$H$66,H$23) -> 0 | I29: =COUNTIFS(Registro!$F$5:$F$66,$A29,Registro!$H$5:$H$66,I$23) -> 0
A30: =Listas!$A$8 -> Gas | B30: =COUNTIFS(Registro!$F$5:$F$66,$A30,Registro!$H$5:$H$66,B$23) -> 0 | C30: =COUNTIFS(Registro!$F$5:$F$66,$A30,Registro!$H$5:$H$66,C$23) -> 0 | D30: =COUNTIFS(Registro!$F$5:$F$66,$A30,Registro!$H$5:$H$66,D$23) -> 0 | E30: =COUNTIFS(Registro!$F$5:$F$66,$A30,Registro!$H$5:$H$66,E$23) -> 0 | F30: =COUNTIFS(Registro!$F$5:$F$66,$A30,Registro!$H$5:$H$66,F$23) -> 0 | G30: =COUNTIFS(Registro!$F$5:$F$66,$A30,Registro!$H$5:$H$66,G$23) -> 0 | H30: =COUNTIFS(Registro!$F$5:$F$66,$A30,Registro!$H$5:$H$66,H$23) -> 0 | I30: =COUNTIFS(Registro!$F$5:$F$66,$A30,Registro!$H$5:$H$66,I$23) -> 0
A31: =Listas!$A$9 -> Corrientes Débiles | B31: =COUNTIFS(Registro!$F$5:$F$66,$A31,Registro!$H$5:$H$66,B$23) -> 0 | C31: =COUNTIFS(Registro!$F$5:$F$66,$A31,Registro!$H$5:$H$66,C$23) -> 0 | D31: =COUNTIFS(Registro!$F$5:$F$66,$A31,Registro!$H$5:$H$66,D$23) -> 0 | E31: =COUNTIFS(Registro!$F$5:$F$66,$A31,Registro!$H$5:$H$66,E$23) -> 0 | F31: =COUNTIFS(Registro!$F$5:$F$66,$A31,Registro!$H$5:$H$66,F$23) -> 0 | G31: =COUNTIFS(Registro!$F$5:$F$66,$A31,Registro!$H$5:$H$66,G$23) -> 0 | H31: =COUNTIFS(Registro!$F$5:$F$66,$A31,Registro!$H$5:$H$66,H$23) -> 0 | I31: =COUNTIFS(Registro!$F$5:$F$66,$A31,Registro!$H$5:$H$66,I$23) -> 0
A33: Por nivel | B33: Total | C33: Pendientes
A34: =Listas!$E$2 -> Subterráneo 2 | B34: =COUNTIF(Registro!$J$5:$J$66,A34) -> 0 | C34: =COUNTIFS(Registro!$J$5:$J$66,A34,Registro!$N$5:$N$66,"<>Resuelto",Registro!$N$5:$N$66,"<>") -> 0
A35: =Listas!$E$3 -> Subterráneo 1 | B35: =COUNTIF(Registro!$J$5:$J$66,A35) -> 0 | C35: =COUNTIFS(Registro!$J$5:$J$66,A35,Registro!$N$5:$N$66,"<>Resuelto",Registro!$N$5:$N$66,"<>") -> 0
A36: =Listas!$E$4 -> Piso 1 | B36: =COUNTIF(Registro!$J$5:$J$66,A36) -> 0 | C36: =COUNTIFS(Registro!$J$5:$J$66,A36,Registro!$N$5:$N$66,"<>Resuelto",Registro!$N$5:$N$66,"<>") -> 0
A37: =Listas!$E$5 -> Piso 2 | B37: =COUNTIF(Registro!$J$5:$J$66,A37) -> 1 | C37: =COUNTIFS(Registro!$J$5:$J$66,A37,Registro!$N$5:$N$66,"<>Resuelto",Registro!$N$5:$N$66,"<>") -> 1
A38: =Listas!$E$6 -> Piso 3 | B38: =COUNTIF(Registro!$J$5:$J$66,A38) -> 0 | C38: =COUNTIFS(Registro!$J$5:$J$66,A38,Registro!$N$5:$N$66,"<>Resuelto",Registro!$N$5:$N$66,"<>") -> 0
A39: =Listas!$E$7 -> Piso 4 | B39: =COUNTIF(Registro!$J$5:$J$66,A39) -> 0 | C39: =COUNTIFS(Registro!$J$5:$J$66,A39,Registro!$N$5:$N$66,"<>Resuelto",Registro!$N$5:$N$66,"<>") -> 0
A40: =Listas!$E$8 -> Cubierta | B40: =COUNTIF(Registro!$J$5:$J$66,A40) -> 0 | C40: =COUNTIFS(Registro!$J$5:$J$66,A40,Registro!$N$5:$N$66,"<>Resuelto",Registro!$N$5:$N$66,"<>") -> 0

Sheet Listas
A1: Disciplina | B1: Tipo | C1: Estado | D1: Prioridad | E1: Nivel | F1: Responsable | H1: Edite o agregue valores en las celdas azules; los desplegables del Registro toman hasta la fila 30.
A2: Arquitectura | B2: Dura | C2: Nuevo | D2: Alta | E2: Subterráneo 2 | F2: Coordinador BIM
A3: Estructura | B3: Holgura | C3: Activo | D3: Media | E3: Subterráneo 1 | F3: Arquitectura
A4: Sanitaria | B4: Duplicado | C4: Revisado | D4: Baja | E4: Piso 1 | F4: Estructura
A5: Eléctrica | C5: Aprobado | E5: Piso 2 | F5: Especialidades MEP
A6: HVAC | C6: Resuelto | E6: Piso 3
A7: Contra Incendio | E7: Piso 4
A8: Gas | E8: Cubierta
A9: Corrientes Débiles

Sheet Instrucciones
A1: INSTRUCCIONES DE USO
A2: 1. Hoja Registro: una fila por interferencia detectada en Navisworks (Clash Detective).
A3: 2. Celdas con texto AZUL son de ingreso manual; texto NEGRO son fórmulas (no editar). Celdas amarillas = datos del proyecto.
A4: 3. Columnas Disciplina, Nivel, Tipo, Estado, Prioridad y Responsable usan listas desplegables definidas en la hoja Listas.
A5: 4. Columna Imagen: hipervínculo a cdXXXXXX.jpg (imágenes exportadas por Navisworks); el .xlsx debe estar en la misma carpeta.
A6: 5. La fila 1 (Clash1) es un EJEMPLO con valores ficticios: reemplácela con datos reales.
A7: 6. Días abiertos se calcula automáticamente; Fecha compromiso se marca en rojo si está vencida y no está Resuelta.
A8: 7. Hoja Resumen: indicadores, conteos por estado/prioridad/nivel, matriz Disciplina A vs B y gráficos (todo con fórmulas).
A9: 8. Para agregar más filas, extienda la tabla desde la esquina inferior derecha; amplíe los rangos del Resumen si supera la fila 66.
A10: Flujo de estados sugerido (Navisworks): Nuevo → Activo → Revisado → Aprobado → Resuelto.
