Workbook

Sheet Diseno_Marshall
A1: LABORATORIO DE ASFALTOS
A2: DISEÑO DE MEZCLAS ASFÁLTICAS EN CALIENTE - MÉTODO MARSHALL
A3: Proyecto: | C3: Práctica académica de diseño Marshall - Maestría UNA Puno
A4: Mezcla: | C4: MAC-2 fina (huso MAC-2, MTC EG-2013)
A5: C.A.: | C5: PEN 120-150
A6: Compactación: | C6: 50 golpes por cara
A8: PARÁMETROS DE DISEÑO (celdas amarillas editables) | G8: ESPECIFICACIONES (EG-2013, Clase B) | J8: Mín. | K8: Máx.
A9: Gb - Peso específico del asfalto | D9: 1.023 | G9: Estabilidad mínima (kN) | J9: 5.44
A10: Gsb - Peso esp. bulk agregado combinado | D10: 2.43 | G10: Flujo (mm) | J10: 2 | K10: 4
A11: Gse - Peso esp. efectivo (calculado de Gmm) | D11: =(100-E15)/(100/D15-E15/D9) -> 2.4556103 | G11: Vacíos de aire Va (%) | J11: 3 | K11: 5
A12: Pba - % asfalto absorbido (% peso agregado) | D12: =100*D9*(D11-D10)/(D10*D11) -> 0.43906061 | G12: VMA mínimo (%) - TMN 12.5 mm | J12: 14
A13: Diámetro de briqueta (cm) | D13: 10.16 | G13: VFA (%) - MS-2 tránsito medio | J13: 65 | K13: 78
A14: Absorción máx. para método SSS (%) | D14: 2 | G14: Va objetivo para óptimo (%) | J14: 4
A15: Gmm (Rice) | Pb del ensayo (%) | D15: 2.28 | E15: 5.5 | G15: Estab./Flujo (kg/cm) | J15: 1700 | K15: 4000
A16: Muestra | B16: Pb (%) | C16: Ps (%) | D16: h1 (cm) | E16: h2 (cm) | F16: h3 (cm) | G16: h4 (cm) | H16: h prom. (cm) | I16: Factor correc. | J16: Peso seco aire (g) | K16: Peso SSS (g) | L16: Sumerg. 1 (g) | M16: Sumerg. 2 (g) | N16: Sumerg. prom. (g) | O16: Vol. bulk (cc) | P16: Gmb | Q16: Gmm teórica | R16: Va (%) | S16: VMA (%) | T16: VFA (%) | U16: Pbe (%) | V16: Estab. leída (kg) | W16: Estab. correg. (kg) | X16: Estab. correg. (kN) | Y16: Flujo (mm) | Z16: Est./Flujo (kg/cm) | AA16: Densidad geom. | AB16: Absorción agua (%)
A17: M1 | B17: 5.5 | C17: =100-B17 -> 94.5 | D17: 6.7 | E17: 6.4 | F17: 6.3 | G17: 6.6 | H17: =AVERAGE(D17:G17) -> 6.5 | I17: =IFERROR(INDEX(Factor_Altura!$B$2:$B$34,MATCH(H17*10,Factor_Altura!$A$2:$A$34,1))+(H17*10-INDEX(Factor_Altura!$A$2:$A$34,MATCH(H17*10,Factor_Altura!$A$2:$A$34,1)))*(INDEX(Factor_Altura!$B$2:$B$34,MATCH(H17*10,Factor_Altura!$A$2:$A$34,1)+1)-INDEX(Factor_Altura!$B$2:$B$34,MATCH(H17*10,Factor_Altura!$A$2:$A$34,1)))/(INDEX(Factor_Altura!$A$2:$A$34,MATCH(H17*10,Factor_Altura!$A$2:$A$34,1)+1)-INDEX(Factor_Altura!$A$2:$A$34,MATCH(H17*10,Factor_Altura!$A$2:$A$34,1))),NA()) -> 0.9625 | J17: 1139 | K17: 1142 | L17: =ROUND(K17-J17/(AA17*AVERAGE(P18/AA18,P19/AA19,P20/AA20,P21/AA21)),0) -> 626 | M17: =ROUND(K17-J17/(AA17*AVERAGE(P18/AA18,P19/AA19,P20/AA20,P21/AA21)),0) -> 626 | N17: =AVERAGE(L17:M17) -> 626 | O17: =K17-N17 -> 516 | P17: =J17/O17 -> 2.2073643 | Q17: =100/(B17/$D$9+C17/$D$11) -> 2.28 | R17: =100*(Q17-P17)/Q17 -> 3.1857745 | S17: =100-P17*C17/$D$10 -> 14.158053 | T17: =100*(S17-R17)/S17 -> 77.498499 | U17: =B17-$D$12*C17/100 -> 5.0850877 | V17: 523 | W17: =V17*I17 -> 503.3875 | X17: =W17*9.80665/1000 -> 4.936545 | Y17: 3.5 | Z17: =W17/(Y17/10) -> 1438.25 | AA17: =J17/(PI()*$D$13^2/4*H17) -> 2.1613897 | AB17: =100*(K17-J17)/O17 -> 0.58139535
A18: M2 | B18: 6 | C18: =100-B18 -> 94 | D18: 6.8 | E18: 6.7 | F18: 6.6 | G18: 6.6 | H18: =AVERAGE(D18:G18) -> 6.675 | I18: =IFERROR(INDEX(Factor_Altura!$B$2:$B$34,MATCH(H18*10,Factor_Altura!$A$2:$A$34,1))+(H18*10-INDEX(Factor_Altura!$A$2:$A$34,MATCH(H18*10,Factor_Altura!$A$2:$A$34,1)))*(INDEX(Factor_Altura!$B$2:$B$34,MATCH(H18*10,Factor_Altura!$A$2:$A$34,1)+1)-INDEX(Factor_Altura!$B$2:$B$34,MATCH(H18*10,Factor_Altura!$A$2:$A$34,1)))/(INDEX(Factor_Altura!$A$2:$A$34,MATCH(H18*10,Factor_Altura!$A$2:$A$34,1)+1)-INDEX(Factor_Altura!$A$2:$A$34,MATCH(H18*10,Factor_Altura!$A$2:$A$34,1))),NA()) -> 0.92875 | J18: 1124 | K18: 1132 | L18: 609 | M18: 614 | N18: =AVERAGE(L18:M18) -> 611.5 | O18: =K18-N18 -> 520.5 | P18: =J18/O18 -> 2.1594621 | Q18: =100/(B18/$D$9+C18/$D$11) -> 2.2652729 | R18: =100*(Q18-P18)/Q18 -> 4.6709961 | S18: =100-P18*C18/$D$10 -> 16.465254 | T18: =100*(S18-R18)/S18 -> 71.631193 | U18: =B18-$D$12*C18/100 -> 5.587283 | V18: 772 | W18: =V18*I18 -> 716.995 | X18: =W18*9.80665/1000 -> 7.031319 | Y18: 3.5 | Z18: =W18/(Y18/10) -> 2048.5571 | AA18: =J18/(PI()*$D$13^2/4*H18) -> 2.077006 | AB18: =100*(K18-J18)/O18 -> 1.5369837
A19: M3 | B19: 6.5 | C19: =100-B19 -> 93.5 | D19: 6.5 | E19: 6.9 | F19: 7 | G19: 6.8 | H19: =AVERAGE(D19:G19) -> 6.8 | I19: =IFERROR(INDEX(Factor_Altura!$B$2:$B$34,MATCH(H19*10,Factor_Altura!$A$2:$A$34,1))+(H19*10-INDEX(Factor_Altura!$A$2:$A$34,MATCH(H19*10,Factor_Altura!$A$2:$A$34,1)))*(INDEX(Factor_Altura!$B$2:$B$34,MATCH(H19*10,Factor_Altura!$A$2:$A$34,1)+1)-INDEX(Factor_Altura!$B$2:$B$34,MATCH(H19*10,Factor_Altura!$A$2:$A$34,1)))/(INDEX(Factor_Altura!$A$2:$A$34,MATCH(H19*10,Factor_Altura!$A$2:$A$34,1)+1)-INDEX(Factor_Altura!$A$2:$A$34,MATCH(H19*10,Factor_Altura!$A$2:$A$34,1))),NA()) -> 0.8975 | J19: 1184 | K19: 1184 | L19: 641 | M19: 643 | N19: =AVERAGE(L19:M19) -> 642 | O19: =K19-N19 -> 542 | P19: =J19/O19 -> 2.1845018 | Q19: =100/(B19/$D$9+C19/$D$11) -> 2.2507348 | R19: =100*(Q19-P19)/Q19 -> 2.942724 | S19: =100-P19*C19/$D$10 -> 15.946122 | T19: =100*(S19-R19)/S19 -> 81.545834 | U19: =B19-$D$12*C19/100 -> 6.0894783 | V19: 669.7 | W19: =V19*I19 -> 601.05575 | X19: =W19*9.80665/1000 -> 5.8943434 | Y19: 3.5 | Z19: =W19/(Y19/10) -> 1717.3021 | AA19: =J19/(PI()*$D$13^2/4*H19) -> 2.1476598 | AB19: =100*(K19-J19)/O19 -> 0
A20: M4 | B20: 8 | C20: =100-B20 -> 92 | D20: 6.5 | E20: 6.6 | F20: 6.4 | G20: 6.4 | H20: =AVERAGE(D20:G20) -> 6.475 | I20: =IFERROR(INDEX(Factor_Altura!$B$2:$B$34,MATCH(H20*10,Factor_Altura!$A$2:$A$34,1))+(H20*10-INDEX(Factor_Altura!$A$2:$A$34,MATCH(H20*10,Factor_Altura!$A$2:$A$34,1)))*(INDEX(Factor_Altura!$B$2:$B$34,MATCH(H20*10,Factor_Altura!$A$2:$A$34,1)+1)-INDEX(Factor_Altura!$B$2:$B$34,MATCH(H20*10,Factor_Altura!$A$2:$A$34,1)))/(INDEX(Factor_Altura!$A$2:$A$34,MATCH(H20*10,Factor_Altura!$A$2:$A$34,1)+1)-INDEX(Factor_Altura!$A$2:$A$34,MATCH(H20*10,Factor_Altura!$A$2:$A$34,1))),NA()) -> 0.96875 | J20: 1134 | K20: 1136 | L20: 617 | M20: 619 | N20: =AVERAGE(L20:M20) -> 618 | O20: =K20-N20 -> 518 | P20: =J20/O20 -> 2.1891892 | Q20: =100/(B20/$D$9+C20/$D$11) -> 2.2082189 | R20: =100*(Q20-P20)/Q20 -> 0.86176843 | S20: =100-P20*C20/$D$10 -> 17.117117 | T20: =100*(S20-R20)/S20 -> 94.965458 | U20: =B20-$D$12*C20/100 -> 7.5960642 | V20: 883.9 | W20: =V20*I20 -> 856.27813 | X20: =W20*9.80665/1000 -> 8.3972199 | Y20: 3.5 | Z20: =W20/(Y20/10) -> 2446.5089 | AA20: =J20/(PI()*$D$13^2/4*H20) -> 2.1602101 | AB20: =100*(K20-J20)/O20 -> 0.38610039
A21: M5 | B21: 10 | C21: =100-B21 -> 90 | D21: 6.9 | E21: 6.9 | F21: 6.8 | G21: 6.8 | H21: =AVERAGE(D21:G21) -> 6.85 | I21: =IFERROR(INDEX(Factor_Altura!$B$2:$B$34,MATCH(H21*10,Factor_Altura!$A$2:$A$34,1))+(H21*10-INDEX(Factor_Altura!$A$2:$A$34,MATCH(H21*10,Factor_Altura!$A$2:$A$34,1)))*(INDEX(Factor_Altura!$B$2:$B$34,MATCH(H21*10,Factor_Altura!$A$2:$A$34,1)+1)-INDEX(Factor_Altura!$B$2:$B$34,MATCH(H21*10,Factor_Altura!$A$2:$A$34,1)))/(INDEX(Factor_Altura!$A$2:$A$34,MATCH(H21*10,Factor_Altura!$A$2:$A$34,1)+1)-INDEX(Factor_Altura!$A$2:$A$34,MATCH(H21*10,Factor_Altura!$A$2:$A$34,1))),NA()) -> 0.88625 | J21: 1187 | K21: 1187 | L21: 640 | M21: 642 | N21: =AVERAGE(L21:M21) -> 641 | O21: =K21-N21 -> 546 | P21: =J21/O21 -> 2.1739927 | Q21: =100/(B21/$D$9+C21/$D$11) -> 2.1539683 | R21: =100*(Q21-P21)/Q21 -> -0.92964859 | S21: =100-P21*C21/$D$10 -> 19.481753 | T21: =100*(S21-R21)/S21 -> 104.77189 | U21: =B21-$D$12*C21/100 -> 9.6048454 | V21: 707.3 | W21: =V21*I21 -> 626.84462 | X21: =W21*9.80665/1000 -> 6.1472458 | Y21: 3.5 | Z21: =W21/(Y21/10) -> 1790.9846 | AA21: =J21/(PI()*$D$13^2/4*H21) -> 2.1373855 | AB21: =100*(K21-J21)/O21 -> 0
A23: VERIFICACIÓN POR BRIQUETA
A24: Muestra | B24: Pb (%) | C24: ="Va "&$J$11&"-"&$K$11&" %" -> Va 3-5 % | D24: VMA ≥ mín | E24: ="VFA "&$J$13&"-"&$K$13&" %" -> VFA 65-78 % | F24: Estab. ≥ mín | G24: ="Flujo "&$J$10&"-"&$K$10&" mm" -> Flujo 2-4 mm | H24: Estado | I24: ="Est/Flujo "&$J$15&"-"&$K$15 -> Est/Flujo 1700-4000 | J24: ="Absorción ≤ "&$D$14&" %" -> Absorción ≤ 2 %
A25: =A17 -> M1 | B25: =B17 -> 5.5 | C25: =IF(AND(R17>=$J$11,R17<=$K$11),"CUMPLE","NO") -> CUMPLE | D25: =IF(S17>=$J$12,"CUMPLE","NO") -> CUMPLE | E25: =IF(AND(T17>=$J$13,T17<=$K$13),"CUMPLE","NO") -> CUMPLE | F25: =IF(X17>=$J$9,"CUMPLE","NO") -> NO | G25: =IF(AND(Y17>=$J$10,Y17<=$K$10),"CUMPLE","NO") -> CUMPLE | H25: =IF(COUNTIF(C25:G25,"NO")+COUNTIF(I25:J25,"NO")=0,"CUMPLE","NO CUMPLE") -> NO CUMPLE | I25: =IF(AND(Z17>=$J$15,Z17<=$K$15),"CUMPLE","NO") -> NO | J25: =IF(AB17<=$D$14,"CUMPLE","NO") -> CUMPLE
A26: =A18 -> M2 | B26: =B18 -> 6 | C26: =IF(AND(R18>=$J$11,R18<=$K$11),"CUMPLE","NO") -> CUMPLE | D26: =IF(S18>=$J$12,"CUMPLE","NO") -> CUMPLE | E26: =IF(AND(T18>=$J$13,T18<=$K$13),"CUMPLE","NO") -> CUMPLE | F26: =IF(X18>=$J$9,"CUMPLE","NO") -> CUMPLE | G26: =IF(AND(Y18>=$J$10,Y18<=$K$10),"CUMPLE","NO") -> CUMPLE | H26: =IF(COUNTIF(C26:G26,"NO")+COUNTIF(I26:J26,"NO")=0,"CUMPLE","NO CUMPLE") -> CUMPLE | I26: =IF(AND(Z18>=$J$15,Z18<=$K$15),"CUMPLE","NO") -> CUMPLE | J26: =IF(AB18<=$D$14,"CUMPLE","NO") -> CUMPLE
A27: =A19 -> M3 | B27: =B19 -> 6.5 | C27: =IF(AND(R19>=$J$11,R19<=$K$11),"CUMPLE","NO") -> NO | D27: =IF(S19>=$J$12,"CUMPLE","NO") -> CUMPLE | E27: =IF(AND(T19>=$J$13,T19<=$K$13),"CUMPLE","NO") -> NO | F27: =IF(X19>=$J$9,"CUMPLE","NO") -> CUMPLE | G27: =IF(AND(Y19>=$J$10,Y19<=$K$10),"CUMPLE","NO") -> CUMPLE | H27: =IF(COUNTIF(C27:G27,"NO")+COUNTIF(I27:J27,"NO")=0,"CUMPLE","NO CUMPLE") -> NO CUMPLE | I27: =IF(AND(Z19>=$J$15,Z19<=$K$15),"CUMPLE","NO") -> CUMPLE | J27: =IF(AB19<=$D$14,"CUMPLE","NO") -> CUMPLE
A28: =A20 -> M4 | B28: =B20 -> 8 | C28: =IF(AND(R20>=$J$11,R20<=$K$11),"CUMPLE","NO") -> NO | D28: =IF(S20>=$J$12,"CUMPLE","NO") -> CUMPLE | E28: =IF(AND(T20>=$J$13,T20<=$K$13),"CUMPLE","NO") -> NO | F28: =IF(X20>=$J$9,"CUMPLE","NO") -> CUMPLE | G28: =IF(AND(Y20>=$J$10,Y20<=$K$10),"CUMPLE","NO") -> CUMPLE | H28: =IF(COUNTIF(C28:G28,"NO")+COUNTIF(I28:J28,"NO")=0,"CUMPLE","NO CUMPLE") -> NO CUMPLE | I28: =IF(AND(Z20>=$J$15,Z20<=$K$15),"CUMPLE","NO") -> CUMPLE | J28: =IF(AB20<=$D$14,"CUMPLE","NO") -> CUMPLE
A29: =A21 -> M5 | B29: =B21 -> 10 | C29: =IF(AND(R21>=$J$11,R21<=$K$11),"CUMPLE","NO") -> NO | D29: =IF(S21>=$J$12,"CUMPLE","NO") -> CUMPLE | E29: =IF(AND(T21>=$J$13,T21<=$K$13),"CUMPLE","NO") -> NO | F29: =IF(X21>=$J$9,"CUMPLE","NO") -> CUMPLE | G29: =IF(AND(Y21>=$J$10,Y21<=$K$10),"CUMPLE","NO") -> CUMPLE | H29: =IF(COUNTIF(C29:G29,"NO")+COUNTIF(I29:J29,"NO")=0,"CUMPLE","NO CUMPLE") -> NO CUMPLE | I29: =IF(AND(Z21>=$J$15,Z21<=$K$15),"CUMPLE","NO") -> CUMPLE | J29: =IF(AB21<=$D$14,"CUMPLE","NO") -> CUMPLE
A31: CONTENIDO ÓPTIMO DE ASFALTO (ajuste parabólico y = a·Pb² + b·Pb + c, criterio Instituto del Asfalto MS-2)
A32: Propiedad | B32: a | C32: b | D32: c | E32: R² | F32: Pb criterio (%) | G32: Nota
A33: Gmb | B33: =INDEX(LINEST($P$17:$P$21,$B$17:$B$21^{1,2}),1,1) -> 0.00062934461 | C33: =INDEX(LINEST($P$17:$P$21,$B$17:$B$21^{1,2}),1,2) -> -0.012388619 | D33: =INDEX(LINEST($P$17:$P$21,$B$17:$B$21^{1,2}),1,3) -> 2.2378008 | E33: =INDEX(LINEST($P$17:$P$21,$B$17:$B$21^{1,2},TRUE(),TRUE()),3,1) -> 0.076456248 | F33: =IF(AND(B33<0,-C33/(2*B33)>=MIN($B$17:$B$21),-C33/(2*B33)<=MAX($B$17:$B$21)),-C33/(2*B33),INDEX($B$17:$B$21,MATCH(MAX($P$17:$P$21),$P$17:$P$21,0))) -> 5.5 | G33: =IF(AND(B33<0,-C33/(2*B33)>=MIN($B$17:$B$21),-C33/(2*B33)<=MAX($B$17:$B$21)),"Máximo de la parábola","Sin máximo interior: se toma el mayor Gmb medido") -> Sin máximo interior: se toma el mayor Gmb medido
A34: Va (%) | B34: =INDEX(LINEST($R$17:$R$21,$B$17:$B$21^{1,2}),1,1) -> -0.023800755 | C34: =INDEX(LINEST($R$17:$R$21,$B$17:$B$21^{1,2}),1,2) -> -0.75697472 | D34: =INDEX(LINEST($R$17:$R$21,$B$17:$B$21^{1,2}),1,3) -> 8.893682 | E34: =INDEX(LINEST($R$17:$R$21,$B$17:$B$21^{1,2},TRUE(),TRUE()),3,1) -> 0.88101326 | F34: =IFERROR(IF((C34^2-4*B34*(D34-$J$14))<0,"N/A",IF(AND(((-C34+SQRT((C34^2-4*B34*(D34-$J$14))))/(2*B34))>=MIN($B$17:$B$21),((-C34+SQRT((C34^2-4*B34*(D34-$J$14))))/(2*B34))<=MAX($B$17:$B$21)),((-C34+SQRT((C34^2-4*B34*(D34-$J$14))))/(2*B34)),IF(AND(((-C34-SQRT((C34^2-4*B34*(D34-$J$14))))/(2*B34))>=MIN($B$17:$B$21),((-C34-SQRT((C34^2-4*B34*(D34-$J$14))))/(2*B34))<=MAX($B$17:$B$21)),((-C34-SQRT((C34^2-4*B34*(D34-$J$14))))/(2*B34)),"N/A"))),"N/A") -> 5.510155 | G34: =IF(ISNUMBER(F34),"Pb para Va objetivo","Va objetivo NO se alcanza en el rango ensayado (Va mín. medido = "&TEXT(MIN($R$17:$R$21),"0.0")&" %)") -> Pb para Va objetivo
A35: VMA (%) | B35: =INDEX(LINEST($S$17:$S$21,$B$17:$B$21^{1,2}),1,1) -> -0.02721812 | C35: =INDEX(LINEST($S$17:$S$21,$B$17:$B$21^{1,2}),1,2) -> 1.4201106 | D35: =INDEX(LINEST($S$17:$S$21,$B$17:$B$21^{1,2}),1,3) -> 7.8922509 | E35: =INDEX(LINEST($S$17:$S$21,$B$17:$B$21^{1,2},TRUE(),TRUE()),3,1) -> 0.88286714 | F35: =IFERROR(IF(AND(B35>0,AND(-C35/(2*B35)>=MIN($B$17:$B$21),-C35/(2*B35)<=MAX($B$17:$B$21))),-C35/(2*B35),"N/A"),"N/A") -> N/A | G35: =IF(ISNUMBER(F35),"Mínimo de VMA (informativo: el óptimo debe quedar en o a la izquierda)","Sin mínimo interior de VMA") -> Sin mínimo interior de VMA
A36: VFA (%) | B36: =INDEX(LINEST($T$17:$T$21,$B$17:$B$21^{1,2}),1,1) -> -0.29643818 | C36: =INDEX(LINEST($T$17:$T$21,$B$17:$B$21^{1,2}),1,2) -> 11.722512 | D36: =INDEX(LINEST($T$17:$T$21,$B$17:$B$21^{1,2}),1,3) -> 17.83637 | E36: =INDEX(LINEST($T$17:$T$21,$B$17:$B$21^{1,2},TRUE(),TRUE()),3,1) -> 0.92135535 | F36: =IFERROR(IF(AND((-C36+SQRT(C36^2-4*B36*(D36-($J$13+$K$13)/2)))/(2*B36)>=MIN($B$17:$B$21),(-C36+SQRT(C36^2-4*B36*(D36-($J$13+$K$13)/2)))/(2*B36)<=MAX($B$17:$B$21)),(-C36+SQRT(C36^2-4*B36*(D36-($J$13+$K$13)/2)))/(2*B36),IF(AND((-C36-SQRT(C36^2-4*B36*(D36-($J$13+$K$13)/2)))/(2*B36)>=MIN($B$17:$B$21),(-C36-SQRT(C36^2-4*B36*(D36-($J$13+$K$13)/2)))/(2*B36)<=MAX($B$17:$B$21)),(-C36-SQRT(C36^2-4*B36*(D36-($J$13+$K$13)/2)))/(2*B36),"N/A")),"N/A") -> N/A | G36: =IF(ISNUMBER(F36),"Pb para VFA medio del rango (informativo)","Fuera del rango ensayado") -> Fuera del rango ensayado
A37: Estabilidad (kN) | B37: =INDEX(LINEST($X$17:$X$21,$B$17:$B$21^{1,2}),1,1) -> -0.46041796 | C37: =INDEX(LINEST($X$17:$X$21,$B$17:$B$21^{1,2}),1,2) -> 7.3895363 | D37: =INDEX(LINEST($X$17:$X$21,$B$17:$B$21^{1,2}),1,3) -> -21.630548 | E37: =INDEX(LINEST($X$17:$X$21,$B$17:$B$21^{1,2},TRUE(),TRUE()),3,1) -> 0.6930734 | F37: =IF(AND(B37<0,-C37/(2*B37)>=MIN($B$17:$B$21),-C37/(2*B37)<=MAX($B$17:$B$21)),-C37/(2*B37),INDEX($B$17:$B$21,MATCH(MAX($X$17:$X$21),$X$17:$X$21,0))) -> 8.0248132 | G37: =IF(AND(B37<0,-C37/(2*B37)>=MIN($B$17:$B$21),-C37/(2*B37)<=MAX($B$17:$B$21)),"Máximo de la parábola","Sin máximo interior: se toma la mayor estabilidad medida") -> Máximo de la parábola
A38: Flujo (mm) | B38: =INDEX(LINEST($Y$17:$Y$21,$B$17:$B$21^{1,2}),1,1) -> 0 | C38: =INDEX(LINEST($Y$17:$Y$21,$B$17:$B$21^{1,2}),1,2) -> 0 | D38: =INDEX(LINEST($Y$17:$Y$21,$B$17:$B$21^{1,2}),1,3) -> 3.5 | E38: =IFERROR(INDEX(LINEST($Y$17:$Y$21,$B$17:$B$21^{1,2},TRUE(),TRUE()),3,1),"-") -> 1 | F38: =IFERROR(IF(AND((-C38+SQRT(C38^2-4*B38*(D38-$K$10)))/(2*B38)>=MIN($B$17:$B$21),(-C38+SQRT(C38^2-4*B38*(D38-$K$10)))/(2*B38)<=MAX($B$17:$B$21)),(-C38+SQRT(C38^2-4*B38*(D38-$K$10)))/(2*B38),IF(AND((-C38-SQRT(C38^2-4*B38*(D38-$K$10)))/(2*B38)>=MIN($B$17:$B$21),(-C38-SQRT(C38^2-4*B38*(D38-$K$10)))/(2*B38)<=MAX($B$17:$B$21)),(-C38-SQRT(C38^2-4*B38*(D38-$K$10)))/(2*B38),"N/A")),"N/A") -> N/A | G38: =IF(ISNUMBER(F38),"Pb para flujo máximo (límite superior de Pb)","Fuera del rango ensayado") -> Fuera del rango ensayado
A40: Pb óptimo calculado (promedio de criterios disponibles) | F40: =AVERAGE(F33,F37,F34) -> 6.3449894 | G40: =IF(ISNUMBER(F34),"Promedio de 3 criterios","PROVISIONAL: solo promedio de máx. Gmb y máx. estabilidad") -> Promedio de 3 criterios
A41: Pb de diseño adoptado (editable; por defecto = calculado) | F41: 6 | G41: Adoptado por criterio: cumple VFA ≤ 78 %
A43: VERIFICACIÓN EN EL Pb DE DISEÑO (valores leídos de las curvas ajustadas)
A44: Propiedad | B44: Valor | C44: Especificación | D44: Resultado
A45: Gmb | B45: =B33*$F$41^2+C33*$F$41+D33 -> 2.1861255 | C45: - | D45: ="-" -> -
...

Sheet Graficas_Marshall
A2: DISEÑO DE MEZCLA ASFÁLTICA
A3: MÉTODO MARSHALL
A4: =Diseno_Marshall!C4&" - C.A. "&Diseno_Marshall!C5&" - "&Diseno_Marshall!C6 -> MAC-2 fina (huso MAC-2, MTC EG-2013) - C.A. PEN 120-150 - 50 golpes por cara
G47: ="RESUMEN DE DISEÑO - CONTENIDO ÓPTIMO DE ASFALTO = "&TEXT(Diseno_Marshall!F41,"0.0")&" %" -> RESUMEN DE DISEÑO - CONTENIDO ÓPTIMO DE ASFALTO = 6.0 %
G48: PROPIEDAD | J48: VALOR | L48: ESPECIFICACIÓN | N48: RESULTADO
G49: =Diseno_Marshall!A45 -> Gmb | J49: =Diseno_Marshall!B45 -> 2.1861255 | L49: =Diseno_Marshall!C45 -> - | N49: =Diseno_Marshall!D45 -> -
G50: =Diseno_Marshall!A46 -> Va (%) | J50: =Diseno_Marshall!B46 -> 3.4950065 | L50: =Diseno_Marshall!C46 -> 3 - 5 % | N50: =Diseno_Marshall!D46 -> CUMPLE
G51: =Diseno_Marshall!A47 -> VMA (%) | J51: =Diseno_Marshall!B47 -> 15.433062 | L51: =Diseno_Marshall!C47 -> ≥ 14 % | N51: =Diseno_Marshall!D47 -> CUMPLE
G52: =Diseno_Marshall!A48 -> VFA (%) | J52: =Diseno_Marshall!B48 -> 77.499668 | L52: =Diseno_Marshall!C48 -> 65 - 78 % | N52: =Diseno_Marshall!D48 -> CUMPLE
G53: =Diseno_Marshall!A49 -> Estabilidad (kN) | J53: =Diseno_Marshall!B49 -> 6.1316234 | L53: =Diseno_Marshall!C49 -> ≥ 5.44 kN | N53: =Diseno_Marshall!D49 -> CUMPLE
G54: =Diseno_Marshall!A50 -> Flujo (mm) | J54: =Diseno_Marshall!B50 -> 3.5 | L54: =Diseno_Marshall!C50 -> 2 - 4 mm | N54: =Diseno_Marshall!D50 -> CUMPLE
G55: =Diseno_Marshall!A51 -> Estab./Flujo (kg/cm) | J55: =Diseno_Marshall!B51 -> 1786.4331 | L55: =Diseno_Marshall!C51 -> 1700 - 4000 kg/cm | N55: =Diseno_Marshall!D51 -> CUMPLE
G56: DISEÑO GLOBAL | N56: =Diseno_Marshall!D52 -> CUMPLE
A58: La línea naranja indica la lectura en el Pb de diseño adoptado. Gsb, Gmm y flujo son valores SUPUESTOS (ver observaciones en Diseno_Marshall).

Sheet Factor_Altura
A1: Altura (mm) | B1: Factor corrección | D1: Fuente: MTC E 504 / ASTM D6927 (interpolación lineal).
A2: 25.4 | B2: 5.56
A3: 27 | B3: 5
A4: 28.6 | B4: 4.55
A5: 30.2 | B5: 4.17
A6: 31.8 | B6: 3.85
A7: 33.3 | B7: 3.57
A8: 34.9 | B8: 3.33
A9: 36.5 | B9: 3.03
A10: 38.1 | B10: 2.78
A11: 39.7 | B11: 2.5
A12: 41.3 | B12: 2.27
A13: 42.9 | B13: 2.08
... A34: 76.2 | B34: 0.76

Sheet Datos_Graficas
A1: Datos auxiliares de las gráficas (fórmulas enlazadas a Diseno_Marshall; los límites de eje son fijos y editables en la fila 40)
A3: Pb (%) | B3: Gmb ajustado | E3: Estabilidad ajustado | H3: Flujo ajustado | K3: Va ajustado | N3: VFA ajustado | Q3: VMA ajustado
A4: =MIN(Diseno_Marshall!$B$17:$B$21)+0*(MAX(Diseno_Marshall!$B$17:$B$21)-MIN(Diseno_Marshall!$B$17:$B$21))/30 -> 5.5 | B4: =Diseno_Marshall!$B$33*A4^2+Diseno_Marshall!$C$33*A4+Diseno_Marshall!$D$33 -> 2.1887011 | E4: =Diseno_Marshall!$B$37*A4^2+Diseno_Marshall!$C$37*A4+Diseno_Marshall!$D$37 -> 5.0842585 | H4: =Diseno_Marshall!$B$38*A4^2+Diseno_Marshall!$C$38*A4+Diseno_Marshall!$D$38 -> 3.5 | K4: =Diseno_Marshall!$B$34*A4^2+Diseno_Marshall!$C$34*A4+Diseno_Marshall!$D$34 -> 4.0103482 | N4: =Diseno_Marshall!$B$36*A4^2+Diseno_Marshall!$C$36*A4+Diseno_Marshall!$D$36 -> 73.342931 | Q4: =Diseno_Marshall!$B$35*A4^2+Diseno_Marshall!$C$35*A4+Diseno_Marshall!$D$35 -> 14.879511
A5: =MIN(Diseno_Marshall!$B$17:$B$21)+1*(MAX(Diseno_Marshall!$B$17:$B$21)-MIN(Diseno_Marshall!$B$17:$B$21))/30 -> 5.65 | B5: =Diseno_Marshall!$B$33*A5^2+Diseno_Marshall!$C$33*A5+Diseno_Marshall!$D$33 -> 2.1878954 | E5: =Diseno_Marshall!$B$37*A5^2+Diseno_Marshall!$C$37*A5+Diseno_Marshall!$D$37 -> 5.4226399 | H5: =Diseno_Marshall!$B$38*A5^2+Diseno_Marshall!$C$38*A5+Diseno_Marshall!$D$38 -> 3.5 | K5: =Diseno_Marshall!$B$34*A5^2+Diseno_Marshall!$C$34*A5+Diseno_Marshall!$D$34 -> 3.8569952 | N5: =Diseno_Marshall!$B$36*A5^2+Diseno_Marshall!$C$36*A5+Diseno_Marshall!$D$36 -> 74.605515 | Q5: =Diseno_Marshall!$B$35*A5^2+Diseno_Marshall!$C$35*A5+Diseno_Marshall!$D$35 -> 15.047006
A6: =MIN(Diseno_Marshall!$B$17:$B$21)+2*(MAX(Diseno_Marshall!$B$17:$B$21)-MIN(Diseno_Marshall!$B$17:$B$21))/30 -> 5.8 | B6: =Diseno_Marshall!$B$33*A6^2+Diseno_Marshall!$C$33*A6+Diseno_Marshall!$D$33 -> 2.187118 | E6: =Diseno_Marshall!$B$37*A6^2+Diseno_Marshall!$C$37*A6+Diseno_Marshall!$D$37 -> 5.7403025 | H6: =Diseno_Marshall!$B$38*A6^2+Diseno_Marshall!$C$38*A6+Diseno_Marshall!$D$38 -> 3.5 | K6: =Diseno_Marshall!$B$34*A6^2+Diseno_Marshall!$C$34*A6+Diseno_Marshall!$D$34 -> 3.7025712 | N6: =Diseno_Marshall!$B$36*A6^2+Diseno_Marshall!$C$36*A6+Diseno_Marshall!$D$36 -> 75.854759 | Q6: =Diseno_Marshall!$B$35*A6^2+Diseno_Marshall!$C$35*A6+Diseno_Marshall!$D$35 -> 15.213275
A7: =MIN(Diseno_Marshall!$B$17:$B$21)+3*(MAX(Diseno_Marshall!$B$17:$B$21)-MIN(Diseno_Marshall!$B$17:$B$21))/30 -> 5.95 | B7: =Diseno_Marshall!$B$33*A7^2+Diseno_Marshall!$C$33*A7+Diseno_Marshall!$D$33 -> 2.1863689 | E7: =Diseno_Marshall!$B$37*A7^2+Diseno_Marshall!$C$37*A7+Diseno_Marshall!$D$37 -> 6.0372463 | H7: =Diseno_Marshall!$B$38*A7^2+Diseno_Marshall!$C$38*A7+Diseno_Marshall!$D$38 -> 3.5 | K7: =Diseno_Marshall!$B$34*A7^2+Diseno_Marshall!$C$34*A7+Diseno_Marshall!$D$34 -> 3.5470762 | N7: =Diseno_Marshall!$B$36*A7^2+Diseno_Marshall!$C$36*A7+Diseno_Marshall!$D$36 -> 77.090664 | Q7: =Diseno_Marshall!$B$35*A7^2+Diseno_Marshall!$C$35*A7+Diseno_Marshall!$D$35 -> 15.37832
A8: =MIN(Diseno_Marshall!$B$17:$B$21)+4*(MAX(Diseno_Marshall!$B$17:$B$21)-MIN(Diseno_Marshall!$B$17:$B$21))/30 -> 6.1 | B8: =Diseno_Marshall!$B$33*A8^2+Diseno_Marshall!$C$33*A8+Diseno_Marshall!$D$33 -> 2.1856481 | E8: =Diseno_Marshall!$B$37*A8^2+Diseno_Marshall!$C$37*A8+Diseno_Marshall!$D$37 -> 6.3134713 | H8: =Diseno_Marshall!$B$38*A8^2+Diseno_Marshall!$C$38*A8+Diseno_Marshall!$D$38 -> 3.5 | K8: =Diseno_Marshall!$B$34*A8^2+Diseno_Marshall!$C$34*A8+Diseno_Marshall!$D$34 -> 3.3905101 | N8: =Diseno_Marshall!$B$36*A8^2+Diseno_Marshall!$C$36*A8+Diseno_Marshall!$D$36 -> 78.313229 | Q8: =Diseno_Marshall!$B$35*A8^2+Diseno_Marshall!$C$35*A8+Diseno_Marshall!$D$35 -> 15.54214
A9: =MIN(Diseno_Marshall!$B$17:$B$21)+5*(MAX(Diseno_Marshall!$B$17:$B$21)-MIN(Diseno_Marshall!$B$17:$B$21))/30 -> 6.25 | B9: =Diseno_Marshall!$B$33*A9^2+Diseno_Marshall!$C$33*A9+Diseno_Marshall!$D$33 -> 2.1849557 | E9: =Diseno_Marshall!$B$37*A9^2+Diseno_Marshall!$C$37*A9+Diseno_Marshall!$D$37 -> 6.5689774 | H9: =Diseno_Marshall!$B$38*A9^2+Diseno_Marshall!$C$38*A9+Diseno_Marshall!$D$38 -> 3.5 | K9: =Diseno_Marshall!$B$34*A9^2+Diseno_Marshall!$C$34*A9+Diseno_Marshall!$D$34 -> 3.232873 | N9: =Diseno_Marshall!$B$36*A9^2+Diseno_Marshall!$C$36*A9+Diseno_Marshall!$D$36 -> 79.522454 | Q9: =Diseno_Marshall!$B$35*A9^2+Diseno_Marshall!$C$35*A9+Diseno_Marshall!$D$35 -> 15.704735
A10: =MIN(Diseno_Marshall!$B$17:$B$21)+6*(MAX(Diseno_Marshall!$B$17:$B$21)-MIN(Diseno_Marshall!$B$17:$B$21))/30 -> 6.4 | B10: =Diseno_Marshall!$B$33*A10^2+Diseno_Marshall!$C$33*A10+Diseno_Marshall!$D$33 -> 2.1842916 | E10: =Diseno_Marshall!$B$37*A10^2+Diseno_Marshall!$C$37*A10+Diseno_Marshall!$D$37 -> 6.8037648 | H10: =Diseno_Marshall!$B$38*A10^2+Diseno_Marshall!$C$38*A10+Diseno_Marshall!$D$38 -> 3.5 | K10: =Diseno_Marshall!$B$34*A10^2+Diseno_Marshall!$C$34*A10+Diseno_Marshall!$D$34 -> 3.0741649 | N10: =Diseno_Marshall!$B$36*A10^2+Diseno_Marshall!$C$36*A10+Diseno_Marshall!$D$36 -> 80.718339 | Q10: =Diseno_Marshall!$B$35*A10^2+Diseno_Marshall!$C$35*A10+Diseno_Marshall!$D$35 -> 15.866105
A11: =MIN(Diseno_Marshall!$B$17:$B$21)+7*(MAX(Diseno_Marshall!$B$17:$B$21)-MIN(Diseno_Marshall!$B$17:$B$21))/30 -> 6.55 | B11: =Diseno_Marshall!$B$33*A11^2+Diseno_Marshall!$C$33*A11+Diseno_Marshall!$D$33 -> 2.1836558 | E11: =Diseno_Marshall!$B$37*A11^2+Diseno_Marshall!$C$37*A11+Diseno_Marshall!$D$37 -> 7.0178333 | H11: =Diseno_Marshall!$B$38*A11^2+Diseno_Marshall!$C$38*A11+Diseno_Marshall!$D$38 -> 3.5 | K11: =Diseno_Marshall!$B$34*A11^2+Diseno_Marshall!$C$34*A11+Diseno_Marshall!$D$34 -> 2.9143857 | N11: =Diseno_Marshall!$B$36*A11^2+Diseno_Marshall!$C$36*A11+Diseno_Marshall!$D$36 -> 81.900885 | Q11: =Diseno_Marshall!$B$35*A11^2+Diseno_Marshall!$C$35*A11+Diseno_Marshall!$D$35 -> 16.02625
A12: =MIN(Diseno_Marshall!$B$17:$B$21)+8*(MAX(Diseno_Marshall!$B$17:$B$21)-MIN(Diseno_Marshall!$B$17:$B$21))/30 -> 6.7 | B12: =Diseno_Marshall!$B$33*A12^2+Diseno_Marshall!$C$33*A12+Diseno_Marshall!$D$33 -> 2.1830483 | E12: =Diseno_Marshall!$B$37*A12^2+Diseno_Marshall!$C$37*A12+Diseno_Marshall!$D$37 -> 7.2111831 | H12: =Diseno_Marshall!$B$38*A12^2+Diseno_Marshall!$C$38*A12+Diseno_Marshall!$D$38 -> 3.5 | K12: =Diseno_Marshall!$B$34*A12^2+Diseno_Marshall!$C$34*A12+Diseno_Marshall!$D$34 -> 2.7535355 | N12: =Diseno_Marshall!$B$36*A12^2+Diseno_Marshall!$C$36*A12+Diseno_Marshall!$D$36 -> 83.070091 | Q12: =Diseno_Marshall!$B$35*A12^2+Diseno_Marshall!$C$35*A12+Diseno_Marshall!$D$35 -> 16.185171
A13: =MIN(Diseno_Marshall!$B$17:$B$21)+9*(MAX(Diseno_Marshall!$B$17:$B$21)-MIN(Diseno_Marshall!$B$17:$B$21))/30 -> 6.85 | B13: =Diseno_Marshall!$B$33*A13^2+Diseno_Marshall!$C$33*A13+Diseno_Marshall!$D$33 -> 2.1824692 | E13: =Diseno_Marshall!$B$37*A13^2+Diseno_Marshall!$C$37*A13+Diseno_Marshall!$D$37 -> 7.383814 | H13: =Diseno_Marshall!$B$38*A13^2+Diseno_Marshall!$C$38*A13+Diseno_Marshall!$D$38 -> 3.5 | K13: =Diseno_Marshall!$B$34*A13^2+Diseno_Marshall!$C$34*A13+Diseno_Marshall!$D$34 -> 2.5916142 | N13: =Diseno_Marshall!$B$36*A13^2+Diseno_Marshall!$C$36*A13+Diseno_Marshall!$D$36 -> 84.225957 | Q13: =Diseno_Marshall!$B$35*A13^2+Diseno_Marshall!$C$35*A13+Diseno_Marshall!$D$35 -> 16.342866
A14: =MIN(Diseno_Marshall!$B$17:$B$21)+10*(MAX(Diseno_Marshall!$B$17:$B$21)-MIN(Diseno_Marshall!$B$17:$B$21))/30 -> 7 | B14: =Diseno_Marshall!$B$33*A14^2+Diseno_Marshall!$C$33*A14+Diseno_Marshall!$D$33 -> 2.1819183 | E14: =Diseno_Marshall!$B$37*A14^2+Diseno_Marshall!$C$37*A14+Diseno_Marshall!$D$37 -> 7.5357262 | H14: =Diseno_Marshall!$B$38*A14^2+Diseno_Marshall!$C$38*A14+Diseno_Marshall!$D$38 -> 3.5 | K14: =Diseno_Marshall!$B$34*A14^2+Diseno_Marshall!$C$34*A14+Diseno_Marshall!$D$34 -> 2.428622 | N14: =Diseno_Marshall!$B$36*A14^2+Diseno_Marshall!$C$36*A14+Diseno_Marshall!$D$36 -> 85.368483 | Q14: =Diseno_Marshall!$B$35*A14^2+Diseno_Marshall!$C$35*A14+Diseno_Marshall!$D$35 -> 16.499337
A15: =MIN(Diseno_Marshall!$B$17:$B$21)+11*(MAX(Diseno_Marshall!$B$17:$B$21)-MIN(Diseno_Marshall!$B$17:$B$21))/30 -> 7.15 | B15: =Diseno_Marshall!$B$33*A15^2+Diseno_Marshall!$C$33*A15+Diseno_Marshall!$D$33 -> 2.1813958 | E15: =Diseno_Marshall!$B$37*A15^2+Diseno_Marshall!$C$37*A15+Diseno_Marshall!$D$37 -> 7.6669195 | H15: =Diseno_Marshall!$B$38*A15^2+Diseno_Marshall!$C$38*A15+Diseno_Marshall!$D$38 -> 3.5 | K15: =Diseno_Marshall!$B$34*A15^2+Diseno_Marshall!$C$34*A15+Diseno_Marshall!$D$34 -> 2.2645587 | N15: =Diseno_Marshall!$B$36*A15^2+Diseno_Marshall!$C$36*A15+Diseno_Marshall!$D$36 -> 86.49767 | Q15: =Diseno_Marshall!$B$35*A15^2+Diseno_Marshall!$C$35*A15+Diseno_Marshall!$D$35 -> 16.654584
A16: =MIN(Diseno_Marshall!$B$17:$B$21)+12*(MAX(Diseno_Marshall!$B$17:$B$21)-MIN(Diseno_Marshall!$B$17:$B$21))/30 -> 7.3 | B16: =Diseno_Marshall!$B$33*A16^2+Diseno_Marshall!$C$33*A16+Diseno_Marshall!$D$33 -> 2.1809017 | E16: =Diseno_Marshall!$B$37*A16^2+Diseno_Marshall!$C$37*A16+Diseno_Marshall!$D$37 -> 7.777394 | H16: =Diseno_Marshall!$B$38*A16^2+Diseno_Marshall!$C$38*A16+Diseno_Marshall!$D$38 -> 3.5 | K16: =Diseno_Marshall!$B$34*A16^2+Diseno_Marshall!$C$34*A16+Diseno_Marshall!$D$34 -> 2.0994243 | N16: =Diseno_Marshall!$B$36*A16^2+Diseno_Marshall!$C$36*A16+Diseno_Marshall!$D$36 -> 87.613517 | Q16: =Diseno_Marshall!$B$35*A16^2+Diseno_Marshall!$C$35*A16+Diseno_Marshall!$D$35 -> 16.808605
A17: =MIN(Diseno_Marshall!$B$17:$B$21)+13*(MAX(Diseno_Marshall!$B$17:$B$21)-MIN(Diseno_Marshall!$B$17:$B$21))/30 -> 7.45 | B17: =Diseno_Marshall!$B$33*A17^2+Diseno_Marshall!$C$33*A17+Diseno_Marshall!$D$33 -> 2.1804358 | E17: =Diseno_Marshall!$B$37*A17^2+Diseno_Marshall!$C$37*A17+Diseno_Marshall!$D$37 -> 7.8671497 | H17: =Diseno_Marshall!$B$38*A17^2+Diseno_Marshall!$C$38*A17+Diseno_Marshall!$D$38 -> 3.5 | K17: =Diseno_Marshall!$B$34*A17^2+Diseno_Marshall!$C$34*A17+Diseno_Marshall!$D$34 -> 1.9332189 | N17: =Diseno_Marshall!$B$36*A17^2+Diseno_Marshall!$C$36*A17+Diseno_Marshall!$D$36 -> 88.716024 | Q17: =Diseno_Marshall!$B$35*A17^2+Diseno_Marshall!$C$35*A17+Diseno_Marshall!$D$35 -> 16.961401
A18: =MIN(Diseno_Marshall!$B$17:$B$21)+14*(MAX(Diseno_Marshall!$B$17:$B$21)-MIN(Diseno_Marshall!$B$17:$B$21))/30 -> 7.6 | B18: =Diseno_Marshall!$B$33*A18^2+Diseno_Marshall!$C$33*A18+Diseno_Marshall!$D$33 -> 2.1799982 | E18: =Diseno_Marshall!$B$37*A18^2+Diseno_Marshall!$C$37*A18+Diseno_Marshall!$D$37 -> 7.9361866 | H18: =Diseno_Marshall!$B$38*A18^2+Diseno_Marshall!$C$38*A18+Diseno_Marshall!$D$38 -> 3.5 | K18: =Diseno_Marshall!$B$34*A18^2+Diseno_Marshall!$C$34*A18+Diseno_Marshall!$D$34 -> 1.7659425 | N18: =Diseno_Marshall!$B$36*A18^2+Diseno_Marshall!$C$36*A18+Diseno_Marshall!$D$36 -> 89.805192 | Q18: =Diseno_Marshall!$B$35*A18^2+Diseno_Marshall!$C$35*A18+Diseno_Marshall!$D$35 -> 17.112973
A19: =MIN(Diseno_Marshall!$B$17:$B$21)+15*(MAX(Diseno_Marshall!$B$17:$B$21)-MIN(Diseno_Marshall!$B$17:$B$21))/30 -> 7.75 | B19: =Diseno_Marshall!$B$33*A19^2+Diseno_Marshall!$C$33*A19+Diseno_Marshall!$D$33 -> 2.179589 | E19: =Diseno_Marshall!$B$37*A19^2+Diseno_Marshall!$C$37*A19+Diseno_Marshall!$D$37 -> 7.9845047 | H19: =Diseno_Marshall!$B$38*A19^2+Diseno_Marshall!$C$38*A19+Diseno_Marshall!$D$38 -> 3.5 | K19: =Diseno_Marshall!$B$34*A19^2+Diseno_Marshall!$C$34*A19+Diseno_Marshall!$D$34 -> 1.5975951 | N19: =Diseno_Marshall!$B$36*A19^2+Diseno_Marshall!$C$36*A19+Diseno_Marshall!$D$36 -> 90.88102 | Q19: =Diseno_Marshall!$B$35*A19^2+Diseno_Marshall!$C$35*A19+Diseno_Marshall!$D$35 -> 17.26332
A20: =MIN(Diseno_Marshall!$B$17:$B$21)+16*(MAX(Diseno_Marshall!$B$17:$B$21)-MIN(Diseno_Marshall!$B$17:$B$21))/30 -> 7.9 | B20: =Diseno_Marshall!$B$33*A20^2+Diseno_Marshall!$C$33*A20+Diseno_Marshall!$D$33 -> 2.1792081 | E20: =Diseno_Marshall!$B$37*A20^2+Diseno_Marshall!$C$37*A20+Diseno_Marshall!$D$37 -> 8.0121039 | H20: =Diseno_Marshall!$B$38*A20^2+Diseno_Marshall!$C$38*A20+Diseno_Marshall!$D$38 -> 3.5 | K20: =Diseno_Marshall!$B$34*A20^2+Diseno_Marshall!$C$34*A20+Diseno_Marshall!$D$34 -> 1.4281766 | N20: =Diseno_Marshall!$B$36*A20^2+Diseno_Marshall!$C$36*A20+Diseno_Marshall!$D$36 -> 91.943508 | Q20: =Diseno_Marshall!$B$35*A20^2+Diseno_Marshall!$C$35*A20+Diseno_Marshall!$D$35 -> 17.412442
A21: =MIN(Diseno_Marshall!$B$17:$B$21)+17*(MAX(Diseno_Marshall!$B$17:$B$21)-MIN(Diseno_Marshall!$B$17:$B$21))/30 -> 8.05 | B21: =Diseno_Marshall!$B$33*A21^2+Diseno_Marshall!$C$33*A21+Diseno_Marshall!$D$33 -> 2.1788555 | E21: =Diseno_Marshall!$B$37*A21^2+Diseno_Marshall!$C$37*A21+Diseno_Marshall!$D$37 -> 8.0189844 | H21: =Diseno_Marshall!$B$38*A21^2+Diseno_Marshall!$C$38*A21+Diseno_Marshall!$D$38 -> 3.5 | K21: =Diseno_Marshall!$B$34*A21^2+Diseno_Marshall!$C$34*A21+Diseno_Marshall!$D$34 -> 1.2576871 | N21: =Diseno_Marshall!$B$36*A21^2+Diseno_Marshall!$C$36*A21+Diseno_Marshall!$D$36 -> 92.992656 | Q21: =Diseno_Marshall!$B$35*A21^2+Diseno_Marshall!$C$35*A21+Diseno_Marshall!$D$35 -> 17.560339
A22: =MIN(Diseno_Marshall!$B$17:$B$21)+18*(MAX(Diseno_Marshall!$B$17:$B$21)-MIN(Diseno_Marshall!$B$17:$B$21))/30 -> 8.2 | B22: =Diseno_Marshall!$B$33*A22^2+Diseno_Marshall!$C$33*A22+Diseno_Marshall!$D$33 -> 2.1785313 | E22: =Diseno_Marshall!$B$37*A22^2+Diseno_Marshall!$C$37*A22+Diseno_Marshall!$D$37 -> 8.0051461 | H22: =Diseno_Marshall!$B$38*A22^2+Diseno_Marshall!$C$38*A22+Diseno_Marshall!$D$38 -> 3.5 | K22: =Diseno_Marshall!$B$34*A22^2+Diseno_Marshall!$C$34*A22+Diseno_Marshall!$D$34 -> 1.0861265 | N22: =Diseno_Marshall!$B$36*A22^2+Diseno_Marshall!$C$36*A22+Diseno_Marshall!$D$36 -> 94.028465 | Q22: =Diseno_Marshall!$B$35*A22^2+Diseno_Marshall!$C$35*A22+Diseno_Marshall!$D$35 -> 17.707012
A23: =MIN(Diseno_Marshall!$B$17:$B$21)+19*(MAX(Diseno_Marshall!$B$17:$B$21)-MIN(Diseno_Marshall!$B$17:$B$21))/30 -> 8.35 | B23: =Diseno_Marshall!$B$33*A23^2+Diseno_Marshall!$C$33*A23+Diseno_Marshall!$D$33 -> 2.1782353 | E23: =Diseno_Marshall!$B$37*A23^2+Diseno_Marshall!$C$37*A23+Diseno_Marshall!$D$37 -> 7.9705889 | H23: =Diseno_Marshall!$B$38*A23^2+Diseno_Marshall!$C$38*A23+Diseno_Marshall!$D$38 -> 3.5 | K23: =Diseno_Marshall!$B$34*A23^2+Diseno_Marshall!$C$34*A23+Diseno_Marshall!$D$34 -> 0.91349496 | N23: =Diseno_Marshall!$B$36*A23^2+Diseno_Marshall!$C$36*A23+Diseno_Marshall!$D$36 -> 95.050934 | Q23: =Diseno_Marshall!$B$35*A23^2+Diseno_Marshall!$C$35*A23+Diseno_Marshall!$D$35 -> 17.852459
A24: =MIN(Diseno_Marshall!$B$17:$B$21)+20*(MAX(Diseno_Marshall!$B$17:$B$21)-MIN(Diseno_Marshall!$B$17:$B$21))/30 -> 8.5 | B24: =Diseno_Marshall!$B$33*A24^2+Diseno_Marshall!$C$33*A24+Diseno_Marshall!$D$33 -> 2.1779677 | E24: =Diseno_Marshall!$B$37*A24^2+Diseno_Marshall!$C$37*A24+Diseno_Marshall!$D$37 -> 7.915313 | H24: =Diseno_Marshall!$B$38*A24^2+Diseno_Marshall!$C$38*A24+Diseno_Marshall!$D$38 -> 3.5 | K24: =Diseno_Marshall!$B$34*A24^2+Diseno_Marshall!$C$34*A24+Diseno_Marshall!$D$34 -> 0.73979234 | N24: =Diseno_Marshall!$B$36*A24^2+Diseno_Marshall!$C$36*A24+Diseno_Marshall!$D$36 -> 96.060063 | Q24: =Diseno_Marshall!$B$35*A24^2+Diseno_Marshall!$C$35*A24+Diseno_Marshall!$D$35 -> 17.996682
A25: =MIN(Diseno_Marshall!$B$17:$B$21)+21*(MAX(Diseno_Marshall!$B$17:$B$21)-MIN(Diseno_Marshall!$B$17:$B$21))/30 -> 8.65 | B25: =Diseno_Marshall!$B$33*A25^2+Diseno_Marshall!$C$33*A25+Diseno_Marshall!$D$33 -> 2.1777284 | E25: =Diseno_Marshall!$B$37*A25^2+Diseno_Marshall!$C$37*A25+Diseno_Marshall!$D$37 -> 7.8393182 | H25: =Diseno_Marshall!$B$38*A25^2+Diseno_Marshall!$C$38*A25+Diseno_Marshall!$D$38 -> 3.5 | K25: =Diseno_Marshall!$B$34*A25^2+Diseno_Marshall!$C$34*A25+Diseno_Marshall!$D$34 -> 0.56501869 | N25: =Diseno_Marshall!$B$36*A25^2+Diseno_Marshall!$C$36*A25+Diseno_Marshall!$D$36 -> 97.055853 | Q25: =Diseno_Marshall!$B$35*A25^2+Diseno_Marshall!$C$35*A25+Diseno_Marshall!$D$35 -> 18.13968
A26: =MIN(Diseno_Marshall!$B$17:$B$21)+22*(MAX(Diseno_Marshall!$B$17:$B$21)-MIN(Diseno_Marshall!$B$17:$B$21))/30 -> 8.8 | B26: =Diseno_Marshall!$B$33*A26^2+Diseno_Marshall!$C$33*A26+Diseno_Marshall!$D$33 -> 2.1775174 | E26: =Diseno_Marshall!$B$37*A26^2+Diseno_Marshall!$C$37*A26+Diseno_Marshall!$D$37 -> 7.7426046 | H26: =Diseno_Marshall!$B$38*A26^2+Diseno_Marshall!$C$38*A26+Diseno_Marshall!$D$38 -> 3.5 | K26: =Diseno_Marshall!$B$34*A26^2+Diseno_Marshall!$C$34*A26+Diseno_Marshall!$D$34 -> 0.38917401 | N26: =Diseno_Marshall!$B$36*A26^2+Diseno_Marshall!$C$36*A26+Diseno_Marshall!$D$36 -> 98.038303 | Q26: =Diseno_Marshall!$B$35*A26^2+Diseno_Marshall!$C$35*A26+Diseno_Marshall!$D$35 -> 18.281453
A27: =MIN(Diseno_Marshall!$B$17:$B$21)+23*(MAX(Diseno_Marshall!$B$17:$B$21)-MIN(Diseno_Marshall!$B$17:$B$21))/30 -> 8.95 | B27: =Diseno_Marshall!$B$33*A27^2+Diseno_Marshall!$C$33*A27+Diseno_Marshall!$D$33 -> 2.1773347 | E27: =Diseno_Marshall!$B$37*A27^2+Diseno_Marshall!$C$37*A27+Diseno_Marshall!$D$37 -> 7.6251723 | H27: =Diseno_Marshall!$B$38*A27^2+Diseno_Marshall!$C$38*A27+Diseno_Marshall!$D$38 -> 3.5 | K27: =Diseno_Marshall!$B$34*A27^2+Diseno_Marshall!$C$34*A27+Diseno_Marshall!$D$34 -> 0.21225829 | N27: =Diseno_Marshall!$B$36*A27^2+Diseno_Marshall!$C$36*A27+Diseno_Marshall!$D$36 -> 99.007413 | Q27: =Diseno_Marshall!$B$35*A27^2+Diseno_Marshall!$C$35*A27+Diseno_Marshall!$D$35 -> 18.422002
A28: =MIN(Diseno_Marshall!$B$17:$B$21)+24*(MAX(Diseno_Marshall!$B$17:$B$21)-MIN(Diseno_Marshall!$B$17:$B$21))/30 -> 9.1 | B28: =Diseno_Marshall!$B$33*A28^2+Diseno_Marshall!$C$33*A28+Diseno_Marshall!$D$33 -> 2.1771804 | E28: =Diseno_Marshall!$B$37*A28^2+Diseno_Marshall!$C$37*A28+Diseno_Marshall!$D$37 -> 7.4870211 | H28: =Diseno_Marshall!$B$38*A28^2+Diseno_Marshall!$C$38*A28+Diseno_Marshall!$D$38 -> 3.5 | K28: =Diseno_Marshall!$B$34*A28^2+Diseno_Marshall!$C$34*A28+Diseno_Marshall!$D$34 -> 0.034271538 | N28: =Diseno_Marshall!$B$36*A28^2+Diseno_Marshall!$C$36*A28+Diseno_Marshall!$D$36 -> 99.963183 | Q28: =Diseno_Marshall!$B$35*A28^2+Diseno_Marshall!$C$35*A28+Diseno_Marshall!$D$35 -> 18.561325
A29: =MIN(Diseno_Marshall!$B$17:$B$21)+25*(MAX(Diseno_Marshall!$B$17:$B$21)-MIN(Diseno_Marshall!$B$17:$B$21))/30 -> 9.25 | B29: =Diseno_Marshall!$B$33*A29^2+Diseno_Marshall!$C$33*A29+Diseno_Marshall!$D$33 -> 2.1770544 | E29: =Diseno_Marshall!$B$37*A29^2+Diseno_Marshall!$C$37*A29+Diseno_Marshall!$D$37 -> 7.3281511 | H29: =Diseno_Marshall!$B$38*A29^2+Diseno_Marshall!$C$38*A29+Diseno_Marshall!$D$38 -> 3.5 | K29: =Diseno_Marshall!$B$34*A29^2+Diseno_Marshall!$C$34*A29+Diseno_Marshall!$D$34 -> -0.14478625 | N29: =Diseno_Marshall!$B$36*A29^2+Diseno_Marshall!$C$36*A29+Diseno_Marshall!$D$36 -> 100.90561 | Q29: =Diseno_Marshall!$B$35*A29^2+Diseno_Marshall!$C$35*A29+Diseno_Marshall!$D$35 -> 18.699424
A30: =MIN(Diseno_Marshall!$B$17:$B$21)+26*(MAX(Diseno_Marshall!$B$17:$B$21)-MIN(Diseno_Marshall!$B$17:$B$21))/30 -> 9.4 | B30: =Diseno_Marshall!$B$33*A30^2+Diseno_Marshall!$C$33*A30+Diseno_Marshall!$D$33 -> 2.1769567 | E30: =Diseno_Marshall!$B$37*A30^2+Diseno_Marshall!$C$37*A30+Diseno_Marshall!$D$37 -> 7.1485623 | H30: =Diseno_Marshall!$B$38*A30^2+Diseno_Marshall!$C$38*A30+Diseno_Marshall!$D$38 -> 3.5 | K30: =Diseno_Marshall!$B$34*A30^2+Diseno_Marshall!$C$34*A30+Diseno_Marshall!$D$34 -> -0.32491507 | N30: =Diseno_Marshall!$B$36*A30^2+Diseno_Marshall!$C$36*A30+Diseno_Marshall!$D$36 -> 101.83471 | Q30: =Diseno_Marshall!$B$35*A30^2+Diseno_Marshall!$C$35*A30+Diseno_Marshall!$D$35 -> 18.836298
A31: =MIN(Diseno_Marshall!$B$17:$B$21)+27*(MAX(Diseno_Marshall!$B$17:$B$21)-MIN(Diseno_Marshall!$B$17:$B$21))/30 -> 9.55 | B31: =Diseno_Marshall!$B$33*A31^2+Diseno_Marshall!$C$33*A31+Diseno_Marshall!$D$33 -> 2.1768873 | E31: =Diseno_Marshall!$B$37*A31^2+Diseno_Marshall!$C$37*A31+Diseno_Marshall!$D$37 -> 6.9482547 | H31: =Diseno_Marshall!$B$38*A31^2+Diseno_Marshall!$C$38*A31+Diseno_Marshall!$D$38 -> 3.5 | K31: =Diseno_Marshall!$B$34*A31^2+Diseno_Marshall!$C$34*A31+Diseno_Marshall!$D$34 -> -0.50611492 | N31: =Diseno_Marshall!$B$36*A31^2+Diseno_Marshall!$C$36*A31+Diseno_Marshall!$D$36 -> 102.75046 | Q31: =Diseno_Marshall!$B$35*A31^2+Diseno_Marshall!$C$35*A31+Diseno_Marshall!$D$35 -> 18.971947
A32: =MIN(Diseno_Marshall!$B$17:$B$21)+28*(MAX(Diseno_Marshall!$B$17:$B$21)-MIN(Diseno_Marshall!$B$17:$B$21))/30 -> 9.7 | B32: =Diseno_Marshall!$B$33*A32^2+Diseno_Marshall!$C$33*A32+Diseno_Marshall!$D$33 -> 2.1768462 | E32: =Diseno_Marshall!$B$37*A32^2+Diseno_Marshall!$C$37*A32+Diseno_Marshall!$D$37 -> 6.7272282 | H32: =Diseno_Marshall!$B$38*A32^2+Diseno_Marshall!$C$38*A32+Diseno_Marshall!$D$38 -> 3.5 | K32: =Diseno_Marshall!$B$34*A32^2+Diseno_Marshall!$C$34*A32+Diseno_Marshall!$D$34 -> -0.68838581 | N32: =Diseno_Marshall!$B$36*A32^2+Diseno_Marshall!$C$36*A32+Diseno_Marshall!$D$36 -> 103.65287 | Q32: =Diseno_Marshall!$B$35*A32^2+Diseno_Marshall!$C$35*A32+Diseno_Marshall!$D$35 -> 19.106371
A33: =MIN(Diseno_Marshall!$B$17:$B$21)+29*(MAX(Diseno_Marshall!$B$17:$B$21)-MIN(Diseno_Marshall!$B$17:$B$21))/30 -> 9.85 | B33: =Diseno_Marshall!$B$33*A33^2+Diseno_Marshall!$C$33*A33+Diseno_Marshall!$D$33 -> 2.1768335 | E33: =Diseno_Marshall!$B$37*A33^2+Diseno_Marshall!$C$37*A33+Diseno_Marshall!$D$37 -> 6.485483 | H33: =Diseno_Marshall!$B$38*A33^2+Diseno_Marshall!$C$38*A33+Diseno_Marshall!$D$38 -> 3.5 | K33: =Diseno_Marshall!$B$34*A33^2+Diseno_Marshall!$C$34*A33+Diseno_Marshall!$D$34 -> -0.87172773 | N33: =Diseno_Marshall!$B$36*A33^2+Diseno_Marshall!$C$36*A33+Diseno_Marshall!$D$36 -> 104.54194 | Q33: =Diseno_Marshall!$B$35*A33^2+Diseno_Marshall!$C$35*A33+Diseno_Marshall!$D$35 -> 19.239571
A34: =MIN(Diseno_Marshall!$B$17:$B$21)+30*(MAX(Diseno_Marshall!$B$17:$B$21)-MIN(Diseno_Marshall!$B$17:$B$21))/30 -> 10 | B34: =Diseno_Marshall!$B$33*A34^2+Diseno_Marshall!$C$33*A34+Diseno_Marshall!$D$33 -> 2.1768491 | E34: =Diseno_Marshall!$B$37*A34^2+Diseno_Marshall!$C$37*A34+Diseno_Marshall!$D$37 -> 6.223019 | H34: =Diseno_Marshall!$B$38*A34^2+Diseno_Marshall!$C$38*A34+Diseno_Marshall!$D$38 -> 3.5 | K34: =Diseno_Marshall!$B$34*A34^2+Diseno_Marshall!$C$34*A34+Diseno_Marshall!$D$34 -> -1.0561407 | N34: =Diseno_Marshall!$B$36*A34^2+Diseno_Marshall!$C$36*A34+Diseno_Marshall!$D$36 -> 105.41767 | Q34: =Diseno_Marshall!$B$35*A34^2+Diseno_Marshall!$C$35*A34+Diseno_Marshall!$D$35 -> 19.371545
A39: Eje X: | B39: Gmb: eje Y mín | C39: eje Y máx | E39: Estabilidad: eje Y mín | F39: eje Y máx | H39: Flujo: eje Y mín | I39: eje Y máx | K39: Va: eje Y mín | L39: eje Y máx | N39: VFA: eje Y mín | O39: eje Y máx | Q39: VMA: eje Y mín | R39: eje Y máx
A40: 5 | B40: 2.14 | C40: 2.22 | E40: 4 | F40: 9 | H40: 3 | I40: 7 | K40: -2 | L40: 6 | N40: 60 | O40: 110 | Q40: 12 | R40: 21
B42: X lectura | C42: Y lectura | E42: X lectura | F42: Y lectura | H42: X lectura | I42: Y lectura | K42: X lectura | L42: Y lectura | N42: X lectura | O42: Y lectura | Q42: X lectura | R42: Y lectura
B43: =Diseno_Marshall!$F$41 -> 6 | C43: =B40 -> 2.14 | E43: =Diseno_Marshall!$F$41 -> 6 | F43: =E40 -> 4 | H43: =Diseno_Marshall!$F$41 -> 6 | I43: =H40 -> 3 | K43: =Diseno_Marshall!$F$41 -> 6 | L43: =K40 -> -2 | N43: =Diseno_Marshall!$F$41 -> 6 | O43: =N40 -> 60 | Q43: =Diseno_Marshall!$F$41 -> 6 | R43: =Q40 -> 12
B44: =Diseno_Marshall!$F$41 -> 6 | C44: =Diseno_Marshall!$B$33*Diseno_Marshall!$F$41^2+Diseno_Marshall!$C$33*Diseno_Marshall!$F$41+Diseno_Marshall!$D$33 -> 2.1861255 | E44: =Diseno_Marshall!$F$41 -> 6 | F44: =Diseno_Marshall!$B$37*Diseno_Marshall!$F$41^2+Diseno_Marshall!$C$37*Diseno_Marshall!$F$41+Diseno_Marshall!$D$37 -> 6.1316234 | H44: =Diseno_Marshall!$F$41 -> 6 | I44: =Diseno_Marshall!$B$38*Diseno_Marshall!$F$41^2+Diseno_Marshall!$C$38*Diseno_Marshall!$F$41+Diseno_Marshall!$D$38 -> 3.5 | K44: =Diseno_Marshall!$F$41 -> 6 | L44: =Diseno_Marshall!$B$34*Diseno_Marshall!$F$41^2+Diseno_Marshall!$C$34*Diseno_Marshall!$F$41+Diseno_Marshall!$D$34 -> 3.4950065 | N44: =Diseno_Marshall!$F$41 -> 6 | O44: =Diseno_Marshall!$B$36*Diseno_Marshall!$F$41^2+Diseno_Marshall!$C$36*Diseno_Marshall!$F$41+Diseno_Marshall!$D$36 -> 77.499668 | Q44: =Diseno_Marshall!$F$41 -> 6 | R44: =Diseno_Marshall!$B$35*Diseno_Marshall!$F$41^2+Diseno_Marshall!$C$35*Diseno_Marshall!$F$41+Diseno_Marshall!$D$35 -> 15.433062
B45: 5 | C45: =Diseno_Marshall!$B$33*Diseno_Marshall!$F$41^2+Diseno_Marshall!$C$33*Diseno_Marshall!$F$41+Diseno_Marshall!$D$33 -> 2.1861255 | E45: 5 | F45: =Diseno_Marshall!$B$37*Diseno_Marshall!$F$41^2+Diseno_Marshall!$C$37*Diseno_Marshall!$F$41+Diseno_Marshall!$D$37 -> 6.1316234 | H45: 5 | I45: =Diseno_Marshall!$B$38*Diseno_Marshall!$F$41^2+Diseno_Marshall!$C$38*Diseno_Marshall!$F$41+Diseno_Marshall!$D$38 -> 3.5 | K45: 5 | L45: =Diseno_Marshall!$B$34*Diseno_Marshall!$F$41^2+Diseno_Marshall!$C$34*Diseno_Marshall!$F$41+Diseno_Marshall!$D$34 -> 3.4950065 | N45: 5 | O45: =Diseno_Marshall!$B$36*Diseno_Marshall!$F$41^2+Diseno_Marshall!$C$36*Diseno_Marshall!$F$41+Diseno_Marshall!$D$36 -> 77.499668 | Q45: 5 | R45: =Diseno_Marshall!$B$35*Diseno_Marshall!$F$41^2+Diseno_Marshall!$C$35*Diseno_Marshall!$F$41+Diseno_Marshall!$D$35 -> 15.433062
B46: =TEXT(Diseno_Marshall!$F$41,"0.0") -> 6.0 | E46: =TEXT(Diseno_Marshall!$F$41,"0.0") -> 6.0 | H46: =TEXT(Diseno_Marshall!$F$41,"0.0") -> 6.0 | K46: =TEXT(Diseno_Marshall!$F$41,"0.0") -> 6.0 | N46: =TEXT(Diseno_Marshall!$F$41,"0.0") -> 6.0 | Q46: =TEXT(Diseno_Marshall!$F$41,"0.0") -> 6.0
